Workbook

Sheet Start Here
A1: START HERE · WHICH TAB DO I NEED?
A2: Every tab has its own blue input cells at the top. Cycle 0 = opening corpus. Calculation rows are tucked away at the bottom of the two main tabs ([+] in the left margin). Click a tab name to jump.
A4: I WANT TO…
A5: Go to | B5: Question it answers | C5: Tax basis
A6: MCX Company vs Personal | B6: Trading MCX gas futures: personally vs a 25.168% company vs company with 1, 2, 3, 4, 5 or 6 family members on payroll — every cycle, in one table | C6: Company 25.168% vs personal slabs
A7: Shipping Engine | B7: (Separate business) BDRY ETF → freight futures under four tax setups, with a ledger of the case you pick | C7: 0% · 25.168% · 31–39%
A8: NG Scenarios | B8: Bull / base / bear paths for MCX natural gas at three starting sizes | C8: Company 25.168%
A9: NG GIFT Bridge | B9: Stay on MCX, switch to GIFT, or run both? | C9: Company 25.168%
A10: NG Risk and Sizing | B10: What do rolls, margin hikes and Kelly sizing do to natural-gas returns? | C10: Company 25.168%
A11: NG Inputs | B11: Shared natural-gas assumptions plus the personal slab tables | C11: —
A12: NG Data | B12: The 123 price legs behind the margin assumptions | C12: —
A13: US ETF Engine | B13: (Separate business) leveraged US ETFs through INDmoney → IBKR | C13: Personal 31–39%
A15: COLOUR CODE
A16: Blue on cream = edit me
A17: Green on mint = linked from another tab — change it at the source
A18: Blue on light-blue = derived
A19: Green bold = result
A21: WHAT CHANGED IN THIS VERSION
A22: 1. MCX tab: one column (and one engine ledger) for every payroll size — Personal, Company, Company + 1 member … + 6 members — so you no longer have to guess how many people are on payroll. The members control is gone.
A23: 2. The ledger dropdown now picks any of those 8 routes; key results list all 8 with the cycle where each overtakes personal.
A24: 3. The members × recycle-ratio grid is kept for the ratio question.

Sheet MCX Company vs Personal
A1: MCX NATURAL-GAS FUTURES · YOU PERSONALLY vs YOUR COMPANY (25.168%) vs COMPANY + 1 … 6 FAMILY MEMBERS ON PAYROLL
A2: Business income from MCX futures (CTT charged ⇒ non-speculative). Change the blue cells; every table reprices. Cycle 0 = opening. The calculation engine is tucked away at the bottom ([+] in the left margin). Money stays in the company.
A4: CONTROLS — this sheet only | U4: Route list
A5: Starting capital (₹ Cr) | B5: 0.6 | C5: Opening trading capital | U5: Personal
A6: Gross return per cycle (on deployed capital) | B6: 1 | C6: Change 100% → 75% and everything reprices | U6: Company
A7: Cycle length (months) | B7: 18 | C7: Spreads each cycle's profit over financial years for personal slab tax | U7: Company + 1 member
A8: Company tax rate (22% + 10% surcharge + 4% cess) | B8: 0.25168 | C8: 0% shows a tax-holiday case | U8: Company + 2 members
A9: Company running cost per cycle (₹ Cr) | B9: 0.05 | C9: Your estimate ≈ ₹5L (statutory audit by a CA is part of it) | U9: Company + 3 members
A10: Personal route running cost per cycle (₹ Cr) | B10: 0 | C10: Laptop + internet ≈ 0 | U10: Company + 4 members
A11: Recycle ratio r (share of salary lent back) | B11: 1 | C11: Rest is spent by the family; the grid below shows the effect | U11: Company + 5 members
A12: Per-person salary cap per YEAR (₹ Cr) | B12: 0.12 | C12: ₹12L/yr — inside the s.87A rebate (assumes no other income) | U12: Company + 6 members
A13: Total salary cap (% of cycle profit) | B13: 0.4 | C13: s.40A(2) prudence limit, not a statutory number
A14: Route shown in the cycle ledger | B14: Company + 3 members | C14: =MATCH(B14,$U$5:$U$12,0) | D14: ◄ route number (1–8)
A15: Deployable-capital ceiling (₹ Cr) | B15: ='NG Inputs'!B9/10000000*'NG Data'!D134 | C15: MCX liquidity ceiling × margin; excess earns the idle yield
A16: Idle-capital yield (liquid fund) | B16: ='NG Inputs'!B10 | C16: From NG Inputs
A17: Salary cap per person per cycle (₹ Cr) | B17: =B12*B7/12 | C17: annual cap × cycle months ÷ 12
A19: KEY RESULTS — corpus at the end of cycle 5, 10 and 20 (₹ Cr), one row per payroll size
A20: Route | B20: After cycle 5 | C20: After cycle 10 | D20: After cycle 20 | E20: Overtakes personal from cycle | F20: Extra vs plain company (cycle 20)
A21: Personal | B21: =INDEX(B33:B53,6) | C21: =INDEX(B33:B53,11) | D21: =INDEX(B33:B53,21) | E21: — | F21: —
A22: Company | B22: =INDEX(C33:C53,6) | C22: =INDEX(C33:C53,11) | D22: =INDEX(C33:C53,21) | E22: =IFERROR(MATCH(1,M33:M53,0)-1,"not within 20") | F22: =D22-$D$22
A23: Company + 1 member | B23: =INDEX(D33:D53,6) | C23: =INDEX(D33:D53,11) | D23: =INDEX(D33:D53,21) | E23: =IFERROR(MATCH(1,N33:N53,0)-1,"not within 20") | F23: =D23-$D$22
A24: Company + 2 members | B24: =INDEX(E33:E53,6) | C24: =INDEX(E33:E53,11) | D24: =INDEX(E33:E53,21) | E24: =IFERROR(MATCH(1,O33:O53,0)-1,"not within 20") | F24: =D24-$D$22
A25: Company + 3 members | B25: =INDEX(F33:F53,6) | C25: =INDEX(F33:F53,11) | D25: =INDEX(F33:F53,21) | E25: =IFERROR(MATCH(1,P33:P53,0)-1,"not within 20") | F25: =D25-$D$22
A26: Company + 4 members | B26: =INDEX(G33:G53,6) | C26: =INDEX(G33:G53,11) | D26: =INDEX(G33:G53,21) | E26: =IFERROR(MATCH(1,Q33:Q53,0)-1,"not within 20") | F26: =D26-$D$22
A27: Company + 5 members | B27: =INDEX(H33:H53,6) | C27: =INDEX(H33:H53,11) | D27: =INDEX(H33:H53,21) | E27: =IFERROR(MATCH(1,R33:R53,0)-1,"not within 20") | F27: =D27-$D$22
A28: Company + 6 members | B28: =INDEX(I33:I53,6) | C28: =INDEX(I33:I53,11) | D28: =INDEX(I33:I53,21) | E28: =IFERROR(MATCH(1,S33:S53,0)-1,"not within 20") | F28: =D28-$D$22
A31: EVERY CYCLE — corpus at the end of each cycle (₹ Cr), one column per payroll size; cycle 0 = opening; best route highlighted
A32: Cycle | B32: Personal | C32: Company | D32: Company + 1 member | E32: Company + 2 members | F32: Company + 3 members | G32: Company + 4 members | H32: Company + 5 members | I32: Company + 6 members | J32: Best route | K32: Company vs personal | L32: Best payroll adds vs company | M32: Co>P? | N32: +1>P? | O32: +2>P? | P32: +3>P? | Q32: +4>P? | R32: +5>P? | S32: +6>P?
A33: 0 | B33: =$B$5 | C33: =$B$5 | D33: =$B$5 | E33: =$B$5 | F33: =$B$5 | G33: =$B$5 | H33: =$B$5 | I33: =$B$5 | J33: =IF(A33=0,"—",INDEX($B$32:$I$32,MATCH(MAX(B33:I33),B33:I33,0))) | K33: =C33-B33 | L33: =MAX(D33:I33)-C33 | M33: =IF(AND($A33>0,C33>$B33),1,0) | N33: =IF(AND($A33>0,D33>$B33),1,0) | O33: =IF(AND($A33>0,E33>$B33),1,0) | P33: =IF(AND($A33>0,F33>$B33),1,0) | Q33: =IF(AND($A33>0,G33>$B33),1,0) | R33: =IF(AND($A33>0,H33>$B33),1,0) | S33: =IF(AND($A33>0,I33>$B33),1,0)
A34: 1 | B34: =K111 | C34: =K136 | D34: =K161 | E34: =K186 | F34: =K211 | G34: =K236 | H34: =K261 | I34: =K286 | J34: =IF(A34=0,"—",INDEX($B$32:$I$32,MATCH(MAX(B34:I34),B34:I34,0))) | K34: =C34-B34 | L34: =MAX(D34:I34)-C34 | M34: =IF(AND($A34>0,C34>$B34),1,0) | N34: =IF(AND($A34>0,D34>$B34),1,0) | O34: =IF(AND($A34>0,E34>$B34),1,0) | P34: =IF(AND($A34>0,F34>$B34),1,0) | Q34: =IF(AND($A34>0,G34>$B34),1,0) | R34: =IF(AND($A34>0,H34>$B34),1,0) | S34: =IF(AND($A34>0,I34>$B34),1,0)
A35: 2 | B35: =K112 | C35: =K137 | D35: =K162 | E35: =K187 | F35: =K212 | G35: =K237 | H35: =K262 | I35: =K287 | J35: =IF(A35=0,"—",INDEX($B$32:$I$32,MATCH(MAX(B35:I35),B35:I35,0))) | K35: =C35-B35 | L35: =MAX(D35:I35)-C35 | M35: =IF(AND($A35>0,C35>$B35),1,0) | N35: =IF(AND($A35>0,D35>$B35),1,0) | O35: =IF(AND($A35>0,E35>$B35),1,0) | P35: =IF(AND($A35>0,F35>$B35),1,0) | Q35: =IF(AND($A35>0,G35>$B35),1,0) | R35: =IF(AND($A35>0,H35>$B35),1,0) | S35: =IF(AND($A35>0,I35>$B35),1,0)
A36: 3 | B36: =K113 | C36: =K138 | D36: =K163 | E36: =K188 | F36: =K213 | G36: =K238 | H36: =K263 | I36: =K288 | J36: =IF(A36=0,"—",INDEX($B$32:$I$32,MATCH(MAX(B36:I36),B36:I36,0))) | K36: =C36-B36 | L36: =MAX(D36:I36)-C36 | M36: =IF(AND($A36>0,C36>$B36),1,0) | N36: =IF(AND($A36>0,D36>$B36),1,0) | O36: =IF(AND($A36>0,E36>$B36),1,0) | P36: =IF(AND($A36>0,F36>$B36),1,0) | Q36: =IF(AND($A36>0,G36>$B36),1,0) | R36: =IF(AND($A36>0,H36>$B36),1,0) | S36: =IF(AND($A36>0,I36>$B36),1,0)
A37: 4 | B37: =K114 | C37: =K139 | D37: =K164 | E37: =K189 | F37: =K214 | G37: =K239 | H37: =K264 | I37: =K289 | J37: =IF(A37=0,"—",INDEX($B$32:$I$32,MATCH(MAX(B37:I37),B37:I37,0))) | K37: =C37-B37 | L37: =MAX(D37:I37)-C37 | M37: =IF(AND($A37>0,C37>$B37),1,0) | N37: =IF(AND($A37>0,D37>$B37),1,0) | O37: =IF(AND($A37>0,E37>$B37),1,0) | P37: =IF(AND($A37>0,F37>$B37),1,0) | Q37: =IF(AND($A37>0,G37>$B37),1,0) | R37: =IF(AND($A37>0,H37>$B37),1,0) | S37: =IF(AND($A37>0,I37>$B37),1,0)
A38: 5 | B38: =K115 | C38: =K140 | D38: =K165 | E38: =K190 | F38: =K215 | G38: =K240 | H38: =K265 | I38: =K290 | J38: =IF(A38=0,"—",INDEX($B$32:$I$32,MATCH(MAX(B38:I38),B38:I38,0))) | K38: =C38-B38 | L38: =MAX(D38:I38)-C38 | M38: =IF(AND($A38>0,C38>$B38),1,0) | N38: =IF(AND($A38>0,D38>$B38),1,0) | O38: =IF(AND($A38>0,E38>$B38),1,0) | P38: =IF(AND($A38>0,F38>$B38),1,0) | Q38: =IF(AND($A38>0,G38>$B38),1,0) | R38: =IF(AND($A38>0,H38>$B38),1,0) | S38: =IF(AND($A38>0,I38>$B38),1,0)
A39: 6 | B39: =K116 | C39: =K141 | D39: =K166 | E39: =K191 | F39: =K216 | G39: =K241 | H39: =K266 | I39: =K291 | J39: =IF(A39=0,"—",INDEX($B$32:$I$32,MATCH(MAX(B39:I39),B39:I39,0))) | K39: =C39-B39 | L39: =MAX(D39:I39)-C39 | M39: =IF(AND($A39>0,C39>$B39),1,0) | N39: =IF(AND($A39>0,D39>$B39),1,0) | O39: =IF(AND($A39>0,E39>$B39),1,0) | P39: =IF(AND($A39>0,F39>$B39),1,0) | Q39: =IF(AND($A39>0,G39>$B39),1,0) | R39: =IF(AND($A39>0,H39>$B39),1,0) | S39: =IF(AND($A39>0,I39>$B39),1,0)
A40: 7 | B40: =K117 | C40: =K142 | D40: =K167 | E40: =K192 | F40: =K217 | G40: =K242 | H40: =K267 | I40: =K292 | J40: =IF(A40=0,"—",INDEX($B$32:$I$32,MATCH(MAX(B40:I40),B40:I40,0))) | K40: =C40-B40 | L40: =MAX(D40:I40)-C40 | M40: =IF(AND($A40>0,C40>$B40),1,0) | N40: =IF(AND($A40>0,D40>$B40),1,0) | O40: =IF(AND($A40>0,E40>$B40),1,0) | P40: =IF(AND($A40>0,F40>$B40),1,0) | Q40: =IF(AND($A40>0,G40>$B40),1,0) | R40: =IF(AND($A40>0,H40>$B40),1,0) | S40: =IF(AND($A40>0,I40>$B40),1,0)
A41: 8 | B41: =K118 | C41: =K143 | D41: =K168 | E41: =K193 | F41: =K218 | G41: =K243 | H41: =K268 | I41: =K293 | J41: =IF(A41=0,"—",INDEX($B$32:$I$32,MATCH(MAX(B41:I41),B41:I41,0))) | K41: =C41-B41 | L41: =MAX(D41:I41)-C41 | M41: =IF(AND($A41>0,C41>$B41),1,0) | N41: =IF(AND($A41>0,D41>$B41),1,0) | O41: =IF(AND($A41>0,E41>$B41),1,0) | P41: =IF(AND($A41>0,F41>$B41),1,0) | Q41: =IF(AND($A41>0,G41>$B41),1,0) | R41: =IF(AND($A41>0,H41>$B41),1,0) | S41: =IF(AND($A41>0,I41>$B41),1,0)
A42: 9 | B42: =K119 | C42: =K144 | D42: =K169 | E42: =K194 | F42: =K219 | G42: =K244 | H42: =K269 | I42: =K294 | J42: =IF(A42=0,"—",INDEX($B$32:$I$32,MATCH(MAX(B42:I42),B42:I42,0))) | K42: =C42-B42 | L42: =MAX(D42:I42)-C42 | M42: =IF(AND($A42>0,C42>$B42),1,0) | N42: =IF(AND($A42>0,D42>$B42),1,0) | O42: =IF(AND($A42>0,E42>$B42),1,0) | P42: =IF(AND($A42>0,F42>$B42),1,0) | Q42: =IF(AND($A42>0,G42>$B42),1,0) | R42: =IF(AND($A42>0,H42>$B42),1,0) | S42: =IF(AND($A42>0,I42>$B42),1,0)
A43: 10 | B43: =K120 | C43: =K145 | D43: =K170 | E43: =K195 | F43: =K220 | G43: =K245 | H43: =K270 | I43: =K295 | J43: =IF(A43=0,"—",INDEX($B$32:$I$32,MATCH(MAX(B43:I43),B43:I43,0))) | K43: =C43-B43 | L43: =MAX(D43:I43)-C43 | M43: =IF(AND($A43>0,C43>$B43),1,0) | N43: =IF(AND($A43>0,D43>$B43),1,0) | O43: =IF(AND($A43>0,E43>$B43),1,0) | P43: =IF(AND($A43>0,F43>$B43),1,0) | Q43: =IF(AND($A43>0,G43>$B43),1,0) | R43: =IF(AND($A43>0,H43>$B43),1,0) | S43: =IF(AND($A43>0,I43>$B43),1,0)
A44: 11 | B44: =K121 | C44: =K146 | D44: =K171 | E44: =K196 | F44: =K221 | G44: =K246 | H44: =K271 | I44: =K296 | J44: =IF(A44=0,"—",INDEX($B$32:$I$32,MATCH(MAX(B44:I44),B44:I44,0))) | K44: =C44-B44 | L44: =MAX(D44:I44)-C44 | M44: =IF(AND($A44>0,C44>$B44),1,0) | N44: =IF(AND($A44>0,D44>$B44),1,0) | O44: =IF(AND($A44>0,E44>$B44),1,0) | P44: =IF(AND($A44>0,F44>$B44),1,0) | Q44: =IF(AND($A44>0,G44>$B44),1,0) | R44: =IF(AND($A44>0,H44>$B44),1,0) | S44: =IF(AND($A44>0,I44>$B44),1,0)
...

Sheet Shipping Engine
A1: SHIPPING ENGINE · BDRY → SGX/ICE FFA · FOUR TAX CASES (separate business — not MCX)
A2: Change the blue cells; pick which tax case to read in the cycle ledger. Cycle 0 is the opening. The four calculation blocks are tucked away at the bottom (click the [+] in the left margin to open them).
A4: CONTROLS — this sheet only
A5: Starting capital (₹ Cr) | B5: 0.6 | C5: Cycle-1 opening corpus
A6: Gross return per cycle | B6: 0.75 | C6: On deployed capital — your assumption, not data
A7: Cycle length (months) | B7: 18 | C7: <24 ⇒ personal STCG at slabs; ≥24 ⇒ LTCG 12.5% (surcharge capped at 15%)
A8: Company-switch threshold (₹ Cr) | B8: 20 | C8: Case 3 only: personal account becomes a GIFT/IFSC company at this corpus
A9: USD/INR | B9: 94.98
A10: Company tax rate (s.115BAA) | B10: ='NG Inputs'!B4 | C10: Linked to NG Inputs!B4
A11: Company running cost per cycle — full stack (₹ Cr) | B11: 0.5 | C11: Charged only in the GIFT/IFSC company stage; deductible
A12: Lean running cost BEFORE threshold (₹ Cr) | B12: 0 | C12: Case 2 only (company from cycle 1)
A13: BDRY liquidity regime | B13: Current | C13: Current = 90-day mean ($82.7K/day); Hot = freight upswing ($352K/day)
A14: BDRY safe $/day — current | B14: 82683 | C14: bdry_liquidity.csv, 90-day mean of tiered safe liquidity
A15: BDRY safe $/day — hot | B15: 352235 | C15: Top-quartile rolling 90-day windows since 2018
A16: Build window — entry (days) | B16: 45 | C16: 1–1.5 month stretched accumulation
A17: Exit window (days) | B17: 45 | C17: Exit capacity = safe $/day × exit days
A18: FFA capacity per position ($) | B18: 60000000 | C18: SGX/ICE Cape 5TC + Pmx 4TC — verify with your FCM
A19: LTCG base (unlisted foreign ≥24m) | B19: 0.125
A20: STCG top base rate (slab) | B20: 0.3 | C20: New Tax Regime top slab
A21: Health & education cess | B21: 0.04
A22: LTCG surcharge cap | B22: 0.15
A23: Idle-capital yield (liquid fund) | B23: ='NG Inputs'!B10 | C23: Linked to NG Inputs!B10
A24: Family payroll | B24: On | C24: On / Off — company stages of Cases 2 and 3; switches off if company tax = 0
A25: Members on payroll | B25: 3 | C25: 0 to 6
A26: Per-person salary cap per YEAR (₹ Cr) | B26: 0.12 | C26: Equals ₹12L/yr — inside the s.87A rebate zone
A27: Total salary cap (% of cycle profit) | B27: 0.4 | C27: s.40A(2) reasonableness guard
A28: Recycle ratio r (share of salary lent back) | B28: 1 | C28: Below 100% leaks (1−r) × salary out of the company each cycle
A29: Tax case shown in the cycle ledger below | B29: Case 3 · Personal slabs → company at threshold | C29: =MATCH(B29,$A$50:$A$53,0)
A30: DERIVED — capacity and caps
A31: BDRY safe $/day in force | B31: =IF(B13="Hot",B15,B14)
A32: BDRY build capacity (₹ Cr) | B32: =B31*B16*B9/10000000 | C32: safe $/day × build days
A33: BDRY exit capacity (₹ Cr) | B33: =B31*B17*B9/10000000 | C33: safe $/day × exit days
A34: FFA position capacity (₹ Cr) | B34: =B18*B9/10000000
A35: ENTRY ceiling — BDRY (₹ Cr) | B35: =MIN(B32,B33/(1+B6)) | C35: Exit binds: the position grows by (1+gross) before it must be sold
A36: ENTRY ceiling — FFA (₹ Cr) | B36: =B34/(1+B6)
A37: Salary cap per person per cycle (₹ Cr) | B37: =B26*B7/12 | C37: annual cap × cycle months ÷ 12
A38: Max family salary per cycle (₹ Cr) | B38: =B25*B37 | C38: members × per-person cap (before the % of profit cap)
A40: PERSONAL TAX LADDER — New Regime, surcharge on slab income (looked up on each cycle's taxable gain)
A41: Taxable gain ≥ (₹ Cr) | B41: Surcharge | C41: Eff. STCG rate | D41: Eff. LTCG rate (cap applied)
A42: 0 | B42: 0 | C42: =$B$20*(1+B42)*(1+$B$21) | D42: =$B$19*(1+MIN(B42,$B$22))*(1+$B$21) | E42: Top surcharge tier is applied to the whole gain (no marginal relief) — slightly overstates personal tax (conservative).
...

Sheet NG Scenarios
A1: REBUILT SCENARIOS · BULL / BASE / BEAR
A2: Per-trade tax, dynamic PDF-bucket margins, costs, slippage, ₹378 Cr ceiling. K'=K+min(dep·K/m,Nmax)·(move−roll−txn−slip)·(1−tax)+idle·yield·(1−tax).
A3: Starting capital bases → | C3: 2000000 | D3: 7500000 | E3: 20000000 | F3: ◄ Edit these to rescale every scenario & the expense schedule. Cells: C3=Base1, D3=Base2, E3=Base3
A4: Scenario | B4: Move % | C4: Margin % | D4: Calls/yr | E4: Gross ROC/call | F4: Rationale
A5: BULL | B5: 0.3 | C5: ='NG Data'!D135 | D5: 2 | E5: =B5/C5 | F5: Catch 2 legs/yr, capture first 30% of a ≥30% swing; margin = PDF ≥30%-bucket avg (25.9%)
A6: BASE | B6: 0.25 | C6: ='NG Data'!D134 | D6: 2 | E6: =B6/C6 | F6: TRUE BASE: 25% move (7-11×/yr, 2020-26) at the 25-30% bucket avg margin 27.3% — NOT 22%. (v9: move corrected 18%→25% to match this rationale and NG Risk and Sizing / NG GIFT Bridge.)
A7: BEAR | B7: 0.15 | C7: 0.28 | D7: 1 | E7: =B7/C7 | F7: 1 catch/yr of a 15% move in an elevated-margin regime (2022-style / Nov-26 fwd 29.7%)
A9: Expense schedule (₹) — blue, scales with each starting-capital base above (C3/D3/E3)
A10: Year | B10: =IF($C$3>=10000000,"₹"&TEXT($C$3/10000000,"0.##")&"Cr","₹"&TEXT($C$3/100000,"0.##")&"L")&" start" | C10: =IF($D$3>=10000000,"₹"&TEXT($D$3/10000000,"0.##")&"Cr","₹"&TEXT($D$3/100000,"0.##")&"L")&" start" | D10: =IF($E$3>=10000000,"₹"&TEXT($E$3/10000000,"0.##")&"Cr","₹"&TEXT($E$3/100000,"0.##")&"L")&" start"
A11: 1 | B11: =ROUND(0.01*$C$3,0) | C11: =ROUND(0.01*$D$3,0) | D11: =ROUND(0.01*$E$3,0)
A12: 2 | B12: =ROUND(0.01*$C$3,0) | C12: =ROUND(0.01*$D$3,0) | D12: =ROUND(0.01*$E$3,0)
A13: 3 | B13: =ROUND(0.025*$C$3,0) | C13: =ROUND(0.025*$D$3,0) | D13: =ROUND(0.025*$E$3,0)
A14: 4 | B14: =ROUND(0.025*$C$3,0) | C14: =ROUND(0.025*$D$3,0) | D14: =ROUND(0.025*$E$3,0)
A15: 5 | B15: =ROUND(0.05*$C$3,0) | C15: =ROUND(0.05*$D$3,0) | D15: =ROUND(0.05*$E$3,0)
A16: 6 | B16: =ROUND(0.05*$C$3,0) | C16: =ROUND(0.05*$D$3,0) | D16: =ROUND(0.05*$E$3,0)
A17: 7 | B17: =ROUND(0.05*$C$3,0) | C17: =ROUND(0.05*$D$3,0) | D17: =ROUND(0.05*$E$3,0)
A18: 8 | B18: =ROUND(0.1*$C$3,0) | C18: =ROUND(0.1*$D$3,0) | D18: =ROUND(0.1*$E$3,0)
A19: 9 | B19: =ROUND(0.1*$C$3,0) | C19: =ROUND(0.1*$D$3,0) | D19: =ROUND(0.1*$E$3,0)
A20: 10 | B20: =ROUND(0.1*$C$3,0) | C20: =ROUND(0.1*$D$3,0) | D20: =ROUND(0.1*$E$3,0)
A21: 11 | B21: =ROUND(0.1*$C$3,0) | C21: =ROUND(0.1*$D$3,0) | D21: =ROUND(0.1*$E$3,0)
A22: 12 | B22: =ROUND(0.1*$C$3,0) | C22: =ROUND(0.1*$D$3,0) | D22: =ROUND(0.1*$E$3,0)
A23: 13 | B23: =ROUND(0.1*$C$3,0) | C23: =ROUND(0.1*$D$3,0) | D23: =ROUND(0.1*$E$3,0)
A24: 14 | B24: =ROUND(0.1*$C$3,0) | C24: =ROUND(0.1*$D$3,0) | D24: =ROUND(0.1*$E$3,0)
A25: 15 | B25: =ROUND(0.1*$C$3,0) | C25: =ROUND(0.1*$D$3,0) | D25: =ROUND(0.1*$E$3,0)
A27: TRADE-BY-TRADE LEDGER — 15 years × calls; even call # = year end (expense applied)
A28: Call # | B28: Year | C28: ="BULL "&IF($C$3>=10000000,"₹"&TEXT($C$3/10000000,"0.##")&"Cr","₹"&TEXT($C$3/100000,"0.##")&"L") | D28: ="BULL "&IF($D$3>=10000000,"₹"&TEXT($D$3/10000000,"0.##")&"Cr","₹"&TEXT($D$3/100000,"0.##")&"L") | E28: ="BULL "&IF($E$3>=10000000,"₹"&TEXT($E$3/10000000,"0.##")&"Cr","₹"&TEXT($E$3/100000,"0.##")&"L") | F28: ="BASE "&IF($C$3>=10000000,"₹"&TEXT($C$3/10000000,"0.##")&"Cr","₹"&TEXT($C$3/100000,"0.##")&"L") | G28: ="BASE "&IF($D$3>=10000000,"₹"&TEXT($D$3/10000000,"0.##")&"Cr","₹"&TEXT($D$3/100000,"0.##")&"L") | H28: ="BASE "&IF($E$3>=10000000,"₹"&TEXT($E$3/10000000,"0.##")&"Cr","₹"&TEXT($E$3/100000,"0.##")&"L") | I28: ="BEAR "&IF($C$3>=10000000,"₹"&TEXT($C$3/10000000,"0.##")&"Cr","₹"&TEXT($C$3/100000,"0.##")&"L") | J28: ="BEAR "&IF($D$3>=10000000,"₹"&TEXT($D$3/10000000,"0.##")&"Cr","₹"&TEXT($D$3/100000,"0.##")&"L") | K28: ="BEAR "&IF($E$3>=10000000,"₹"&TEXT($E$3/10000000,"0.##")&"Cr","₹"&TEXT($E$3/100000,"0.##")&"L")
A29: 1 | B29: =ROUNDUP(A29/2,0) | C29: =$C$3+IF(OR($D$5=2,MOD(A29,2)=1),1,0)*(MIN('NG Inputs'!$B$12*$C$3/$C$5,'NG Inputs'!$B$9)*($B$5-'NG Inputs'!$B$5-'NG Inputs'!$B$6-2*'NG Inputs'!$B$7*SQRT(MIN('NG Inputs'!$B$12*$C$3/$C$5,'NG Inputs'!$B$9)/'NG Inputs'!$B$8))+MAX($C$3-MIN('NG Inputs'!$B$12*$C$3/$C$5,'NG Inputs'!$B$9)*$C$5,0)*'NG Inputs'!$B$10/$D$5)*(1-'NG Inputs'!$B$4)+IF($D$5=1,(1-IF(OR($D$5=2,MOD(A29,2)=1),1,0))*$C$3*'NG Inputs'!$B$10*(1-'NG Inputs'!$B$4)/2,0)-IF(MOD(A29,2)=0,INDEX($B$11:$D$25,B29,1)*(1-'NG Inputs'!$B$4),0) | D29: =$D$3+IF(OR($D$5=2,MOD(A29,2)=1),1,0)*(MIN('NG Inputs'!$B$12*$D$3/$C$5,'NG Inputs'!$B$9)*($B$5-'NG Inputs'!$B$5-'NG Inputs'!$B$6-2*'NG Inputs'!$B$7*SQRT(MIN('NG Inputs'!$B$12*$D$3/$C$5,'NG Inputs'!$B$9)/'NG Inputs'!$B$8))+MAX($D$3-MIN('NG Inputs'!$B$12*$D$3/$C$5,'NG Inputs'!$B$9)*$C$5,0)*'NG Inputs'!$B$10/$D$5)*(1-'NG Inputs'!$B$4)+IF($D$5=1,(1-IF(OR($D$5=2,MOD(A29,2)=1),1,0))*$D$3*'NG Inputs'!$B$10*(1-'NG Inputs'!$B$4)/2,0)-IF(MOD(A29,2)=0,INDEX($B$11:$D$25,B29,2)*(1-'NG Inputs'!$B$4),0) | E29: =$E$3+IF(OR($D$5=2,MOD(A29,2)=1),1,0)*(MIN('NG Inputs'!$B$12*$E$3/$C$5,'NG Inputs'!$B$9)*($B$5-'NG Inputs'!$B$5-'NG Inputs'!$B$6-2*'NG Inputs'!$B$7*SQRT(MIN('NG Inputs'!$B$12*$E$3/$C$5,'NG Inputs'!$B$9)/'NG Inputs'!$B$8))+MAX($E$3-MIN('NG Inputs'!$B$12*$E$3/$C$5,'NG Inputs'!$B$9)*$C$5,0)*'NG Inputs'!$B$10/$D$5)*(1-'NG Inputs'!$B$4)+IF($D$5=1,(1-IF(OR($D$5=2,MOD(A29,2)=1),1,0))*$E$3*'NG Inputs'!$B$10*(1-'NG Inputs'!$B$4)/2,0)-IF(MOD(A29,2)=0,INDEX($B$11:$D$25,B29,3)*(1-'NG Inputs'!$B$4),0) | F29: =$C$3+IF(OR($D$6=2,MOD(A29,2)=1),1,0)*(MIN('NG Inputs'!$B$12*$C$3/$C$6,'NG Inputs'!$B$9)*($B$6-'NG Inputs'!$B$5-'NG Inputs'!$B$6-2*'NG Inputs'!$B$7*SQRT(MIN('NG Inputs'!$B$12*$C$3/$C$6,'NG Inputs'!$B$9)/'NG Inputs'!$B$8))+MAX($C$3-MIN('NG Inputs'!$B$12*$C$3/$C$6,'NG Inputs'!$B$9)*$C$6,0)*'NG Inputs'!$B$10/$D$6)*(1-'NG Inputs'!$B$4)+IF($D$6=1,(1-IF(OR($D$6=2,MOD(A29,2)=1),1,0))*$C$3*'NG Inputs'!$B$10*(1-'NG Inputs'!$B$4)/2,0)-IF(MOD(A29,2)=0,INDEX($B$11:$D$25,B29,1)*(1-'NG Inputs'!$B$4),0) | G29: =$D$3+IF(OR($D$6=2,MOD(A29,2)=1),1,0)*(MIN('NG Inputs'!$B$12*$D$3/$C$6,'NG Inputs'!$B$9)*($B$6-'NG Inputs'!$B$5-'NG Inputs'!$B$6-2*'NG Inputs'!$B$7*SQRT(MIN('NG Inputs'!$B$12*$D$3/$C$6,'NG Inputs'!$B$9)/'NG Inputs'!$B$8))+MAX($D$3-MIN('NG Inputs'!$B$12*$D$3/$C$6,'NG Inputs'!$B$9)*$C$6,0)*'NG Inputs'!$B$10/$D$6)*(1-'NG Inputs'!$B$4)+IF($D$6=1,(1-IF(OR($D$6=2,MOD(A29,2)=1),1,0))*$D$3*'NG Inputs'!$B$10*(1-'NG Inputs'!$B$4)/2,0)-IF(MOD(A29,2)=0,INDEX($B$11:$D$25,B29,2)*(1-'NG Inputs'!$B$4),0) | H29: =$E$3+IF(OR($D$6=2,MOD(A29,2)=1),1,0)*(MIN('NG Inputs'!$B$12*$E$3/$C$6,'NG Inputs'!$B$9)*($B$6-'NG Inputs'!$B$5-'NG Inputs'!$B$6-2*'NG Inputs'!$B$7*SQRT(MIN('NG Inputs'!$B$12*$E$3/$C$6,'NG Inputs'!$B$9)/'NG Inputs'!$B$8))+MAX($E$3-MIN('NG Inputs'!$B$12*$E$3/$C$6,'NG Inputs'!$B$9)*$C$6,0)*'NG Inputs'!$B$10/$D$6)*(1-'NG Inputs'!$B$4)+IF($D$6=1,(1-IF(OR($D$6=2,MOD(A29,2)=1),1,0))*$E$3*'NG Inputs'!$B$10*(1-'NG Inputs'!$B$4)/2,0)-IF(MOD(A29,2)=0,INDEX($B$11:$D$25,B29,3)*(1-'NG Inputs'!$B$4),0) | I29: =$C$3+IF(OR($D$7=2,MOD(A29,2)=1),1,0)*(MIN('NG Inputs'!$B$12*$C$3/$C$7,'NG Inputs'!$B$9)*($B$7-'NG Inputs'!$B$5-'NG Inputs'!$B$6-2*'NG Inputs'!$B$7*SQRT(MIN('NG Inputs'!$B$12*$C$3/$C$7,'NG Inputs'!$B$9)/'NG Inputs'!$B$8))+MAX($C$3-MIN('NG Inputs'!$B$12*$C$3/$C$7,'NG Inputs'!$B$9)*$C$7,0)*'NG Inputs'!$B$10/$D$7)*(1-'NG Inputs'!$B$4)+IF($D$7=1,(1-IF(OR($D$7=2,MOD(A29,2)=1),1,0))*$C$3*'NG Inputs'!$B$10*(1-'NG Inputs'!$B$4)/2,0)-IF(MOD(A29,2)=0,INDEX($B$11:$D$25,B29,1)*(1-'NG Inputs'!$B$4),0) | J29: =$D$3+IF(OR($D$7=2,MOD(A29,2)=1),1,0)*(MIN('NG Inputs'!$B$12*$D$3/$C$7,'NG Inputs'!$B$9)*($B$7-'NG Inputs'!$B$5-'NG Inputs'!$B$6-2*'NG Inputs'!$B$7*SQRT(MIN('NG Inputs'!$B$12*$D$3/$C$7,'NG Inputs'!$B$9)/'NG Inputs'!$B$8))+MAX($D$3-MIN('NG Inputs'!$B$12*$D$3/$C$7,'NG Inputs'!$B$9)*$C$7,0)*'NG Inputs'!$B$10/$D$7)*(1-'NG Inputs'!$B$4)+IF($D$7=1,(1-IF(OR($D$7=2,MOD(A29,2)=1),1,0))*$D$3*'NG Inputs'!$B$10*(1-'NG Inputs'!$B$4)/2,0)-IF(MOD(A29,2)=0,INDEX($B$11:$D$25,B29,2)*(1-'NG Inputs'!$B$4),0) | K29: =$E$3+IF(OR($D$7=2,MOD(A29,2)=1),1,0)*(MIN('NG Inputs'!$B$12*$E$3/$C$7,'NG Inputs'!$B$9)*($B$7-'NG Inputs'!$B$5-'NG Inputs'!$B$6-2*'NG Inputs'!$B$7*SQRT(MIN('NG Inputs'!$B$12*$E$3/$C$7,'NG Inputs'!$B$9)/'NG Inputs'!$B$8))+MAX($E$3-MIN('NG Inputs'!$B$12*$E$3/$C$7,'NG Inputs'!$B$9)*$C$7,0)*'NG Inputs'!$B$10/$D$7)*(1-'NG Inputs'!$B$4)+IF($D$7=1,(1-IF(OR($D$7=2,MOD(A29,2)=1),1,0))*$E$3*'NG Inputs'!$B$10*(1-'NG Inputs'!$B$4)/2,0)-IF(MOD(A29,2)=0,INDEX($B$11:$D$25,B29,3)*(1-'NG Inputs'!$B$4),0)
A30: 2 | B30: =ROUNDUP(A30/2,0) | C30: =C29+IF(OR($D$5=2,MOD(A30,2)=1),1,0)*(MIN('NG Inputs'!$B$12*C29/$C$5,'NG Inputs'!$B$9)*($B$5-'NG Inputs'!$B$5-'NG Inputs'!$B$6-2*'NG Inputs'!$B$7*SQRT(MIN('NG Inputs'!$B$12*C29/$C$5,'NG Inputs'!$B$9)/'NG Inputs'!$B$8))+MAX(C29-MIN('NG Inputs'!$B$12*C29/$C$5,'NG Inputs'!$B$9)*$C$5,0)*'NG Inputs'!$B$10/$D$5)*(1-'NG Inputs'!$B$4)+IF($D$5=1,(1-IF(OR($D$5=2,MOD(A30,2)=1),1,0))*C29*'NG Inputs'!$B$10*(1-'NG Inputs'!$B$4)/2,0)-IF(MOD(A30,2)=0,INDEX($B$11:$D$25,B30,1)*(1-'NG Inputs'!$B$4),0) | D30: =D29+IF(OR($D$5=2,MOD(A30,2)=1),1,0)*(MIN('NG Inputs'!$B$12*D29/$C$5,'NG Inputs'!$B$9)*($B$5-'NG Inputs'!$B$5-'NG Inputs'!$B$6-2*'NG Inputs'!$B$7*SQRT(MIN('NG Inputs'!$B$12*D29/$C$5,'NG Inputs'!$B$9)/'NG Inputs'!$B$8))+MAX(D29-MIN('NG Inputs'!$B$12*D29/$C$5,'NG Inputs'!$B$9)*$C$5,0)*'NG Inputs'!$B$10/$D$5)*(1-'NG Inputs'!$B$4)+IF($D$5=1,(1-IF(OR($D$5=2,MOD(A30,2)=1),1,0))*D29*'NG Inputs'!$B$10*(1-'NG Inputs'!$B$4)/2,0)-IF(MOD(A30,2)=0,INDEX($B$11:$D$25,B30,2)*(1-'NG Inputs'!$B$4),0) | E30: =E29+IF(OR($D$5=2,MOD(A30,2)=1),1,0)*(MIN('NG Inputs'!$B$12*E29/$C$5,'NG Inputs'!$B$9)*($B$5-'NG Inputs'!$B$5-'NG Inputs'!$B$6-2*'NG Inputs'!$B$7*SQRT(MIN('NG Inputs'!$B$12*E29/$C$5,'NG Inputs'!$B$9)/'NG Inputs'!$B$8))+MAX(E29-MIN('NG Inputs'!$B$12*E29/$C$5,'NG Inputs'!$B$9)*$C$5,0)*'NG Inputs'!$B$10/$D$5)*(1-'NG Inputs'!$B$4)+IF($D$5=1,(1-IF(OR($D$5=2,MOD(A30,2)=1),1,0))*E29*'NG Inputs'!$B$10*(1-'NG Inputs'!$B$4)/2,0)-IF(MOD(A30,2)=0,INDEX($B$11:$D$25,B30,3)*(1-'NG Inputs'!$B$4),0) | F30: =F29+IF(OR($D$6=2,MOD(A30,2)=1),1,0)*(MIN('NG Inputs'!$B$12*F29/$C$6,'NG Inputs'!$B$9)*($B$6-'NG Inputs'!$B$5-'NG Inputs'!$B$6-2*'NG Inputs'!$B$7*SQRT(MIN('NG Inputs'!$B$12*F29/$C$6,'NG Inputs'!$B$9)/'NG Inputs'!$B$8))+MAX(F29-MIN('NG Inputs'!$B$12*F29/$C$6,'NG Inputs'!$B$9)*$C$6,0)*'NG Inputs'!$B$10/$D$6)*(1-'NG Inputs'!$B$4)+IF($D$6=1,(1-IF(OR($D$6=2,MOD(A30,2)=1),1,0))*F29*'NG Inputs'!$B$10*(1-'NG Inputs'!$B$4)/2,0)-IF(MOD(A30,2)=0,INDEX($B$11:$D$25,B30,1)*(1-'NG Inputs'!$B$4),0) | G30: =G29+IF(OR($D$6=2,MOD(A30,2)=1),1,0)*(MIN('NG Inputs'!$B$12*G29/$C$6,'NG Inputs'!$B$9)*($B$6-'NG Inputs'!$B$5-'NG Inputs'!$B$6-2*'NG Inputs'!$B$7*SQRT(MIN('NG Inputs'!$B$12*G29/$C$6,'NG Inputs'!$B$9)/'NG Inputs'!$B$8))+MAX(G29-MIN('NG Inputs'!$B$12*G29/$C$6,'NG Inputs'!$B$9)*$C$6,0)*'NG Inputs'!$B$10/$D$6)*(1-'NG Inputs'!$B$4)+IF($D$6=1,(1-IF(OR($D$6=2,MOD(A30,2)=1),1,0))*G29*'NG Inputs'!$B$10*(1-'NG Inputs'!$B$4)/2,0)-IF(MOD(A30,2)=0,INDEX($B$11:$D$25,B30,2)*(1-'NG Inputs'!$B$4),0) | H30: =H29+IF(OR($D$6=2,MOD(A30,2)=1),1,0)*(MIN('NG Inputs'!$B$12*H29/$C$6,'NG Inputs'!$B$9)*($B$6-'NG Inputs'!$B$5-'NG Inputs'!$B$6-2*'NG Inputs'!$B$7*SQRT(MIN('NG Inputs'!$B$12*H29/$C$6,'NG Inputs'!$B$9)/'NG Inputs'!$B$8))+MAX(H29-MIN('NG Inputs'!$B$12*H29/$C$6,'NG Inputs'!$B$9)*$C$6,0)*'NG Inputs'!$B$10/$D$6)*(1-'NG Inputs'!$B$4)+IF($D$6=1,(1-IF(OR($D$6=2,MOD(A30,2)=1),1,0))*H29*'NG Inputs'!$B$10*(1-'NG Inputs'!$B$4)/2,0)-IF(MOD(A30,2)=0,INDEX($B$11:$D$25,B30,3)*(1-'NG Inputs'!$B$4),0) | I30: =I29+IF(OR($D$7=2,MOD(A30,2)=1),1,0)*(MIN('NG Inputs'!$B$12*I29/$C$7,'NG Inputs'!$B$9)*($B$7-'NG Inputs'!$B$5-'NG Inputs'!$B$6-2*'NG Inputs'!$B$7*SQRT(MIN('NG Inputs'!$B$12*I29/$C$7,'NG Inputs'!$B$9)/'NG Inputs'!$B$8))+MAX(I29-MIN('NG Inputs'!$B$12*I29/$C$7,'NG Inputs'!$B$9)*$C$7,0)*'NG Inputs'!$B$10/$D$7)*(1-'NG Inputs'!$B$4)+IF($D$7=1,(1-IF(OR($D$7=2,MOD(A30,2)=1),1,0))*I29*'NG Inputs'!$B$10*(1-'NG Inputs'!$B$4)/2,0)-IF(MOD(A30,2)=0,INDEX($B$11:$D$25,B30,1)*(1-'NG Inputs'!$B$4),0) | J30: =J29+IF(OR($D$7=2,MOD(A30,2)=1),1,0)*(MIN('NG Inputs'!$B$12*J29/$C$7,'NG Inputs'!$B$9)*($B$7-'NG Inputs'!$B$5-'NG Inputs'!$B$6-2*'NG Inputs'!$B$7*SQRT(MIN('NG Inputs'!$B$12*J29/$C$7,'NG Inputs'!$B$9)/'NG Inputs'!$B$8))+MAX(J29-MIN('NG Inputs'!$B$12*J29/$C$7,'NG Inputs'!$B$9)*$C$7,0)*'NG Inputs'!$B$10/$D$7)*(1-'NG Inputs'!$B$4)+IF($D$7=1,(1-IF(OR($D$7=2,MOD(A30,2)=1),1,0))*J29*'NG Inputs'!$B$10*(1-'NG Inputs'!$B$4)/2,0)-IF(MOD(A30,2)=0,INDEX($B$11:$D$25,B30,2)*(1-'NG Inputs'!$B$4),0) | K30: =K29+IF(OR($D$7=2,MOD(A30,2)=1),1,0)*(MIN('NG Inputs'!$B$12*K29/$C$7,'NG Inputs'!$B$9)*($B$7-'NG Inputs'!$B$5-'NG Inputs'!$B$6-2*'NG Inputs'!$B$7*SQRT(MIN('NG Inputs'!$B$12*K29/$C$7,'NG Inputs'!$B$9)/'NG Inputs'!$B$8))+MAX(K29-MIN('NG Inputs'!$B$12*K29/$C$7,'NG Inputs'!$B$9)*$C$7,0)*'NG Inputs'!$B$10/$D$7)*(1-'NG Inputs'!$B$4)+IF($D$7=1,(1-IF(OR($D$7=2,MOD(A30,2)=1),1,0))*K29*'NG Inputs'!$B$10*(1-'NG Inputs'!$B$4)/2,0)-IF(MOD(A30,2)=0,INDEX($B$11:$D$25,B30,3)*(1-'NG Inputs'!$B$4),0)
A31: 3 | B31: =ROUNDUP(A31/2,0) | C31: =C30+IF(OR($D$5=2,MOD(A31,2)=1),1,0)*(MIN('NG Inputs'!$B$12*C30/$C$5,'NG Inputs'!$B$9)*($B$5-'NG Inputs'!$B$5-'NG Inputs'!$B$6-2*'NG Inputs'!$B$7*SQRT(MIN('NG Inputs'!$B$12*C30/$C$5,'NG Inputs'!$B$9)/'NG Inputs'!$B$8))+MAX(C30-MIN('NG Inputs'!$B$12*C30/$C$5,'NG Inputs'!$B$9)*$C$5,0)*'NG Inputs'!$B$10/$D$5)*(1-'NG Inputs'!$B$4)+IF($D$5=1,(1-IF(OR($D$5=2,MOD(A31,2)=1),1,0))*C30*'NG Inputs'!$B$10*(1-'NG Inputs'!$B$4)/2,0)-IF(MOD(A31,2)=0,INDEX($B$11:$D$25,B31,1)*(1-'NG Inputs'!$B$4),0) | D31: =D30+IF(OR($D$5=2,MOD(A31,2)=1),1,0)*(MIN('NG Inputs'!$B$12*D30/$C$5,'NG Inputs'!$B$9)*($B$5-'NG Inputs'!$B$5-'NG Inputs'!$B$6-2*'NG Inputs'!$B$7*SQRT(MIN('NG Inputs'!$B$12*D30/$C$5,'NG Inputs'!$B$9)/'NG Inputs'!$B$8))+MAX(D30-MIN('NG Inputs'!$B$12*D30/$C$5,'NG Inputs'!$B$9)*$C$5,0)*'NG Inputs'!$B$10/$D$5)*(1-'NG Inputs'!$B$4)+IF($D$5=1,(1-IF(OR($D$5=2,MOD(A31,2)=1),1,0))*D30*'NG Inputs'!$B$10*(1-'NG Inputs'!$B$4)/2,0)-IF(MOD(A31,2)=0,INDEX($B$11:$D$25,B31,2)*(1-'NG Inputs'!$B$4),0) | E31: =E30+IF(OR($D$5=2,MOD(A31,2)=1),1,0)*(MIN('NG Inputs'!$B$12*E30/$C$5,'NG Inputs'!$B$9)*($B$5-'NG Inputs'!$B$5-'NG Inputs'!$B$6-2*'NG Inputs'!$B$7*SQRT(MIN('NG Inputs'!$B$12*E30/$C$5,'NG Inputs'!$B$9)/'NG Inputs'!$B$8))+MAX(E30-MIN('NG Inputs'!$B$12*E30/$C$5,'NG Inputs'!$B$9)*$C$5,0)*'NG Inputs'!$B$10/$D$5)*(1-'NG Inputs'!$B$4)+IF($D$5=1,(1-IF(OR($D$5=2,MOD(A31,2)=1),1,0))*E30*'NG Inputs'!$B$10*(1-'NG Inputs'!$B$4)/2,0)-IF(MOD(A31,2)=0,INDEX($B$11:$D$25,B31,3)*(1-'NG Inputs'!$B$4),0) | F31: =F30+IF(OR($D$6=2,MOD(A31,2)=1),1,0)*(MIN('NG Inputs'!$B$12*F30/$C$6,'NG Inputs'!$B$9)*($B$6-'NG Inputs'!$B$5-'NG Inputs'!$B$6-2*'NG Inputs'!$B$7*SQRT(MIN('NG Inputs'!$B$12*F30/$C$6,'NG Inputs'!$B$9)/'NG Inputs'!$B$8))+MAX(F30-MIN('NG Inputs'!$B$12*F30/$C$6,'NG Inputs'!$B$9)*$C$6,0)*'NG Inputs'!$B$10/$D$6)*(1-'NG Inputs'!$B$4)+IF($D$6=1,(1-IF(OR($D$6=2,MOD(A31,2)=1),1,0))*F30*'NG Inputs'!$B$10*(1-'NG Inputs'!$B$4)/2,0)-IF(MOD(A31,2)=0,INDEX($B$11:$D$25,B31,1)*(1-'NG Inputs'!$B$4),0) | G31: =G30+IF(OR($D$6=2,MOD(A31,2)=1),1,0)*(MIN('NG Inputs'!$B$12*G30/$C$6,'NG Inputs'!$B$9)*($B$6-'NG Inputs'!$B$5-'NG Inputs'!$B$6-2*'NG Inputs'!$B$7*SQRT(MIN('NG Inputs'!$B$12*G30/$C$6,'NG Inputs'!$B$9)/'NG Inputs'!$B$8))+MAX(G30-MIN('NG Inputs'!$B$12*G30/$C$6,'NG Inputs'!$B$9)*$C$6,0)*'NG Inputs'!$B$10/$D$6)*(1-'NG Inputs'!$B$4)+IF($D$6=1,(1-IF(OR($D$6=2,MOD(A31,2)=1),1,0))*G30*'NG Inputs'!$B$10*(1-'NG Inputs'!$B$4)/2,0)-IF(MOD(A31,2)=0,INDEX($B$11:$D$25,B31,2)*(1-'NG Inputs'!$B$4),0) | H31: =H30+IF(OR($D$6=2,MOD(A31,2)=1),1,0)*(MIN('NG Inputs'!$B$12*H30/$C$6,'NG Inputs'!$B$9)*($B$6-'NG Inputs'!$B$5-'NG Inputs'!$B$6-2*'NG Inputs'!$B$7*SQRT(MIN('NG Inputs'!$B$12*H30/$C$6,'NG Inputs'!$B$9)/'NG Inputs'!$B$8))+MAX(H30-MIN('NG Inputs'!$B$12*H30/$C$6,'NG Inputs'!$B$9)*$C$6,0)*'NG Inputs'!$B$10/$D$6)*(1-'NG Inputs'!$B$4)+IF($D$6=1,(1-IF(OR($D$6=2,MOD(A31,2)=1),1,0))*H30*'NG Inputs'!$B$10*(1-'NG Inputs'!$B$4)/2,0)-IF(MOD(A31,2)=0,INDEX($B$11:$D$25,B31,3)*(1-'NG Inputs'!$B$4),0) | I31: =I30+IF(OR($D$7=2,MOD(A31,2)=1),1,0)*(MIN('NG Inputs'!$B$12*I30/$C$7,'NG Inputs'!$B$9)*($B$7-'NG Inputs'!$B$5-'NG Inputs'!$B$6-2*'NG Inputs'!$B$7*SQRT(MIN('NG Inputs'!$B$12*I30/$C$7,'NG Inputs'!$B$9)/'NG Inputs'!$B$8))+MAX(I30-MIN('NG Inputs'!$B$12*I30/$C$7,'NG Inputs'!$B$9)*$C$7,0)*'NG Inputs'!$B$10/$D$7)*(1-'NG Inputs'!$B$4)+IF($D$7=1,(1-IF(OR($D$7=2,MOD(A31,2)=1),1,0))*I30*'NG Inputs'!$B$10*(1-'NG Inputs'!$B$4)/2,0)-IF(MOD(A31,2)=0,INDEX($B$11:$D$25,B31,1)*(1-'NG Inputs'!$B$4),0) | J31: =J30+IF(OR($D$7=2,MOD(A31,2)=1),1,0)*(MIN('NG Inputs'!$B$12*J30/$C$7,'NG Inputs'!$B$9)*($B$7-'NG Inputs'!$B$5-'NG Inputs'!$B$6-2*'NG Inputs'!$B$7*SQRT(MIN('NG Inputs'!$B$12*J30/$C$7,'NG Inputs'!$B$9)/'NG Inputs'!$B$8))+MAX(J30-MIN('NG Inputs'!$B$12*J30/$C$7,'NG Inputs'!$B$9)*$C$7,0)*'NG Inputs'!$B$10/$D$7)*(1-'NG Inputs'!$B$4)+IF($D$7=1,(1-IF(OR($D$7=2,MOD(A31,2)=1),1,0))*J30*'NG Inputs'!$B$10*(1-'NG Inputs'!$B$4)/2,0)-IF(MOD(A31,2)=0,INDEX($B$11:$D$25,B31,2)*(1-'NG Inputs'!$B$4),0) | K31: =K30+IF(OR($D$7=2,MOD(A31,2)=1),1,0)*(MIN('NG Inputs'!$B$12*K30/$C$7,'NG Inputs'!$B$9)*($B$7-'NG Inputs'!$B$5-'NG Inputs'!$B$6-2*'NG Inputs'!$B$7*SQRT(MIN('NG Inputs'!$B$12*K30/$C$7,'NG Inputs'!$B$9)/'NG Inputs'!$B$8))+MAX(K30-MIN('NG Inputs'!$B$12*K30/$C$7,'NG Inputs'!$B$9)*$C$7,0)*'NG Inputs'!$B$10/$D$7)*(1-'NG Inputs'!$B$4)+IF($D$7=1,(1-IF(OR($D$7=2,MOD(A31,2)=1),1,0))*K30*'NG Inputs'!$B$10*(1-'NG Inputs'!$B$4)/2,0)-IF(MOD(A31,2)=0,INDEX($B$11:$D$25,B31,3)*(1-'NG Inputs'!$B$4),0)
A32: 4 | B32: =ROUNDUP(A32/2,0) | C32: =C31+IF(OR($D$5=2,MOD(A32,2)=1),1,0)*(MIN('NG Inputs'!$B$12*C31/$C$5,'NG Inputs'!$B$9)*($B$5-'NG Inputs'!$B$5-'NG Inputs'!$B$6-2*'NG Inputs'!$B$7*SQRT(MIN('NG Inputs'!$B$12*C31/$C$5,'NG Inputs'!$B$9)/'NG Inputs'!$B$8))+MAX(C31-MIN('NG Inputs'!$B$12*C31/$C$5,'NG Inputs'!$B$9)*$C$5,0)*'NG Inputs'!$B$10/$D$5)*(1-'NG Inputs'!$B$4)+IF($D$5=1,(1-IF(OR($D$5=2,MOD(A32,2)=1),1,0))*C31*'NG Inputs'!$B$10*(1-'NG Inputs'!$B$4)/2,0)-IF(MOD(A32,2)=0,INDEX($B$11:$D$25,B32,1)*(1-'NG Inputs'!$B$4),0) | D32: =D31+IF(OR($D$5=2,MOD(A32,2)=1),1,0)*(MIN('NG Inputs'!$B$12*D31/$C$5,'NG Inputs'!$B$9)*($B$5-'NG Inputs'!$B$5-'NG Inputs'!$B$6-2*'NG Inputs'!$B$7*SQRT(MIN('NG Inputs'!$B$12*D31/$C$5,'NG Inputs'!$B$9)/'NG Inputs'!$B$8))+MAX(D31-MIN('NG Inputs'!$B$12*D31/$C$5,'NG Inputs'!$B$9)*$C$5,0)*'NG Inputs'!$B$10/$D$5)*(1-'NG Inputs'!$B$4)+IF($D$5=1,(1-IF(OR($D$5=2,MOD(A32,2)=1),1,0))*D31*'NG Inputs'!$B$10*(1-'NG Inputs'!$B$4)/2,0)-IF(MOD(A32,2)=0,INDEX($B$11:$D$25,B32,2)*(1-'NG Inputs'!$B$4),0) | E32: =E31+IF(OR($D$5=2,MOD(A32,2)=1),1,0)*(MIN('NG Inputs'!$B$12*E31/$C$5,'NG Inputs'!$B$9)*($B$5-'NG Inputs'!$B$5-'NG Inputs'!$B$6-2*'NG Inputs'!$B$7*SQRT(MIN('NG Inputs'!$B$12*E31/$C$5,'NG Inputs'!$B$9)/'NG Inputs'!$B$8))+MAX(E31-MIN('NG Inputs'!$B$12*E31/$C$5,'NG Inputs'!$B$9)*$C$5,0)*'NG Inputs'!$B$10/$D$5)*(1-'NG Inputs'!$B$4)+IF($D$5=1,(1-IF(OR($D$5=2,MOD(A32,2)=1),1,0))*E31*'NG Inputs'!$B$10*(1-'NG Inputs'!$B$4)/2,0)-IF(MOD(A32,2)=0,INDEX($B$11:$D$25,B32,3)*(1-'NG Inputs'!$B$4),0) | F32: =F31+IF(OR($D$6=2,MOD(A32,2)=1),1,0)*(MIN('NG Inputs'!$B$12*F31/$C$6,'NG Inputs'!$B$9)*($B$6-'NG Inputs'!$B$5-'NG Inputs'!$B$6-2*'NG Inputs'!$B$7*SQRT(MIN('NG Inputs'!$B$12*F31/$C$6,'NG Inputs'!$B$9)/'NG Inputs'!$B$8))+MAX(F31-MIN('NG Inputs'!$B$12*F31/$C$6,'NG Inputs'!$B$9)*$C$6,0)*'NG Inputs'!$B$10/$D$6)*(1-'NG Inputs'!$B$4)+IF($D$6=1,(1-IF(OR($D$6=2,MOD(A32,2)=1),1,0))*F31*'NG Inputs'!$B$10*(1-'NG Inputs'!$B$4)/2,0)-IF(MOD(A32,2)=0,INDEX($B$11:$D$25,B32,1)*(1-'NG Inputs'!$B$4),0) | G32: =G31+IF(OR($D$6=2,MOD(A32,2)=1),1,0)*(MIN('NG Inputs'!$B$12*G31/$C$6,'NG Inputs'!$B$9)*($B$6-'NG Inputs'!$B$5-'NG Inputs'!$B$6-2*'NG Inputs'!$B$7*SQRT(MIN('NG Inputs'!$B$12*G31/$C$6,'NG Inputs'!$B$9)/'NG Inputs'!$B$8))+MAX(G31-MIN('NG Inputs'!$B$12*G31/$C$6,'NG Inputs'!$B$9)*$C$6,0)*'NG Inputs'!$B$10/$D$6)*(1-'NG Inputs'!$B$4)+IF($D$6=1,(1-IF(OR($D$6=2,MOD(A32,2)=1),1,0))*G31*'NG Inputs'!$B$10*(1-'NG Inputs'!$B$4)/2,0)-IF(MOD(A32,2)=0,INDEX($B$11:$D$25,B32,2)*(1-'NG Inputs'!$B$4),0) | H32: =H31+IF(OR($D$6=2,MOD(A32,2)=1),1,0)*(MIN('NG Inputs'!$B$12*H31/$C$6,'NG Inputs'!$B$9)*($B$6-'NG Inputs'!$B$5-'NG Inputs'!$B$6-2*'NG Inputs'!$B$7*SQRT(MIN('NG Inputs'!$B$12*H31/$C$6,'NG Inputs'!$B$9)/'NG Inputs'!$B$8))+MAX(H31-MIN('NG Inputs'!$B$12*H31/$C$6,'NG Inputs'!$B$9)*$C$6,0)*'NG Inputs'!$B$10/$D$6)*(1-'NG Inputs'!$B$4)+IF($D$6=1,(1-IF(OR($D$6=2,MOD(A32,2)=1),1,0))*H31*'NG Inputs'!$B$10*(1-'NG Inputs'!$B$4)/2,0)-IF(MOD(A32,2)=0,INDEX($B$11:$D$25,B32,3)*(1-'NG Inputs'!$B$4),0) | I32: =I31+IF(OR($D$7=2,MOD(A32,2)=1),1,0)*(MIN('NG Inputs'!$B$12*I31/$C$7,'NG Inputs'!$B$9)*($B$7-'NG Inputs'!$B$5-'NG Inputs'!$B$6-2*'NG Inputs'!$B$7*SQRT(MIN('NG Inputs'!$B$12*I31/$C$7,'NG Inputs'!$B$9)/'NG Inputs'!$B$8))+MAX(I31-MIN('NG Inputs'!$B$12*I31/$C$7,'NG Inputs'!$B$9)*$C$7,0)*'NG Inputs'!$B$10/$D$7)*(1-'NG Inputs'!$B$4)+IF($D$7=1,(1-IF(OR($D$7=2,MOD(A32,2)=1),1,0))*I31*'NG Inputs'!$B$10*(1-'NG Inputs'!$B$4)/2,0)-IF(MOD(A32,2)=0,INDEX($B$11:$D$25,B32,1)*(1-'NG Inputs'!$B$4),0) | J32: =J31+IF(OR($D$7=2,MOD(A32,2)=1),1,0)*(MIN('NG Inputs'!$B$12*J31/$C$7,'NG Inputs'!$B$9)*($B$7-'NG Inputs'!$B$5-'NG Inputs'!$B$6-2*'NG Inputs'!$B$7*SQRT(MIN('NG Inputs'!$B$12*J31/$C$7,'NG Inputs'!$B$9)/'NG Inputs'!$B$8))+MAX(J31-MIN('NG Inputs'!$B$12*J31/$C$7,'NG Inputs'!$B$9)*$C$7,0)*'NG Inputs'!$B$10/$D$7)*(1-'NG Inputs'!$B$4)+IF($D$7=1,(1-IF(OR($D$7=2,MOD(A32,2)=1),1,0))*J31*'NG Inputs'!$B$10*(1-'NG Inputs'!$B$4)/2,0)-IF(MOD(A32,2)=0,INDEX($B$11:$D$25,B32,2)*(1-'NG Inputs'!$B$4),0) | K32: =K31+IF(OR($D$7=2,MOD(A32,2)=1),1,0)*(MIN('NG Inputs'!$B$12*K31/$C$7,'NG Inputs'!$B$9)*($B$7-'NG Inputs'!$B$5-'NG Inputs'!$B$6-2*'NG Inputs'!$B$7*SQRT(MIN('NG Inputs'!$B$12*K31/$C$7,'NG Inputs'!$B$9)/'NG Inputs'!$B$8))+MAX(K31-MIN('NG Inputs'!$B$12*K31/$C$7,'NG Inputs'!$B$9)*$C$7,0)*'NG Inputs'!$B$10/$D$7)*(1-'NG Inputs'!$B$4)+IF($D$7=1,(1-IF(OR($D$7=2,MOD(A32,2)=1),1,0))*K31*'NG Inputs'!$B$10*(1-'NG Inputs'!$B$4)/2,0)-IF(MOD(A32,2)=0,INDEX($B$11:$D$25,B32,3)*(1-'NG Inputs'!$B$4),0)
A33: 5 | B33: =ROUNDUP(A33/2,0) | C33: =C32+IF(OR($D$5=2,MOD(A33,2)=1),1,0)*(MIN('NG Inputs'!$B$12*C32/$C$5,'NG Inputs'!$B$9)*($B$5-'NG Inputs'!$B$5-'NG Inputs'!$B$6-2*'NG Inputs'!$B$7*SQRT(MIN('NG Inputs'!$B$12*C32/$C$5,'NG Inputs'!$B$9)/'NG Inputs'!$B$8))+MAX(C32-MIN('NG Inputs'!$B$12*C32/$C$5,'NG Inputs'!$B$9)*$C$5,0)*'NG Inputs'!$B$10/$D$5)*(1-'NG Inputs'!$B$4)+IF($D$5=1,(1-IF(OR($D$5=2,MOD(A33,2)=1),1,0))*C32*'NG Inputs'!$B$10*(1-'NG Inputs'!$B$4)/2,0)-IF(MOD(A33,2)=0,INDEX($B$11:$D$25,B33,1)*(1-'NG Inputs'!$B$4),0) | D33: =D32+IF(OR($D$5=2,MOD(A33,2)=1),1,0)*(MIN('NG Inputs'!$B$12*D32/$C$5,'NG Inputs'!$B$9)*($B$5-'NG Inputs'!$B$5-'NG Inputs'!$B$6-2*'NG Inputs'!$B$7*SQRT(MIN('NG Inputs'!$B$12*D32/$C$5,'NG Inputs'!$B$9)/'NG Inputs'!$B$8))+MAX(D32-MIN('NG Inputs'!$B$12*D32/$C$5,'NG Inputs'!$B$9)*$C$5,0)*'NG Inputs'!$B$10/$D$5)*(1-'NG Inputs'!$B$4)+IF($D$5=1,(1-IF(OR($D$5=2,MOD(A33,2)=1),1,0))*D32*'NG Inputs'!$B$10*(1-'NG Inputs'!$B$4)/2,0)-IF(MOD(A33,2)=0,INDEX($B$11:$D$25,B33,2)*(1-'NG Inputs'!$B$4),0) | E33: =E32+IF(OR($D$5=2,MOD(A33,2)=1),1,0)*(MIN('NG Inputs'!$B$12*E32/$C$5,'NG Inputs'!$B$9)*($B$5-'NG Inputs'!$B$5-'NG Inputs'!$B$6-2*'NG Inputs'!$B$7*SQRT(MIN('NG Inputs'!$B$12*E32/$C$5,'NG Inputs'!$B$9)/'NG Inputs'!$B$8))+MAX(E32-MIN('NG Inputs'!$B$12*E32/$C$5,'NG Inputs'!$B$9)*$C$5,0)*'NG Inputs'!$B$10/$D$5)*(1-'NG Inputs'!$B$4)+IF($D$5=1,(1-IF(OR($D$5=2,MOD(A33,2)=1),1,0))*E32*'NG Inputs'!$B$10*(1-'NG Inputs'!$B$4)/2,0)-IF(MOD(A33,2)=0,INDEX($B$11:$D$25,B33,3)*(1-'NG Inputs'!$B$4),0) | F33: =F32+IF(OR($D$6=2,MOD(A33,2)=1),1,0)*(MIN('NG Inputs'!$B$12*F32/$C$6,'NG Inputs'!$B$9)*($B$6-'NG Inputs'!$B$5-'NG Inputs'!$B$6-2*'NG Inputs'!$B$7*SQRT(MIN('NG Inputs'!$B$12*F32/$C$6,'NG Inputs'!$B$9)/'NG Inputs'!$B$8))+MAX(F32-MIN('NG Inputs'!$B$12*F32/$C$6,'NG Inputs'!$B$9)*$C$6,0)*'NG Inputs'!$B$10/$D$6)*(1-'NG Inputs'!$B$4)+IF($D$6=1,(1-IF(OR($D$6=2,MOD(A33,2)=1),1,0))*F32*'NG Inputs'!$B$10*(1-'NG Inputs'!$B$4)/2,0)-IF(MOD(A33,2)=0,INDEX($B$11:$D$25,B33,1)*(1-'NG Inputs'!$B$4),0) | G33: =G32+IF(OR($D$6=2,MOD(A33,2)=1),1,0)*(MIN('NG Inputs'!$B$12*G32/$C$6,'NG Inputs'!$B$9)*($B$6-'NG Inputs'!$B$5-'NG Inputs'!$B$6-2*'NG Inputs'!$B$7*SQRT(MIN('NG Inputs'!$B$12*G32/$C$6,'NG Inputs'!$B$9)/'NG Inputs'!$B$8))+MAX(G32-MIN('NG Inputs'!$B$12*G32/$C$6,'NG Inputs'!$B$9)*$C$6,0)*'NG Inputs'!$B$10/$D$6)*(1-'NG Inputs'!$B$4)+IF($D$6=1,(1-IF(OR($D$6=2,MOD(A33,2)=1),1,0))*G32*'NG Inputs'!$B$10*(1-'NG Inputs'!$B$4)/2,0)-IF(MOD(A33,2)=0,INDEX($B$11:$D$25,B33,2)*(1-'NG Inputs'!$B$4),0) | H33: =H32+IF(OR($D$6=2,MOD(A33,2)=1),1,0)*(MIN('NG Inputs'!$B$12*H32/$C$6,'NG Inputs'!$B$9)*($B$6-'NG Inputs'!$B$5-'NG Inputs'!$B$6-2*'NG Inputs'!$B$7*SQRT(MIN('NG Inputs'!$B$12*H32/$C$6,'NG Inputs'!$B$9)/'NG Inputs'!$B$8))+MAX(H32-MIN('NG Inputs'!$B$12*H32/$C$6,'NG Inputs'!$B$9)*$C$6,0)*'NG Inputs'!$B$10/$D$6)*(1-'NG Inputs'!$B$4)+IF($D$6=1,(1-IF(OR($D$6=2,MOD(A33,2)=1),1,0))*H32*'NG Inputs'!$B$10*(1-'NG Inputs'!$B$4)/2,0)-IF(MOD(A33,2)=0,INDEX($B$11:$D$25,B33,3)*(1-'NG Inputs'!$B$4),0) | I33: =I32+IF(OR($D$7=2,MOD(A33,2)=1),1,0)*(MIN('NG Inputs'!$B$12*I32/$C$7,'NG Inputs'!$B$9)*($B$7-'NG Inputs'!$B$5-'NG Inputs'!$B$6-2*'NG Inputs'!$B$7*SQRT(MIN('NG Inputs'!$B$12*I32/$C$7,'NG Inputs'!$B$9)/'NG Inputs'!$B$8))+MAX(I32-MIN('NG Inputs'!$B$12*I32/$C$7,'NG Inputs'!$B$9)*$C$7,0)*'NG Inputs'!$B$10/$D$7)*(1-'NG Inputs'!$B$4)+IF($D$7=1,(1-IF(OR($D$7=2,MOD(A33,2)=1),1,0))*I32*'NG Inputs'!$B$10*(1-'NG Inputs'!$B$4)/2,0)-IF(MOD(A33,2)=0,INDEX($B$11:$D$25,B33,1)*(1-'NG Inputs'!$B$4),0) | J33: =J32+IF(OR($D$7=2,MOD(A33,2)=1),1,0)*(MIN('NG Inputs'!$B$12*J32/$C$7,'NG Inputs'!$B$9)*($B$7-'NG Inputs'!$B$5-'NG Inputs'!$B$6-2*'NG Inputs'!$B$7*SQRT(MIN('NG Inputs'!$B$12*J32/$C$7,'NG Inputs'!$B$9)/'NG Inputs'!$B$8))+MAX(J32-MIN('NG Inputs'!$B$12*J32/$C$7,'NG Inputs'!$B$9)*$C$7,0)*'NG Inputs'!$B$10/$D$7)*(1-'NG Inputs'!$B$4)+IF($D$7=1,(1-IF(OR($D$7=2,MOD(A33,2)=1),1,0))*J32*'NG Inputs'!$B$10*(1-'NG Inputs'!$B$4)/2,0)-IF(MOD(A33,2)=0,INDEX($B$11:$D$25,B33,2)*(1-'NG Inputs'!$B$4),0) | K33: =K32+IF(OR($D$7=2,MOD(A33,2)=1),1,0)*(MIN('NG Inputs'!$B$12*K32/$C$7,'NG Inputs'!$B$9)*($B$7-'NG Inputs'!$B$5-'NG Inputs'!$B$6-2*'NG Inputs'!$B$7*SQRT(MIN('NG Inputs'!$B$12*K32/$C$7,'NG Inputs'!$B$9)/'NG Inputs'!$B$8))+MAX(K32-MIN('NG Inputs'!$B$12*K32/$C$7,'NG Inputs'!$B$9)*$C$7,0)*'NG Inputs'!$B$10/$D$7)*(1-'NG Inputs'!$B$4)+IF($D$7=1,(1-IF(OR($D$7=2,MOD(A33,2)=1),1,0))*K32*'NG Inputs'!$B$10*(1-'NG Inputs'!$B$4)/2,0)-IF(MOD(A33,2)=0,INDEX($B$11:$D$25,B33,3)*(1-'NG Inputs'!$B$4),0)
A34: 6 | B34: =ROUNDUP(A34/2,0) | C34: =C33+IF(OR($D$5=2,MOD(A34,2)=1),1,0)*(MIN('NG Inputs'!$B$12*C33/$C$5,'NG Inputs'!$B$9)*($B$5-'NG Inputs'!$B$5-'NG Inputs'!$B$6-2*'NG Inputs'!$B$7*SQRT(MIN('NG Inputs'!$B$12*C33/$C$5,'NG Inputs'!$B$9)/'NG Inputs'!$B$8))+MAX(C33-MIN('NG Inputs'!$B$12*C33/$C$5,'NG Inputs'!$B$9)*$C$5,0)*'NG Inputs'!$B$10/$D$5)*(1-'NG Inputs'!$B$4)+IF($D$5=1,(1-IF(OR($D$5=2,MOD(A34,2)=1),1,0))*C33*'NG Inputs'!$B$10*(1-'NG Inputs'!$B$4)/2,0)-IF(MOD(A34,2)=0,INDEX($B$11:$D$25,B34,1)*(1-'NG Inputs'!$B$4),0) | D34: =D33+IF(OR($D$5=2,MOD(A34,2)=1),1,0)*(MIN('NG Inputs'!$B$12*D33/$C$5,'NG Inputs'!$B$9)*($B$5-'NG Inputs'!$B$5-'NG Inputs'!$B$6-2*'NG Inputs'!$B$7*SQRT(MIN('NG Inputs'!$B$12*D33/$C$5,'NG Inputs'!$B$9)/'NG Inputs'!$B$8))+MAX(D33-MIN('NG Inputs'!$B$12*D33/$C$5,'NG Inputs'!$B$9)*$C$5,0)*'NG Inputs'!$B$10/$D$5)*(1-'NG Inputs'!$B$4)+IF($D$5=1,(1-IF(OR($D$5=2,MOD(A34,2)=1),1,0))*D33*'NG Inputs'!$B$10*(1-'NG Inputs'!$B$4)/2,0)-IF(MOD(A34,2)=0,INDEX($B$11:$D$25,B34,2)*(1-'NG Inputs'!$B$4),0) | E34: =E33+IF(OR($D$5=2,MOD(A34,2)=1),1,0)*(MIN('NG Inputs'!$B$12*E33/$C$5,'NG Inputs'!$B$9)*($B$5-'NG Inputs'!$B$5-'NG Inputs'!$B$6-2*'NG Inputs'!$B$7*SQRT(MIN('NG Inputs'!$B$12*E33/$C$5,'NG Inputs'!$B$9)/'NG Inputs'!$B$8))+MAX(E33-MIN('NG Inputs'!$B$12*E33/$C$5,'NG Inputs'!$B$9)*$C$5,0)*'NG Inputs'!$B$10/$D$5)*(1-'NG Inputs'!$B$4)+IF($D$5=1,(1-IF(OR($D$5=2,MOD(A34,2)=1),1,0))*E33*'NG Inputs'!$B$10*(1-'NG Inputs'!$B$4)/2,0)-IF(MOD(A34,2)=0,INDEX($B$11:$D$25,B34,3)*(1-'NG Inputs'!$B$4),0) | F34: =F33+IF(OR($D$6=2,MOD(A34,2)=1),1,0)*(MIN('NG Inputs'!$B$12*F33/$C$6,'NG Inputs'!$B$9)*($B$6-'NG Inputs'!$B$5-'NG Inputs'!$B$6-2*'NG Inputs'!$B$7*SQRT(MIN('NG Inputs'!$B$12*F33/$C$6,'NG Inputs'!$B$9)/'NG Inputs'!$B$8))+MAX(F33-MIN('NG Inputs'!$B$12*F33/$C$6,'NG Inputs'!$B$9)*$C$6,0)*'NG Inputs'!$B$10/$D$6)*(1-'NG Inputs'!$B$4)+IF($D$6=1,(1-IF(OR($D$6=2,MOD(A34,2)=1),1,0))*F33*'NG Inputs'!$B$10*(1-'NG Inputs'!$B$4)/2,0)-IF(MOD(A34,2)=0,INDEX($B$11:$D$25,B34,1)*(1-'NG Inputs'!$B$4),0) | G34: =G33+IF(OR($D$6=2,MOD(A34,2)=1),1,0)*(MIN('NG Inputs'!$B$12*G33/$C$6,'NG Inputs'!$B$9)*($B$6-'NG Inputs'!$B$5-'NG Inputs'!$B$6-2*'NG Inputs'!$B$7*SQRT(MIN('NG Inputs'!$B$12*G33/$C$6,'NG Inputs'!$B$9)/'NG Inputs'!$B$8))+MAX(G33-MIN('NG Inputs'!$B$12*G33/$C$6,'NG Inputs'!$B$9)*$C$6,0)*'NG Inputs'!$B$10/$D$6)*(1-'NG Inputs'!$B$4)+IF($D$6=1,(1-IF(OR($D$6=2,MOD(A34,2)=1),1,0))*G33*'NG Inputs'!$B$10*(1-'NG Inputs'!$B$4)/2,0)-IF(MOD(A34,2)=0,INDEX($B$11:$D$25,B34,2)*(1-'NG Inputs'!$B$4),0) | H34: =H33+IF(OR($D$6=2,MOD(A34,2)=1),1,0)*(MIN('NG Inputs'!$B$12*H33/$C$6,'NG Inputs'!$B$9)*($B$6-'NG Inputs'!$B$5-'NG Inputs'!$B$6-2*'NG Inputs'!$B$7*SQRT(MIN('NG Inputs'!$B$12*H33/$C$6,'NG Inputs'!$B$9)/'NG Inputs'!$B$8))+MAX(H33-MIN('NG Inputs'!$B$12*H33/$C$6,'NG Inputs'!$B$9)*$C$6,0)*'NG Inputs'!$B$10/$D$6)*(1-'NG Inputs'!$B$4)+IF($D$6=1,(1-IF(OR($D$6=2,MOD(A34,2)=1),1,0))*H33*'NG Inputs'!$B$10*(1-'NG Inputs'!$B$4)/2,0)-IF(MOD(A34,2)=0,INDEX($B$11:$D$25,B34,3)*(1-'NG Inputs'!$B$4),0) | I34: =I33+IF(OR($D$7=2,MOD(A34,2)=1),1,0)*(MIN('NG Inputs'!$B$12*I33/$C$7,'NG Inputs'!$B$9)*($B$7-'NG Inputs'!$B$5-'NG Inputs'!$B$6-2*'NG Inputs'!$B$7*SQRT(MIN('NG Inputs'!$B$12*I33/$C$7,'NG Inputs'!$B$9)/'NG Inputs'!$B$8))+MAX(I33-MIN('NG Inputs'!$B$12*I33/$C$7,'NG Inputs'!$B$9)*$C$7,0)*'NG Inputs'!$B$10/$D$7)*(1-'NG Inputs'!$B$4)+IF($D$7=1,(1-IF(OR($D$7=2,MOD(A34,2)=1),1,0))*I33*'NG Inputs'!$B$10*(1-'NG Inputs'!$B$4)/2,0)-IF(MOD(A34,2)=0,INDEX($B$11:$D$25,B34,1)*(1-'NG Inputs'!$B$4),0) | J34: =J33+IF(OR($D$7=2,MOD(A34,2)=1),1,0)*(MIN('NG Inputs'!$B$12*J33/$C$7,'NG Inputs'!$B$9)*($B$7-'NG Inputs'!$B$5-'NG Inputs'!$B$6-2*'NG Inputs'!$B$7*SQRT(MIN('NG Inputs'!$B$12*J33/$C$7,'NG Inputs'!$B$9)/'NG Inputs'!$B$8))+MAX(J33-MIN('NG Inputs'!$B$12*J33/$C$7,'NG Inputs'!$B$9)*$C$7,0)*'NG Inputs'!$B$10/$D$7)*(1-'NG Inputs'!$B$4)+IF($D$7=1,(1-IF(OR($D$7=2,MOD(A34,2)=1),1,0))*J33*'NG Inputs'!$B$10*(1-'NG Inputs'!$B$4)/2,0)-IF(MOD(A34,2)=0,INDEX($B$11:$D$25,B34,2)*(1-'NG Inputs'!$B$4),0) | K34: =K33+IF(OR($D$7=2,MOD(A34,2)=1),1,0)*(MIN('NG Inputs'!$B$12*K33/$C$7,'NG Inputs'!$B$9)*($B$7-'NG Inputs'!$B$5-'NG Inputs'!$B$6-2*'NG Inputs'!$B$7*SQRT(MIN('NG Inputs'!$B$12*K33/$C$7,'NG Inputs'!$B$9)/'NG Inputs'!$B$8))+MAX(K33-MIN('NG Inputs'!$B$12*K33/$C$7,'NG Inputs'!$B$9)*$C$7,0)*'NG Inputs'!$B$10/$D$7)*(1-'NG Inputs'!$B$4)+IF($D$7=1,(1-IF(OR($D$7=2,MOD(A34,2)=1),1,0))*K33*'NG Inputs'!$B$10*(1-'NG Inputs'!$B$4)/2,0)-IF(MOD(A34,2)=0,INDEX($B$11:$D$25,B34,3)*(1-'NG Inputs'!$B$4),0)
A35: 7 | B35: =ROUNDUP(A35/2,0) | C35: =C34+IF(OR($D$5=2,MOD(A35,2)=1),1,0)*(MIN('NG Inputs'!$B$12*C34/$C$5,'NG Inputs'!$B$9)*($B$5-'NG Inputs'!$B$5-'NG Inputs'!$B$6-2*'NG Inputs'!$B$7*SQRT(MIN('NG Inputs'!$B$12*C34/$C$5,'NG Inputs'!$B$9)/'NG Inputs'!$B$8))+MAX(C34-MIN('NG Inputs'!$B$12*C34/$C$5,'NG Inputs'!$B$9)*$C$5,0)*'NG Inputs'!$B$10/$D$5)*(1-'NG Inputs'!$B$4)+IF($D$5=1,(1-IF(OR($D$5=2,MOD(A35,2)=1),1,0))*C34*'NG Inputs'!$B$10*(1-'NG Inputs'!$B$4)/2,0)-IF(MOD(A35,2)=0,INDEX($B$11:$D$25,B35,1)*(1-'NG Inputs'!$B$4),0) | D35: =D34+IF(OR($D$5=2,MOD(A35,2)=1),1,0)*(MIN('NG Inputs'!$B$12*D34/$C$5,'NG Inputs'!$B$9)*($B$5-'NG Inputs'!$B$5-'NG Inputs'!$B$6-2*'NG Inputs'!$B$7*SQRT(MIN('NG Inputs'!$B$12*D34/$C$5,'NG Inputs'!$B$9)/'NG Inputs'!$B$8))+MAX(D34-MIN('NG Inputs'!$B$12*D34/$C$5,'NG Inputs'!$B$9)*$C$5,0)*'NG Inputs'!$B$10/$D$5)*(1-'NG Inputs'!$B$4)+IF($D$5=1,(1-IF(OR($D$5=2,MOD(A35,2)=1),1,0))*D34*'NG Inputs'!$B$10*(1-'NG Inputs'!$B$4)/2,0)-IF(MOD(A35,2)=0,INDEX($B$11:$D$25,B35,2)*(1-'NG Inputs'!$B$4),0) | E35: =E34+IF(OR($D$5=2,MOD(A35,2)=1),1,0)*(MIN('NG Inputs'!$B$12*E34/$C$5,'NG Inputs'!$B$9)*($B$5-'NG Inputs'!$B$5-'NG Inputs'!$B$6-2*'NG Inputs'!$B$7*SQRT(MIN('NG Inputs'!$B$12*E34/$C$5,'NG Inputs'!$B$9)/'NG Inputs'!$B$8))+MAX(E34-MIN('NG Inputs'!$B$12*E34/$C$5,'NG Inputs'!$B$9)*$C$5,0)*'NG Inputs'!$B$10/$D$5)*(1-'NG Inputs'!$B$4)+IF($D$5=1,(1-IF(OR($D$5=2,MOD(A35,2)=1),1,0))*E34*'NG Inputs'!$B$10*(1-'NG Inputs'!$B$4)/2,0)-IF(MOD(A35,2)=0,INDEX($B$11:$D$25,B35,3)*(1-'NG Inputs'!$B$4),0) | F35: =F34+IF(OR($D$6=2,MOD(A35,2)=1),1,0)*(MIN('NG Inputs'!$B$12*F34/$C$6,'NG Inputs'!$B$9)*($B$6-'NG Inputs'!$B$5-'NG Inputs'!$B$6-2*'NG Inputs'!$B$7*SQRT(MIN('NG Inputs'!$B$12*F34/$C$6,'NG Inputs'!$B$9)/'NG Inputs'!$B$8))+MAX(F34-MIN('NG Inputs'!$B$12*F34/$C$6,'NG Inputs'!$B$9)*$C$6,0)*'NG Inputs'!$B$10/$D$6)*(1-'NG Inputs'!$B$4)+IF($D$6=1,(1-IF(OR($D$6=2,MOD(A35,2)=1),1,0))*F34*'NG Inputs'!$B$10*(1-'NG Inputs'!$B$4)/2,0)-IF(MOD(A35,2)=0,INDEX($B$11:$D$25,B35,1)*(1-'NG Inputs'!$B$4),0) | G35: =G34+IF(OR($D$6=2,MOD(A35,2)=1),1,0)*(MIN('NG Inputs'!$B$12*G34/$C$6,'NG Inputs'!$B$9)*($B$6-'NG Inputs'!$B$5-'NG Inputs'!$B$6-2*'NG Inputs'!$B$7*SQRT(MIN('NG Inputs'!$B$12*G34/$C$6,'NG Inputs'!$B$9)/'NG Inputs'!$B$8))+MAX(G34-MIN('NG Inputs'!$B$12*G34/$C$6,'NG Inputs'!$B$9)*$C$6,0)*'NG Inputs'!$B$10/$D$6)*(1-'NG Inputs'!$B$4)+IF($D$6=1,(1-IF(OR($D$6=2,MOD(A35,2)=1),1,0))*G34*'NG Inputs'!$B$10*(1-'NG Inputs'!$B$4)/2,0)-IF(MOD(A35,2)=0,INDEX($B$11:$D$25,B35,2)*(1-'NG Inputs'!$B$4),0) | H35: =H34+IF(OR($D$6=2,MOD(A35,2)=1),1,0)*(MIN('NG Inputs'!$B$12*H34/$C$6,'NG Inputs'!$B$9)*($B$6-'NG Inputs'!$B$5-'NG Inputs'!$B$6-2*'NG Inputs'!$B$7*SQRT(MIN('NG Inputs'!$B$12*H34/$C$6,'NG Inputs'!$B$9)/'NG Inputs'!$B$8))+MAX(H34-MIN('NG Inputs'!$B$12*H34/$C$6,'NG Inputs'!$B$9)*$C$6,0)*'NG Inputs'!$B$10/$D$6)*(1-'NG Inputs'!$B$4)+IF($D$6=1,(1-IF(OR($D$6=2,MOD(A35,2)=1),1,0))*H34*'NG Inputs'!$B$10*(1-'NG Inputs'!$B$4)/2,0)-IF(MOD(A35,2)=0,INDEX($B$11:$D$25,B35,3)*(1-'NG Inputs'!$B$4),0) | I35: =I34+IF(OR($D$7=2,MOD(A35,2)=1),1,0)*(MIN('NG Inputs'!$B$12*I34/$C$7,'NG Inputs'!$B$9)*($B$7-'NG Inputs'!$B$5-'NG Inputs'!$B$6-2*'NG Inputs'!$B$7*SQRT(MIN('NG Inputs'!$B$12*I34/$C$7,'NG Inputs'!$B$9)/'NG Inputs'!$B$8))+MAX(I34-MIN('NG Inputs'!$B$12*I34/$C$7,'NG Inputs'!$B$9)*$C$7,0)*'NG Inputs'!$B$10/$D$7)*(1-'NG Inputs'!$B$4)+IF($D$7=1,(1-IF(OR($D$7=2,MOD(A35,2)=1),1,0))*I34*'NG Inputs'!$B$10*(1-'NG Inputs'!$B$4)/2,0)-IF(MOD(A35,2)=0,INDEX($B$11:$D$25,B35,1)*(1-'NG Inputs'!$B$4),0) | J35: =J34+IF(OR($D$7=2,MOD(A35,2)=1),1,0)*(MIN('NG Inputs'!$B$12*J34/$C$7,'NG Inputs'!$B$9)*($B$7-'NG Inputs'!$B$5-'NG Inputs'!$B$6-2*'NG Inputs'!$B$7*SQRT(MIN('NG Inputs'!$B$12*J34/$C$7,'NG Inputs'!$B$9)/'NG Inputs'!$B$8))+MAX(J34-MIN('NG Inputs'!$B$12*J34/$C$7,'NG Inputs'!$B$9)*$C$7,0)*'NG Inputs'!$B$10/$D$7)*(1-'NG Inputs'!$B$4)+IF($D$7=1,(1-IF(OR($D$7=2,MOD(A35,2)=1),1,0))*J34*'NG Inputs'!$B$10*(1-'NG Inputs'!$B$4)/2,0)-IF(MOD(A35,2)=0,INDEX($B$11:$D$25,B35,2)*(1-'NG Inputs'!$B$4),0) | K35: =K34+IF(OR($D$7=2,MOD(A35,2)=1),1,0)*(MIN('NG Inputs'!$B$12*K34/$C$7,'NG Inputs'!$B$9)*($B$7-'NG Inputs'!$B$5-'NG Inputs'!$B$6-2*'NG Inputs'!$B$7*SQRT(MIN('NG Inputs'!$B$12*K34/$C$7,'NG Inputs'!$B$9)/'NG Inputs'!$B$8))+MAX(K34-MIN('NG Inputs'!$B$12*K34/$C$7,'NG Inputs'!$B$9)*$C$7,0)*'NG Inputs'!$B$10/$D$7)*(1-'NG Inputs'!$B$4)+IF($D$7=1,(1-IF(OR($D$7=2,MOD(A35,2)=1),1,0))*K34*'NG Inputs'!$B$10*(1-'NG Inputs'!$B$4)/2,0)-IF(MOD(A35,2)=0,INDEX($B$11:$D$25,B35,3)*(1-'NG Inputs'!$B$4),0)
A36: 8 | B36: =ROUNDUP(A36/2,0) | C36: =C35+IF(OR($D$5=2,MOD(A36,2)=1),1,0)*(MIN('NG Inputs'!$B$12*C35/$C$5,'NG Inputs'!$B$9)*($B$5-'NG Inputs'!$B$5-'NG Inputs'!$B$6-2*'NG Inputs'!$B$7*SQRT(MIN('NG Inputs'!$B$12*C35/$C$5,'NG Inputs'!$B$9)/'NG Inputs'!$B$8))+MAX(C35-MIN('NG Inputs'!$B$12*C35/$C$5,'NG Inputs'!$B$9)*$C$5,0)*'NG Inputs'!$B$10/$D$5)*(1-'NG Inputs'!$B$4)+IF($D$5=1,(1-IF(OR($D$5=2,MOD(A36,2)=1),1,0))*C35*'NG Inputs'!$B$10*(1-'NG Inputs'!$B$4)/2,0)-IF(MOD(A36,2)=0,INDEX($B$11:$D$25,B36,1)*(1-'NG Inputs'!$B$4),0) | D36: =D35+IF(OR($D$5=2,MOD(A36,2)=1),1,0)*(MIN('NG Inputs'!$B$12*D35/$C$5,'NG Inputs'!$B$9)*($B$5-'NG Inputs'!$B$5-'NG Inputs'!$B$6-2*'NG Inputs'!$B$7*SQRT(MIN('NG Inputs'!$B$12*D35/$C$5,'NG Inputs'!$B$9)/'NG Inputs'!$B$8))+MAX(D35-MIN('NG Inputs'!$B$12*D35/$C$5,'NG Inputs'!$B$9)*$C$5,0)*'NG Inputs'!$B$10/$D$5)*(1-'NG Inputs'!$B$4)+IF($D$5=1,(1-IF(OR($D$5=2,MOD(A36,2)=1),1,0))*D35*'NG Inputs'!$B$10*(1-'NG Inputs'!$B$4)/2,0)-IF(MOD(A36,2)=0,INDEX($B$11:$D$25,B36,2)*(1-'NG Inputs'!$B$4),0) | E36: =E35+IF(OR($D$5=2,MOD(A36,2)=1),1,0)*(MIN('NG Inputs'!$B$12*E35/$C$5,'NG Inputs'!$B$9)*($B$5-'NG Inputs'!$B$5-'NG Inputs'!$B$6-2*'NG Inputs'!$B$7*SQRT(MIN('NG Inputs'!$B$12*E35/$C$5,'NG Inputs'!$B$9)/'NG Inputs'!$B$8))+MAX(E35-MIN('NG Inputs'!$B$12*E35/$C$5,'NG Inputs'!$B$9)*$C$5,0)*'NG Inputs'!$B$10/$D$5)*(1-'NG Inputs'!$B$4)+IF($D$5=1,(1-IF(OR($D$5=2,MOD(A36,2)=1),1,0))*E35*'NG Inputs'!$B$10*(1-'NG Inputs'!$B$4)/2,0)-IF(MOD(A36,2)=0,INDEX($B$11:$D$25,B36,3)*(1-'NG Inputs'!$B$4),0) | F36: =F35+IF(OR($D$6=2,MOD(A36,2)=1),1,0)*(MIN('NG Inputs'!$B$12*F35/$C$6,'NG Inputs'!$B$9)*($B$6-'NG Inputs'!$B$5-'NG Inputs'!$B$6-2*'NG Inputs'!$B$7*SQRT(MIN('NG Inputs'!$B$12*F35/$C$6,'NG Inputs'!$B$9)/'NG Inputs'!$B$8))+MAX(F35-MIN('NG Inputs'!$B$12*F35/$C$6,'NG Inputs'!$B$9)*$C$6,0)*'NG Inputs'!$B$10/$D$6)*(1-'NG Inputs'!$B$4)+IF($D$6=1,(1-IF(OR($D$6=2,MOD(A36,2)=1),1,0))*F35*'NG Inputs'!$B$10*(1-'NG Inputs'!$B$4)/2,0)-IF(MOD(A36,2)=0,INDEX($B$11:$D$25,B36,1)*(1-'NG Inputs'!$B$4),0) | G36: =G35+IF(OR($D$6=2,MOD(A36,2)=1),1,0)*(MIN('NG Inputs'!$B$12*G35/$C$6,'NG Inputs'!$B$9)*($B$6-'NG Inputs'!$B$5-'NG Inputs'!$B$6-2*'NG Inputs'!$B$7*SQRT(MIN('NG Inputs'!$B$12*G35/$C$6,'NG Inputs'!$B$9)/'NG Inputs'!$B$8))+MAX(G35-MIN('NG Inputs'!$B$12*G35/$C$6,'NG Inputs'!$B$9)*$C$6,0)*'NG Inputs'!$B$10/$D$6)*(1-'NG Inputs'!$B$4)+IF($D$6=1,(1-IF(OR($D$6=2,MOD(A36,2)=1),1,0))*G35*'NG Inputs'!$B$10*(1-'NG Inputs'!$B$4)/2,0)-IF(MOD(A36,2)=0,INDEX($B$11:$D$25,B36,2)*(1-'NG Inputs'!$B$4),0) | H36: =H35+IF(OR($D$6=2,MOD(A36,2)=1),1,0)*(MIN('NG Inputs'!$B$12*H35/$C$6,'NG Inputs'!$B$9)*($B$6-'NG Inputs'!$B$5-'NG Inputs'!$B$6-2*'NG Inputs'!$B$7*SQRT(MIN('NG Inputs'!$B$12*H35/$C$6,'NG Inputs'!$B$9)/'NG Inputs'!$B$8))+MAX(H35-MIN('NG Inputs'!$B$12*H35/$C$6,'NG Inputs'!$B$9)*$C$6,0)*'NG Inputs'!$B$10/$D$6)*(1-'NG Inputs'!$B$4)+IF($D$6=1,(1-IF(OR($D$6=2,MOD(A36,2)=1),1,0))*H35*'NG Inputs'!$B$10*(1-'NG Inputs'!$B$4)/2,0)-IF(MOD(A36,2)=0,INDEX($B$11:$D$25,B36,3)*(1-'NG Inputs'!$B$4),0) | I36: =I35+IF(OR($D$7=2,MOD(A36,2)=1),1,0)*(MIN('NG Inputs'!$B$12*I35/$C$7,'NG Inputs'!$B$9)*($B$7-'NG Inputs'!$B$5-'NG Inputs'!$B$6-2*'NG Inputs'!$B$7*SQRT(MIN('NG Inputs'!$B$12*I35/$C$7,'NG Inputs'!$B$9)/'NG Inputs'!$B$8))+MAX(I35-MIN('NG Inputs'!$B$12*I35/$C$7,'NG Inputs'!$B$9)*$C$7,0)*'NG Inputs'!$B$10/$D$7)*(1-'NG Inputs'!$B$4)+IF($D$7=1,(1-IF(OR($D$7=2,MOD(A36,2)=1),1,0))*I35*'NG Inputs'!$B$10*(1-'NG Inputs'!$B$4)/2,0)-IF(MOD(A36,2)=0,INDEX($B$11:$D$25,B36,1)*(1-'NG Inputs'!$B$4),0) | J36: =J35+IF(OR($D$7=2,MOD(A36,2)=1),1,0)*(MIN('NG Inputs'!$B$12*J35/$C$7,'NG Inputs'!$B$9)*($B$7-'NG Inputs'!$B$5-'NG Inputs'!$B$6-2*'NG Inputs'!$B$7*SQRT(MIN('NG Inputs'!$B$12*J35/$C$7,'NG Inputs'!$B$9)/'NG Inputs'!$B$8))+MAX(J35-MIN('NG Inputs'!$B$12*J35/$C$7,'NG Inputs'!$B$9)*$C$7,0)*'NG Inputs'!$B$10/$D$7)*(1-'NG Inputs'!$B$4)+IF($D$7=1,(1-IF(OR($D$7=2,MOD(A36,2)=1),1,0))*J35*'NG Inputs'!$B$10*(1-'NG Inputs'!$B$4)/2,0)-IF(MOD(A36,2)=0,INDEX($B$11:$D$25,B36,2)*(1-'NG Inputs'!$B$4),0) | K36: =K35+IF(OR($D$7=2,MOD(A36,2)=1),1,0)*(MIN('NG Inputs'!$B$12*K35/$C$7,'NG Inputs'!$B$9)*($B$7-'NG Inputs'!$B$5-'NG Inputs'!$B$6-2*'NG Inputs'!$B$7*SQRT(MIN('NG Inputs'!$B$12*K35/$C$7,'NG Inputs'!$B$9)/'NG Inputs'!$B$8))+MAX(K35-MIN('NG Inputs'!$B$12*K35/$C$7,'NG Inputs'!$B$9)*$C$7,0)*'NG Inputs'!$B$10/$D$7)*(1-'NG Inputs'!$B$4)+IF($D$7=1,(1-IF(OR($D$7=2,MOD(A36,2)=1),1,0))*K35*'NG Inputs'!$B$10*(1-'NG Inputs'!$B$4)/2,0)-IF(MOD(A36,2)=0,INDEX($B$11:$D$25,B36,3)*(1-'NG Inputs'!$B$4),0)
A37: 9 | B37: =ROUNDUP(A37/2,0) | C37: =C36+IF(OR($D$5=2,MOD(A37,2)=1),1,0)*(MIN('NG Inputs'!$B$12*C36/$C$5,'NG Inputs'!$B$9)*($B$5-'NG Inputs'!$B$5-'NG Inputs'!$B$6-2*'NG Inputs'!$B$7*SQRT(MIN('NG Inputs'!$B$12*C36/$C$5,'NG Inputs'!$B$9)/'NG Inputs'!$B$8))+MAX(C36-MIN('NG Inputs'!$B$12*C36/$C$5,'NG Inputs'!$B$9)*$C$5,0)*'NG Inputs'!$B$10/$D$5)*(1-'NG Inputs'!$B$4)+IF($D$5=1,(1-IF(OR($D$5=2,MOD(A37,2)=1),1,0))*C36*'NG Inputs'!$B$10*(1-'NG Inputs'!$B$4)/2,0)-IF(MOD(A37,2)=0,INDEX($B$11:$D$25,B37,1)*(1-'NG Inputs'!$B$4),0) | D37: =D36+IF(OR($D$5=2,MOD(A37,2)=1),1,0)*(MIN('NG Inputs'!$B$12*D36/$C$5,'NG Inputs'!$B$9)*($B$5-'NG Inputs'!$B$5-'NG Inputs'!$B$6-2*'NG Inputs'!$B$7*SQRT(MIN('NG Inputs'!$B$12*D36/$C$5,'NG Inputs'!$B$9)/'NG Inputs'!$B$8))+MAX(D36-MIN('NG Inputs'!$B$12*D36/$C$5,'NG Inputs'!$B$9)*$C$5,0)*'NG Inputs'!$B$10/$D$5)*(1-'NG Inputs'!$B$4)+IF($D$5=1,(1-IF(OR($D$5=2,MOD(A37,2)=1),1,0))*D36*'NG Inputs'!$B$10*(1-'NG Inputs'!$B$4)/2,0)-IF(MOD(A37,2)=0,INDEX($B$11:$D$25,B37,2)*(1-'NG Inputs'!$B$4),0) | E37: =E36+IF(OR($D$5=2,MOD(A37,2)=1),1,0)*(MIN('NG Inputs'!$B$12*E36/$C$5,'NG Inputs'!$B$9)*($B$5-'NG Inputs'!$B$5-'NG Inputs'!$B$6-2*'NG Inputs'!$B$7*SQRT(MIN('NG Inputs'!$B$12*E36/$C$5,'NG Inputs'!$B$9)/'NG Inputs'!$B$8))+MAX(E36-MIN('NG Inputs'!$B$12*E36/$C$5,'NG Inputs'!$B$9)*$C$5,0)*'NG Inputs'!$B$10/$D$5)*(1-'NG Inputs'!$B$4)+IF($D$5=1,(1-IF(OR($D$5=2,MOD(A37,2)=1),1,0))*E36*'NG Inputs'!$B$10*(1-'NG Inputs'!$B$4)/2,0)-IF(MOD(A37,2)=0,INDEX($B$11:$D$25,B37,3)*(1-'NG Inputs'!$B$4),0) | F37: =F36+IF(OR($D$6=2,MOD(A37,2)=1),1,0)*(MIN('NG Inputs'!$B$12*F36/$C$6,'NG Inputs'!$B$9)*($B$6-'NG Inputs'!$B$5-'NG Inputs'!$B$6-2*'NG Inputs'!$B$7*SQRT(MIN('NG Inputs'!$B$12*F36/$C$6,'NG Inputs'!$B$9)/'NG Inputs'!$B$8))+MAX(F36-MIN('NG Inputs'!$B$12*F36/$C$6,'NG Inputs'!$B$9)*$C$6,0)*'NG Inputs'!$B$10/$D$6)*(1-'NG Inputs'!$B$4)+IF($D$6=1,(1-IF(OR($D$6=2,MOD(A37,2)=1),1,0))*F36*'NG Inputs'!$B$10*(1-'NG Inputs'!$B$4)/2,0)-IF(MOD(A37,2)=0,INDEX($B$11:$D$25,B37,1)*(1-'NG Inputs'!$B$4),0) | G37: =G36+IF(OR($D$6=2,MOD(A37,2)=1),1,0)*(MIN('NG Inputs'!$B$12*G36/$C$6,'NG Inputs'!$B$9)*($B$6-'NG Inputs'!$B$5-'NG Inputs'!$B$6-2*'NG Inputs'!$B$7*SQRT(MIN('NG Inputs'!$B$12*G36/$C$6,'NG Inputs'!$B$9)/'NG Inputs'!$B$8))+MAX(G36-MIN('NG Inputs'!$B$12*G36/$C$6,'NG Inputs'!$B$9)*$C$6,0)*'NG Inputs'!$B$10/$D$6)*(1-'NG Inputs'!$B$4)+IF($D$6=1,(1-IF(OR($D$6=2,MOD(A37,2)=1),1,0))*G36*'NG Inputs'!$B$10*(1-'NG Inputs'!$B$4)/2,0)-IF(MOD(A37,2)=0,INDEX($B$11:$D$25,B37,2)*(1-'NG Inputs'!$B$4),0) | H37: =H36+IF(OR($D$6=2,MOD(A37,2)=1),1,0)*(MIN('NG Inputs'!$B$12*H36/$C$6,'NG Inputs'!$B$9)*($B$6-'NG Inputs'!$B$5-'NG Inputs'!$B$6-2*'NG Inputs'!$B$7*SQRT(MIN('NG Inputs'!$B$12*H36/$C$6,'NG Inputs'!$B$9)/'NG Inputs'!$B$8))+MAX(H36-MIN('NG Inputs'!$B$12*H36/$C$6,'NG Inputs'!$B$9)*$C$6,0)*'NG Inputs'!$B$10/$D$6)*(1-'NG Inputs'!$B$4)+IF($D$6=1,(1-IF(OR($D$6=2,MOD(A37,2)=1),1,0))*H36*'NG Inputs'!$B$10*(1-'NG Inputs'!$B$4)/2,0)-IF(MOD(A37,2)=0,INDEX($B$11:$D$25,B37,3)*(1-'NG Inputs'!$B$4),0) | I37: =I36+IF(OR($D$7=2,MOD(A37,2)=1),1,0)*(MIN('NG Inputs'!$B$12*I36/$C$7,'NG Inputs'!$B$9)*($B$7-'NG Inputs'!$B$5-'NG Inputs'!$B$6-2*'NG Inputs'!$B$7*SQRT(MIN('NG Inputs'!$B$12*I36/$C$7,'NG Inputs'!$B$9)/'NG Inputs'!$B$8))+MAX(I36-MIN('NG Inputs'!$B$12*I36/$C$7,'NG Inputs'!$B$9)*$C$7,0)*'NG Inputs'!$B$10/$D$7)*(1-'NG Inputs'!$B$4)+IF($D$7=1,(1-IF(OR($D$7=2,MOD(A37,2)=1),1,0))*I36*'NG Inputs'!$B$10*(1-'NG Inputs'!$B$4)/2,0)-IF(MOD(A37,2)=0,INDEX($B$11:$D$25,B37,1)*(1-'NG Inputs'!$B$4),0) | J37: =J36+IF(OR($D$7=2,MOD(A37,2)=1),1,0)*(MIN('NG Inputs'!$B$12*J36/$C$7,'NG Inputs'!$B$9)*($B$7-'NG Inputs'!$B$5-'NG Inputs'!$B$6-2*'NG Inputs'!$B$7*SQRT(MIN('NG Inputs'!$B$12*J36/$C$7,'NG Inputs'!$B$9)/'NG Inputs'!$B$8))+MAX(J36-MIN('NG Inputs'!$B$12*J36/$C$7,'NG Inputs'!$B$9)*$C$7,0)*'NG Inputs'!$B$10/$D$7)*(1-'NG Inputs'!$B$4)+IF($D$7=1,(1-IF(OR($D$7=2,MOD(A37,2)=1),1,0))*J36*'NG Inputs'!$B$10*(1-'NG Inputs'!$B$4)/2,0)-IF(MOD(A37,2)=0,INDEX($B$11:$D$25,B37,2)*(1-'NG Inputs'!$B$4),0) | K37: =K36+IF(OR($D$7=2,MOD(A37,2)=1),1,0)*(MIN('NG Inputs'!$B$12*K36/$C$7,'NG Inputs'!$B$9)*($B$7-'NG Inputs'!$B$5-'NG Inputs'!$B$6-2*'NG Inputs'!$B$7*SQRT(MIN('NG Inputs'!$B$12*K36/$C$7,'NG Inputs'!$B$9)/'NG Inputs'!$B$8))+MAX(K36-MIN('NG Inputs'!$B$12*K36/$C$7,'NG Inputs'!$B$9)*$C$7,0)*'NG Inputs'!$B$10/$D$7)*(1-'NG Inputs'!$B$4)+IF($D$7=1,(1-IF(OR($D$7=2,MOD(A37,2)=1),1,0))*K36*'NG Inputs'!$B$10*(1-'NG Inputs'!$B$4)/2,0)-IF(MOD(A37,2)=0,INDEX($B$11:$D$25,B37,3)*(1-'NG Inputs'!$B$4),0)
