Workbook

Sheet Engine Inputs
A1: REBUILT ENGINE · SHARED INPUTS
A2: Blue cells drive every NG scenario tab. Edit here; the whole model reprices.
A3: Parameter | B3: Value | C3: Basis
A4: Tax rate (115BAA per-trade) | B4: 0.25168 | C4: Flat 22%+10% surch+4% cess; applied per trade (conservative vs annual assessment)
A5: Roll + carry cost (% notional / trade) | B5: 0.005 | C5: PDF gives MARGIN term structure only, not price contango; 0.50% is a placeholder INPUT — replace with measured roll gaps
A6: Txn + brokerage RT (% notional) | B6: 0.0006 | C6: CTT 0.01% sell side + brokerage + stamp; round trip
A7: Daily realized vol (for impact) | B7: 0.028 | C7: ≈45% ann. vol (PDF leg avg) / √252
A8: ADV notional (₹) | B8: 37800000000 | C8: ≈100,000 lots/day (PDF 2025-26 legs) × 1,250 mmBtu × ₹302.4 ≈ ₹3,780 Cr
A9: Max notional per position (₹) | B9: 3780000000 | C9: 10% of ADV: ≤2%/day participation × ~5-day entry+exit. HARD liquidity ceiling
A10: Idle-capital yield (liquid fund) | B10: 0.065 | C10: Undeployable capital above ceiling parked in liquid funds
A11: GIFT gateway capital (₹) | B11: 200000000 | C11: ₹20 Cr — corporate wrapper inflection from US ETF tab
A12: Deployment fraction of corpus | B12: 1 | C12: Set <1 to apply Kelly sizing from Kelly tab

Sheet Margin-Move Link
A1: DYNAMIC MARGIN ↔ MOVE LINK
A2: 123 contract legs (2020-2026) from the PDF Leg Dynamics table — kills the Static Margin Fallacy.
A4: Year | B4: Move % | C4: Avg Margin % during leg | D4: |Move| % | E4: Lev. Eff. (|move|/margin)
A5: 2020 | B5: -0.2431 | C5: 0.1412 | D5: =ABS(B5) -> 0.2431 | E5: =D5/C5 -> 1.7216714
A6: 2020 | B6: -0.1927 | C6: 0.1153 | D6: =ABS(B6) -> 0.1927 | E6: =D6/C6 -> 1.6712923
A7: 2020 | B7: 0.1746 | C7: 0.1417 | D7: =ABS(B7) -> 0.1746 | E7: =D7/C7 -> 1.2321807
A8: 2020 | B8: 0.1665 | C8: 0.1297 | D8: =ABS(B8) -> 0.1665 | E8: =D8/C8 -> 1.2837317
A9: 2020 | B9: -0.1842 | C9: 0.1728 | D9: =ABS(B9) -> 0.1842 | E9: =D9/C9 -> 1.0659722
A10: 2020 | B10: -0.1901 | C10: 0.1709 | D10: =ABS(B10) -> 0.1901 | E10: =D10/C10 -> 1.1123464
A11: 2020 | B11: 0.2155 | C11: 0.2316 | D11: =ABS(B11) -> 0.2155 | E11: =D11/C11 -> 0.93048359
A12: 2020 | B12: 0.2158 | C12: 0.2428 | D12: =ABS(B12) -> 0.2158 | E12: =D12/C12 -> 0.88879736
A13: 2020 | B13: -0.2978 | C13: 0.2164 | D13: =ABS(B13) -> 0.2978 | E13: =D13/C13 -> 1.3761553
A14: 2020 | B14: -0.2316 | C14: 0.2691 | D14: =ABS(B14) -> 0.2316 | E14: =D14/C14 -> 0.8606466
A15: 2020 | B15: -0.1927 | C15: 0.1675 | D15: =ABS(B15) -> 0.1927 | E15: =D15/C15 -> 1.1504478
A16: 2020 | B16: 0.209 | C16: 0.2228 | D16: =ABS(B16) -> 0.209 | E16: =D16/C16 -> 0.93806104
... A127: 2026 | B127: 0.1876 | C127: 0.1644 | D127: =ABS(B127) -> 0.1876 | E127: =D127/C127 -> 1.1411192
A130: BUCKET STATISTICS (live formulas)
A131: Bucket |move| | B131: n legs | C131: Avg |move| | D131: Avg margin during leg | E131: Avg Lev. Eff. | F131: Implied gross ROC (avg|move|/avg margin)
A132: 15–20% | B132: =COUNTIFS(D5:D127,">="&0.15,D5:D127,"<"&0.2) -> 42 | C132: =AVERAGEIFS(D5:D127,D5:D127,">="&0.15,D5:D127,"<"&0.2) -> 0.17562619 | D132: =AVERAGEIFS(C5:C127,D5:D127,">="&0.15,D5:D127,"<"&0.2) -> 0.21009048 | E132: =AVERAGEIFS(E5:E127,D5:D127,">="&0.15,D5:D127,"<"&0.2) -> 0.91175104 | F132: =C132/D132 -> 0.83595503
A133: 20–25% | B133: =COUNTIFS(D5:D127,">="&0.2,D5:D127,"<"&0.25) -> 26 | C133: =AVERAGEIFS(D5:D127,D5:D127,">="&0.2,D5:D127,"<"&0.25) -> 0.22343462 | D133: =AVERAGEIFS(C5:C127,D5:D127,">="&0.2,D5:D127,"<"&0.25) -> 0.21355 | E133: =AVERAGEIFS(E5:E127,D5:D127,">="&0.2,D5:D127,"<"&0.25) -> 1.1036244 | F133: =C133/D133 -> 1.0462871
A134: 25–30% | B134: =COUNTIFS(D5:D127,">="&0.25,D5:D127,"<"&0.3) -> 17 | C134: =AVERAGEIFS(D5:D127,D5:D127,">="&0.25,D5:D127,"<"&0.3) -> 0.27347059 | D134: =AVERAGEIFS(C5:C127,D5:D127,">="&0.25,D5:D127,"<"&0.3) -> 0.27272941 | E134: =AVERAGEIFS(E5:E127,D5:D127,">="&0.25,D5:D127,"<"&0.3) -> 1.0640057 | F134: =C134/D134 -> 1.0027176
A135: ≥30% | B135: =COUNTIFS(D5:D127,">="&0.3,D5:D127,"<"&10) -> 38 | C135: =AVERAGEIFS(D5:D127,D5:D127,">="&0.3,D5:D127,"<"&10) -> 0.43265263 | D135: =AVERAGEIFS(C5:C127,D5:D127,">="&0.3,D5:D127,"<"&10) -> 0.25867632 | E135: =AVERAGEIFS(E5:E127,D5:D127,">="&0.3,D5:D127,"<"&10) -> 1.7892979 | F135: =C135/D135 -> 1.6725638
A137: Correlation |move| vs margin | B137: =CORREL(D5:D127,C5:C127) -> 0.29945113
A138: Linear fit: margin = a + b·|move| | B138: =INTERCEPT(C5:C127,D5:D127) -> 0.18662725 | C138: =SLOPE(C5:C127,D5:D127) -> 0.17175723

Sheet Rebuilt Scenarios
A1: REBUILT SCENARIOS · BULL / BASE / BEAR
A2: Per-trade tax, dynamic PDF-bucket margins, costs, slippage, ₹378 Cr ceiling. K'=K+min(dep·K/m,Nmax)·(move−roll−txn−slip)·(1−tax)+idle·yield·(1−tax).
A3: Starting capital bases → | C3: 2000000 | D3: 7500000 | E3: 20000000 | F3: ◄ Edit these to rescale every scenario & the expense schedule. Cells: C3=Base1, D3=Base2, E3=Base3
A4: Scenario | B4: Move % | C4: Margin % | D4: Calls/yr | E4: Gross ROC/call | F4: Rationale
A5: BULL | B5: 0.3 | C5: ='Margin-Move Link'!D135 -> 0.25867632 | D5: 2 | E5: =B5/C5 -> 1.1597506 | F5: Catch 2 legs/yr, capture first 30% of a ≥30% swing; margin = PDF ≥30%-bucket avg (25.9%)
A6: BASE | B6: 0.18 | C6: ='Margin-Move Link'!D134 -> 0.27272941 | D6: 2 | E6: =B6/C6 -> 0.65999482 | F6: TRUE BASE: 25% move (7-11×/yr, 2020-26) at the 25-30% bucket avg margin 27.3% — NOT 22%
A7: BEAR | B7: 0.15 | C7: 0.28 | D7: 1 | E7: =B7/C7 -> 0.53571429 | F7: 1 catch/yr of a 15% move in an elevated-margin regime (2022-style / Nov-26 fwd 29.7%)
A9: Expense schedule (₹) — blue, scales with each starting-capital base above (C3/D3/E3)
A10: Year | B10: =IF($C$3>=10000000,"₹"&TEXT($C$3/10000000,"0.##")&"Cr","₹"&TEXT($C$3/100000,"0.##")&"L")&" start" -> ₹20.L start | C10: =IF($D$3>=10000000,"₹"&TEXT($D$3/10000000,"0.##")&"Cr","₹"&TEXT($D$3/100000,"0.##")&"L")&" start" -> ₹75.L start | D10: =IF($E$3>=10000000,"₹"&TEXT($E$3/10000000,"0.##")&"Cr","₹"&TEXT($E$3/100000,"0.##")&"L")&" start" -> ₹2.Cr start
A11: 1 | B11: =ROUND(0.01*$C$3,0) -> 20000 | C11: =ROUND(0.01*$D$3,0) -> 75000 | D11: =ROUND(0.01*$E$3,0) -> 200000
A12: 2 | B12: =ROUND(0.01*$C$3,0) -> 20000 | C12: =ROUND(0.01*$D$3,0) -> 75000 | D12: =ROUND(0.01*$E$3,0) -> 200000
A13: 3 | B13: =ROUND(0.025*$C$3,0) -> 50000 | C13: =ROUND(0.025*$D$3,0) -> 187500 | D13: =ROUND(0.025*$E$3,0) -> 500000
A14: 4 | B14: =ROUND(0.025*$C$3,0) -> 50000 | C14: =ROUND(0.025*$D$3,0) -> 187500 | D14: =ROUND(0.025*$E$3,0) -> 500000
A15: 5 | B15: =ROUND(0.05*$C$3,0) -> 100000 | C15: =ROUND(0.05*$D$3,0) -> 375000 | D15: =ROUND(0.05*$E$3,0) -> 1000000
A16: 6 | B16: =ROUND(0.05*$C$3,0) -> 100000 | C16: =ROUND(0.05*$D$3,0) -> 375000 | D16: =ROUND(0.05*$E$3,0) -> 1000000
A17: 7 | B17: =ROUND(0.05*$C$3,0) -> 100000 | C17: =ROUND(0.05*$D$3,0) -> 375000 | D17: =ROUND(0.05*$E$3,0) -> 1000000
A18: 8 | B18: =ROUND(0.1*$C$3,0) -> 200000 | C18: =ROUND(0.1*$D$3,0) -> 750000 | D18: =ROUND(0.1*$E$3,0) -> 2000000
A19: 9 | B19: =ROUND(0.1*$C$3,0) -> 200000 | C19: =ROUND(0.1*$D$3,0) -> 750000 | D19: =ROUND(0.1*$E$3,0) -> 2000000
A20: 10 | B20: =ROUND(0.1*$C$3,0) -> 200000 | C20: =ROUND(0.1*$D$3,0) -> 750000 | D20: =ROUND(0.1*$E$3,0) -> 2000000
A21: 11 | B21: =ROUND(0.1*$C$3,0) -> 200000 | C21: =ROUND(0.1*$D$3,0) -> 750000 | D21: =ROUND(0.1*$E$3,0) -> 2000000
A22: 12 | B22: =ROUND(0.1*$C$3,0) -> 200000 | C22: =ROUND(0.1*$D$3,0) -> 750000 | D22: =ROUND(0.1*$E$3,0) -> 2000000
A23: 13 | B23: =ROUND(0.1*$C$3,0) -> 200000 | C23: =ROUND(0.1*$D$3,0) -> 750000 | D23: =ROUND(0.1*$E$3,0) -> 2000000
A24: 14 | B24: =ROUND(0.1*$C$3,0) -> 200000 | C24: =ROUND(0.1*$D$3,0) -> 750000 | D24: =ROUND(0.1*$E$3,0) -> 2000000
A25: 15 | B25: =ROUND(0.1*$C$3,0) -> 200000 | C25: =ROUND(0.1*$D$3,0) -> 750000 | D25: =ROUND(0.1*$E$3,0) -> 2000000
A27: TRADE-BY-TRADE LEDGER — 15 years × calls; even call # = year end (expense applied)
A28: Call # | B28: Year | C28: ="BULL "&IF($C$3>=10000000,"₹"&TEXT($C$3/10000000,"0.##")&"Cr","₹"&TEXT($C$3/100000,"0.##")&"L") -> BULL ₹20.L | D28: ="BULL "&IF($D$3>=10000000,"₹"&TEXT($D$3/10000000,"0.##")&"Cr","₹"&TEXT($D$3/100000,"0.##")&"L") -> BULL ₹75.L | E28: ="BULL "&IF($E$3>=10000000,"₹"&TEXT($E$3/10000000,"0.##")&"Cr","₹"&TEXT($E$3/100000,"0.##")&"L") -> BULL ₹2.Cr | F28: ="BASE "&IF($C$3>=10000000,"₹"&TEXT($C$3/10000000,"0.##")&"Cr","₹"&TEXT($C$3/100000,"0.##")&"L") -> BASE ₹20.L | G28: ="BASE "&IF($D$3>=10000000,"₹"&TEXT($D$3/10000000,"0.##")&"Cr","₹"&TEXT($D$3/100000,"0.##")&"L") -> BASE ₹75.L | H28: ="BASE "&IF($E$3>=10000000,"₹"&TEXT($E$3/10000000,"0.##")&"Cr","₹"&TEXT($E$3/100000,"0.##")&"L") -> BASE ₹2.Cr | I28: ="BEAR "&IF($C$3>=10000000,"₹"&TEXT($C$3/10000000,"0.##")&"Cr","₹"&TEXT($C$3/100000,"0.##")&"L") -> BEAR ₹20.L | J28: ="BEAR "&IF($D$3>=10000000,"₹"&TEXT($D$3/10000000,"0.##")&"Cr","₹"&TEXT($D$3/100000,"0.##")&"L") -> BEAR ₹75.L | K28: ="BEAR "&IF($E$3>=10000000,"₹"&TEXT($E$3/10000000,"0.##")&"Cr","₹"&TEXT($E$3/100000,"0.##")&"L") -> BEAR ₹2.Cr
A29: 1 | B29: =ROUNDUP(A29/2,0) -> 1 | C29: =$C$3+IF(OR($D$5=2,MOD(A29,2)=1),1,0)*(MIN('Engine Inputs'!$B$12*$C$3/$C$5,'Engine Inputs'!$B$9)*($B$5-'Engine Inputs'!$B$5-'Engine Inputs'!$B$6-2*'Engine Inputs'!$B$7*SQRT(MIN('Engine Inputs'!$B$12*$C$3/$C$5,'Engine Inputs'!$B$9)/'Engine Inputs'!$B$8))+MAX($C$3-MIN('Engine Inputs'!$B$12*$C$3/$C$5,'Engine Inputs'!$B$9)*$C$5,0)*'Engine Inputs'!$B$10/$D$5)*(1-'Engine Inputs'!$B$4)+IF($D$5=1,(1-IF(OR($D$5=2,MOD(A29,2)=1),1,0))*$C$3*'Engine Inputs'!$B$10*(1-'Engine Inputs'!$B$4)/2,0)-IF(MOD(A29,2)=0,INDEX($B$11:$D$25,B29,1)*(1-'Engine Inputs'!$B$4),0) -> 3698695 | D29: =$D$3+IF(OR($D$5=2,MOD(A29,2)=1),1,0)*(MIN('Engine Inputs'!$B$12*$D$3/$C$5,'Engine Inputs'!$B$9)*($B$5-'Engine Inputs'!$B$5-'Engine Inputs'!$B$6-2*'Engine Inputs'!$B$7*SQRT(MIN('Engine Inputs'!$B$12*$D$3/$C$5,'Engine Inputs'!$B$9)/'Engine Inputs'!$B$8))+MAX($D$3-MIN('Engine Inputs'!$B$12*$D$3/$C$5,'Engine Inputs'!$B$9)*$C$5,0)*'Engine Inputs'!$B$10/$D$5)*(1-'Engine Inputs'!$B$4)+IF($D$5=1,(1-IF(OR($D$5=2,MOD(A29,2)=1),1,0))*$D$3*'Engine Inputs'!$B$10*(1-'Engine Inputs'!$B$4)/2,0)-IF(MOD(A29,2)=0,INDEX($B$11:$D$25,B29,2)*(1-'Engine Inputs'!$B$4),0) -> 13853833 | E29: =$E$3+IF(OR($D$5=2,MOD(A29,2)=1),1,0)*(MIN('Engine Inputs'!$B$12*$E$3/$C$5,'Engine Inputs'!$B$9)*($B$5-'Engine Inputs'!$B$5-'Engine Inputs'!$B$6-2*'Engine Inputs'!$B$7*SQRT(MIN('Engine Inputs'!$B$12*$E$3/$C$5,'Engine Inputs'!$B$9)/'Engine Inputs'!$B$8))+MAX($E$3-MIN('Engine Inputs'!$B$12*$E$3/$C$5,'Engine Inputs'!$B$9)*$C$5,0)*'Engine Inputs'!$B$10/$D$5)*(1-'Engine Inputs'!$B$4)+IF($D$5=1,(1-IF(OR($D$5=2,MOD(A29,2)=1),1,0))*$E$3*'Engine Inputs'!$B$10*(1-'Engine Inputs'!$B$4)/2,0)-IF(MOD(A29,2)=0,INDEX($B$11:$D$25,B29,3)*(1-'Engine Inputs'!$B$4),0) -> 36886754 | F29: =$C$3+IF(OR($D$6=2,MOD(A29,2)=1),1,0)*(MIN('Engine Inputs'!$B$12*$C$3/$C$6,'Engine Inputs'!$B$9)*($B$6-'Engine Inputs'!$B$5-'Engine Inputs'!$B$6-2*'Engine Inputs'!$B$7*SQRT(MIN('Engine Inputs'!$B$12*$C$3/$C$6,'Engine Inputs'!$B$9)/'Engine Inputs'!$B$8))+MAX($C$3-MIN('Engine Inputs'!$B$12*$C$3/$C$6,'Engine Inputs'!$B$9)*$C$6,0)*'Engine Inputs'!$B$10/$D$6)*(1-'Engine Inputs'!$B$4)+IF($D$6=1,(1-IF(OR($D$6=2,MOD(A29,2)=1),1,0))*$C$3*'Engine Inputs'!$B$10*(1-'Engine Inputs'!$B$4)/2,0)-IF(MOD(A29,2)=0,INDEX($B$11:$D$25,B29,1)*(1-'Engine Inputs'!$B$4),0) -> 2952763.6 | G29: =$D$3+IF(OR($D$6=2,MOD(A29,2)=1),1,0)*(MIN('Engine Inputs'!$B$12*$D$3/$C$6,'Engine Inputs'!$B$9)*($B$6-'Engine Inputs'!$B$5-'Engine Inputs'!$B$6-2*'Engine Inputs'!$B$7*SQRT(MIN('Engine Inputs'!$B$12*$D$3/$C$6,'Engine Inputs'!$B$9)/'Engine Inputs'!$B$8))+MAX($D$3-MIN('Engine Inputs'!$B$12*$D$3/$C$6,'Engine Inputs'!$B$9)*$C$6,0)*'Engine Inputs'!$B$10/$D$6)*(1-'Engine Inputs'!$B$4)+IF($D$6=1,(1-IF(OR($D$6=2,MOD(A29,2)=1),1,0))*$D$3*'Engine Inputs'!$B$10*(1-'Engine Inputs'!$B$4)/2,0)-IF(MOD(A29,2)=0,INDEX($B$11:$D$25,B29,2)*(1-'Engine Inputs'!$B$4),0) -> 11057832 | H29: =$E$3+IF(OR($D$6=2,MOD(A29,2)=1),1,0)*(MIN('Engine Inputs'!$B$12*$E$3/$C$6,'Engine Inputs'!$B$9)*($B$6-'Engine Inputs'!$B$5-'Engine Inputs'!$B$6-2*'Engine Inputs'!$B$7*SQRT(MIN('Engine Inputs'!$B$12*$E$3/$C$6,'Engine Inputs'!$B$9)/'Engine Inputs'!$B$8))+MAX($E$3-MIN('Engine Inputs'!$B$12*$E$3/$C$6,'Engine Inputs'!$B$9)*$C$6,0)*'Engine Inputs'!$B$10/$D$6)*(1-'Engine Inputs'!$B$4)+IF($D$6=1,(1-IF(OR($D$6=2,MOD(A29,2)=1),1,0))*$E$3*'Engine Inputs'!$B$10*(1-'Engine Inputs'!$B$4)/2,0)-IF(MOD(A29,2)=0,INDEX($B$11:$D$25,B29,3)*(1-'Engine Inputs'!$B$4),0) -> 29435083 | I29: =$C$3+IF(OR($D$7=2,MOD(A29,2)=1),1,0)*(MIN('Engine Inputs'!$B$12*$C$3/$C$7,'Engine Inputs'!$B$9)*($B$7-'Engine Inputs'!$B$5-'Engine Inputs'!$B$6-2*'Engine Inputs'!$B$7*SQRT(MIN('Engine Inputs'!$B$12*$C$3/$C$7,'Engine Inputs'!$B$9)/'Engine Inputs'!$B$8))+MAX($C$3-MIN('Engine Inputs'!$B$12*$C$3/$C$7,'Engine Inputs'!$B$9)*$C$7,0)*'Engine Inputs'!$B$10/$D$7)*(1-'Engine Inputs'!$B$4)+IF($D$7=1,(1-IF(OR($D$7=2,MOD(A29,2)=1),1,0))*$C$3*'Engine Inputs'!$B$10*(1-'Engine Inputs'!$B$4)/2,0)-IF(MOD(A29,2)=0,INDEX($B$11:$D$25,B29,1)*(1-'Engine Inputs'!$B$4),0) -> 2767723.9 | J29: =$D$3+IF(OR($D$7=2,MOD(A29,2)=1),1,0)*(MIN('Engine Inputs'!$B$12*$D$3/$C$7,'Engine Inputs'!$B$9)*($B$7-'Engine Inputs'!$B$5-'Engine Inputs'!$B$6-2*'Engine Inputs'!$B$7*SQRT(MIN('Engine Inputs'!$B$12*$D$3/$C$7,'Engine Inputs'!$B$9)/'Engine Inputs'!$B$8))+MAX($D$3-MIN('Engine Inputs'!$B$12*$D$3/$C$7,'Engine Inputs'!$B$9)*$C$7,0)*'Engine Inputs'!$B$10/$D$7)*(1-'Engine Inputs'!$B$4)+IF($D$7=1,(1-IF(OR($D$7=2,MOD(A29,2)=1),1,0))*$D$3*'Engine Inputs'!$B$10*(1-'Engine Inputs'!$B$4)/2,0)-IF(MOD(A29,2)=0,INDEX($B$11:$D$25,B29,2)*(1-'Engine Inputs'!$B$4),0) -> 10364515 | K29: =$E$3+IF(OR($D$7=2,MOD(A29,2)=1),1,0)*(MIN('Engine Inputs'!$B$12*$E$3/$C$7,'Engine Inputs'!$B$9)*($B$7-'Engine Inputs'!$B$5-'Engine Inputs'!$B$6-2*'Engine Inputs'!$B$7*SQRT(MIN('Engine Inputs'!$B$12*$E$3/$C$7,'Engine Inputs'!$B$9)/'Engine Inputs'!$B$8))+MAX($E$3-MIN('Engine Inputs'!$B$12*$E$3/$C$7,'Engine Inputs'!$B$9)*$C$7,0)*'Engine Inputs'!$B$10/$D$7)*(1-'Engine Inputs'!$B$4)+IF($D$7=1,(1-IF(OR($D$7=2,MOD(A29,2)=1),1,0))*$E$3*'Engine Inputs'!$B$10*(1-'Engine Inputs'!$B$4)/2,0)-IF(MOD(A29,2)=0,INDEX($B$11:$D$25,B29,3)*(1-'Engine Inputs'!$B$4),0) -> 27588268
A30: 2 | B30: =ROUNDUP(A30/2,0) -> 1 | C30: =C29+IF(OR($D$5=2,MOD(A30,2)=1),1,0)*(MIN('Engine Inputs'!$B$12*C29/$C$5,'Engine Inputs'!$B$9)*($B$5-'Engine Inputs'!$B$5-'Engine Inputs'!$B$6-2*'Engine Inputs'!$B$7*SQRT(MIN('Engine Inputs'!$B$12*C29/$C$5,'Engine Inputs'!$B$9)/'Engine Inputs'!$B$8))+MAX(C29-MIN('Engine Inputs'!$B$12*C29/$C$5,'Engine Inputs'!$B$9)*$C$5,0)*'Engine Inputs'!$B$10/$D$5)*(1-'Engine Inputs'!$B$4)+IF($D$5=1,(1-IF(OR($D$5=2,MOD(A30,2)=1),1,0))*C29*'Engine Inputs'!$B$10*(1-'Engine Inputs'!$B$4)/2,0)-IF(MOD(A30,2)=0,INDEX($B$11:$D$25,B30,1)*(1-'Engine Inputs'!$B$4),0) -> 6822121.6 | D30: =D29+IF(OR($D$5=2,MOD(A30,2)=1),1,0)*(MIN('Engine Inputs'!$B$12*D29/$C$5,'Engine Inputs'!$B$9)*($B$5-'Engine Inputs'!$B$5-'Engine Inputs'!$B$6-2*'Engine Inputs'!$B$7*SQRT(MIN('Engine Inputs'!$B$12*D29/$C$5,'Engine Inputs'!$B$9)/'Engine Inputs'!$B$8))+MAX(D29-MIN('Engine Inputs'!$B$12*D29/$C$5,'Engine Inputs'!$B$9)*$C$5,0)*'Engine Inputs'!$B$10/$D$5)*(1-'Engine Inputs'!$B$4)+IF($D$5=1,(1-IF(OR($D$5=2,MOD(A30,2)=1),1,0))*D29*'Engine Inputs'!$B$10*(1-'Engine Inputs'!$B$4)/2,0)-IF(MOD(A30,2)=0,INDEX($B$11:$D$25,B30,2)*(1-'Engine Inputs'!$B$4),0) -> 25512046 | E30: =E29+IF(OR($D$5=2,MOD(A30,2)=1),1,0)*(MIN('Engine Inputs'!$B$12*E29/$C$5,'Engine Inputs'!$B$9)*($B$5-'Engine Inputs'!$B$5-'Engine Inputs'!$B$6-2*'Engine Inputs'!$B$7*SQRT(MIN('Engine Inputs'!$B$12*E29/$C$5,'Engine Inputs'!$B$9)/'Engine Inputs'!$B$8))+MAX(E29-MIN('Engine Inputs'!$B$12*E29/$C$5,'Engine Inputs'!$B$9)*$C$5,0)*'Engine Inputs'!$B$10/$D$5)*(1-'Engine Inputs'!$B$4)+IF($D$5=1,(1-IF(OR($D$5=2,MOD(A30,2)=1),1,0))*E29*'Engine Inputs'!$B$10*(1-'Engine Inputs'!$B$4)/2,0)-IF(MOD(A30,2)=0,INDEX($B$11:$D$25,B30,3)*(1-'Engine Inputs'!$B$4),0) -> 67785195 | F30: =F29+IF(OR($D$6=2,MOD(A30,2)=1),1,0)*(MIN('Engine Inputs'!$B$12*F29/$C$6,'Engine Inputs'!$B$9)*($B$6-'Engine Inputs'!$B$5-'Engine Inputs'!$B$6-2*'Engine Inputs'!$B$7*SQRT(MIN('Engine Inputs'!$B$12*F29/$C$6,'Engine Inputs'!$B$9)/'Engine Inputs'!$B$8))+MAX(F29-MIN('Engine Inputs'!$B$12*F29/$C$6,'Engine Inputs'!$B$9)*$C$6,0)*'Engine Inputs'!$B$10/$D$6)*(1-'Engine Inputs'!$B$4)+IF($D$6=1,(1-IF(OR($D$6=2,MOD(A30,2)=1),1,0))*F29*'Engine Inputs'!$B$10*(1-'Engine Inputs'!$B$4)/2,0)-IF(MOD(A30,2)=0,INDEX($B$11:$D$25,B30,1)*(1-'Engine Inputs'!$B$4),0) -> 4343080.9 | G30: =G29+IF(OR($D$6=2,MOD(A30,2)=1),1,0)*(MIN('Engine Inputs'!$B$12*G29/$C$6,'Engine Inputs'!$B$9)*($B$6-'Engine Inputs'!$B$5-'Engine Inputs'!$B$6-2*'Engine Inputs'!$B$7*SQRT(MIN('Engine Inputs'!$B$12*G29/$C$6,'Engine Inputs'!$B$9)/'Engine Inputs'!$B$8))+MAX(G29-MIN('Engine Inputs'!$B$12*G29/$C$6,'Engine Inputs'!$B$9)*$C$6,0)*'Engine Inputs'!$B$10/$D$6)*(1-'Engine Inputs'!$B$4)+IF($D$6=1,(1-IF(OR($D$6=2,MOD(A30,2)=1),1,0))*G29*'Engine Inputs'!$B$10*(1-'Engine Inputs'!$B$4)/2,0)-IF(MOD(A30,2)=0,INDEX($B$11:$D$25,B30,2)*(1-'Engine Inputs'!$B$4),0) -> 16237476 | H30: =H29+IF(OR($D$6=2,MOD(A30,2)=1),1,0)*(MIN('Engine Inputs'!$B$12*H29/$C$6,'Engine Inputs'!$B$9)*($B$6-'Engine Inputs'!$B$5-'Engine Inputs'!$B$6-2*'Engine Inputs'!$B$7*SQRT(MIN('Engine Inputs'!$B$12*H29/$C$6,'Engine Inputs'!$B$9)/'Engine Inputs'!$B$8))+MAX(H29-MIN('Engine Inputs'!$B$12*H29/$C$6,'Engine Inputs'!$B$9)*$C$6,0)*'Engine Inputs'!$B$10/$D$6)*(1-'Engine Inputs'!$B$4)+IF($D$6=1,(1-IF(OR($D$6=2,MOD(A30,2)=1),1,0))*H29*'Engine Inputs'!$B$10*(1-'Engine Inputs'!$B$4)/2,0)-IF(MOD(A30,2)=0,INDEX($B$11:$D$25,B30,3)*(1-'Engine Inputs'!$B$4),0) -> 43129079 | I30: =I29+IF(OR($D$7=2,MOD(A30,2)=1),1,0)*(MIN('Engine Inputs'!$B$12*I29/$C$7,'Engine Inputs'!$B$9)*($B$7-'Engine Inputs'!$B$5-'Engine Inputs'!$B$6-2*'Engine Inputs'!$B$7*SQRT(MIN('Engine Inputs'!$B$12*I29/$C$7,'Engine Inputs'!$B$9)/'Engine Inputs'!$B$8))+MAX(I29-MIN('Engine Inputs'!$B$12*I29/$C$7,'Engine Inputs'!$B$9)*$C$7,0)*'Engine Inputs'!$B$10/$D$7)*(1-'Engine Inputs'!$B$4)+IF($D$7=1,(1-IF(OR($D$7=2,MOD(A30,2)=1),1,0))*I29*'Engine Inputs'!$B$10*(1-'Engine Inputs'!$B$4)/2,0)-IF(MOD(A30,2)=0,INDEX($B$11:$D$25,B30,1)*(1-'Engine Inputs'!$B$4),0) -> 2820069.7 | J30: =J29+IF(OR($D$7=2,MOD(A30,2)=1),1,0)*(MIN('Engine Inputs'!$B$12*J29/$C$7,'Engine Inputs'!$B$9)*($B$7-'Engine Inputs'!$B$5-'Engine Inputs'!$B$6-2*'Engine Inputs'!$B$7*SQRT(MIN('Engine Inputs'!$B$12*J29/$C$7,'Engine Inputs'!$B$9)/'Engine Inputs'!$B$8))+MAX(J29-MIN('Engine Inputs'!$B$12*J29/$C$7,'Engine Inputs'!$B$9)*$C$7,0)*'Engine Inputs'!$B$10/$D$7)*(1-'Engine Inputs'!$B$4)+IF($D$7=1,(1-IF(OR($D$7=2,MOD(A30,2)=1),1,0))*J29*'Engine Inputs'!$B$10*(1-'Engine Inputs'!$B$4)/2,0)-IF(MOD(A30,2)=0,INDEX($B$11:$D$25,B30,2)*(1-'Engine Inputs'!$B$4),0) -> 10560460 | K30: =K29+IF(OR($D$7=2,MOD(A30,2)=1),1,0)*(MIN('Engine Inputs'!$B$12*K29/$C$7,'Engine Inputs'!$B$9)*($B$7-'Engine Inputs'!$B$5-'Engine Inputs'!$B$6-2*'Engine Inputs'!$B$7*SQRT(MIN('Engine Inputs'!$B$12*K29/$C$7,'Engine Inputs'!$B$9)/'Engine Inputs'!$B$8))+MAX(K29-MIN('Engine Inputs'!$B$12*K29/$C$7,'Engine Inputs'!$B$9)*$C$7,0)*'Engine Inputs'!$B$10/$D$7)*(1-'Engine Inputs'!$B$4)+IF($D$7=1,(1-IF(OR($D$7=2,MOD(A30,2)=1),1,0))*K29*'Engine Inputs'!$B$10*(1-'Engine Inputs'!$B$4)/2,0)-IF(MOD(A30,2)=0,INDEX($B$11:$D$25,B30,3)*(1-'Engine Inputs'!$B$4),0) -> 28109562
A31: 3 | B31: =ROUNDUP(A31/2,0) -> 2 | C31: =C30+IF(OR($D$5=2,MOD(A31,2)=1),1,0)*(MIN('Engine Inputs'!$B$12*C30/$C$5,'Engine Inputs'!$B$9)*($B$5-'Engine Inputs'!$B$5-'Engine Inputs'!$B$6-2*'Engine Inputs'!$B$7*SQRT(MIN('Engine Inputs'!$B$12*C30/$C$5,'Engine Inputs'!$B$9)/'Engine Inputs'!$B$8))+MAX(C30-MIN('Engine Inputs'!$B$12*C30/$C$5,'Engine Inputs'!$B$9)*$C$5,0)*'Engine Inputs'!$B$10/$D$5)*(1-'Engine Inputs'!$B$4)+IF($D$5=1,(1-IF(OR($D$5=2,MOD(A31,2)=1),1,0))*C30*'Engine Inputs'!$B$10*(1-'Engine Inputs'!$B$4)/2,0)-IF(MOD(A31,2)=0,INDEX($B$11:$D$25,B31,1)*(1-'Engine Inputs'!$B$4),0) -> 12603087 | D31: =D30+IF(OR($D$5=2,MOD(A31,2)=1),1,0)*(MIN('Engine Inputs'!$B$12*D30/$C$5,'Engine Inputs'!$B$9)*($B$5-'Engine Inputs'!$B$5-'Engine Inputs'!$B$6-2*'Engine Inputs'!$B$7*SQRT(MIN('Engine Inputs'!$B$12*D30/$C$5,'Engine Inputs'!$B$9)/'Engine Inputs'!$B$8))+MAX(D30-MIN('Engine Inputs'!$B$12*D30/$C$5,'Engine Inputs'!$B$9)*$C$5,0)*'Engine Inputs'!$B$10/$D$5)*(1-'Engine Inputs'!$B$4)+IF($D$5=1,(1-IF(OR($D$5=2,MOD(A31,2)=1),1,0))*D30*'Engine Inputs'!$B$10*(1-'Engine Inputs'!$B$4)/2,0)-IF(MOD(A31,2)=0,INDEX($B$11:$D$25,B31,2)*(1-'Engine Inputs'!$B$4),0) -> 47028635 | E31: =E30+IF(OR($D$5=2,MOD(A31,2)=1),1,0)*(MIN('Engine Inputs'!$B$12*E30/$C$5,'Engine Inputs'!$B$9)*($B$5-'Engine Inputs'!$B$5-'Engine Inputs'!$B$6-2*'Engine Inputs'!$B$7*SQRT(MIN('Engine Inputs'!$B$12*E30/$C$5,'Engine Inputs'!$B$9)/'Engine Inputs'!$B$8))+MAX(E30-MIN('Engine Inputs'!$B$12*E30/$C$5,'Engine Inputs'!$B$9)*$C$5,0)*'Engine Inputs'!$B$10/$D$5)*(1-'Engine Inputs'!$B$4)+IF($D$5=1,(1-IF(OR($D$5=2,MOD(A31,2)=1),1,0))*E30*'Engine Inputs'!$B$10*(1-'Engine Inputs'!$B$4)/2,0)-IF(MOD(A31,2)=0,INDEX($B$11:$D$25,B31,3)*(1-'Engine Inputs'!$B$4),0) -> 1.2460112e+08 | F31: =F30+IF(OR($D$6=2,MOD(A31,2)=1),1,0)*(MIN('Engine Inputs'!$B$12*F30/$C$6,'Engine Inputs'!$B$9)*($B$6-'Engine Inputs'!$B$5-'Engine Inputs'!$B$6-2*'Engine Inputs'!$B$7*SQRT(MIN('Engine Inputs'!$B$12*F30/$C$6,'Engine Inputs'!$B$9)/'Engine Inputs'!$B$8))+MAX(F30-MIN('Engine Inputs'!$B$12*F30/$C$6,'Engine Inputs'!$B$9)*$C$6,0)*'Engine Inputs'!$B$10/$D$6)*(1-'Engine Inputs'!$B$4)+IF($D$6=1,(1-IF(OR($D$6=2,MOD(A31,2)=1),1,0))*F30*'Engine Inputs'!$B$10*(1-'Engine Inputs'!$B$4)/2,0)-IF(MOD(A31,2)=0,INDEX($B$11:$D$25,B31,1)*(1-'Engine Inputs'!$B$4),0) -> 6407643.2 | G31: =G30+IF(OR($D$6=2,MOD(A31,2)=1),1,0)*(MIN('Engine Inputs'!$B$12*G30/$C$6,'Engine Inputs'!$B$9)*($B$6-'Engine Inputs'!$B$5-'Engine Inputs'!$B$6-2*'Engine Inputs'!$B$7*SQRT(MIN('Engine Inputs'!$B$12*G30/$C$6,'Engine Inputs'!$B$9)/'Engine Inputs'!$B$8))+MAX(G30-MIN('Engine Inputs'!$B$12*G30/$C$6,'Engine Inputs'!$B$9)*$C$6,0)*'Engine Inputs'!$B$10/$D$6)*(1-'Engine Inputs'!$B$4)+IF($D$6=1,(1-IF(OR($D$6=2,MOD(A31,2)=1),1,0))*G30*'Engine Inputs'!$B$10*(1-'Engine Inputs'!$B$4)/2,0)-IF(MOD(A31,2)=0,INDEX($B$11:$D$25,B31,2)*(1-'Engine Inputs'!$B$4),0) -> 23908448 | H31: =H30+IF(OR($D$6=2,MOD(A31,2)=1),1,0)*(MIN('Engine Inputs'!$B$12*H30/$C$6,'Engine Inputs'!$B$9)*($B$6-'Engine Inputs'!$B$5-'Engine Inputs'!$B$6-2*'Engine Inputs'!$B$7*SQRT(MIN('Engine Inputs'!$B$12*H30/$C$6,'Engine Inputs'!$B$9)/'Engine Inputs'!$B$8))+MAX(H30-MIN('Engine Inputs'!$B$12*H30/$C$6,'Engine Inputs'!$B$9)*$C$6,0)*'Engine Inputs'!$B$10/$D$6)*(1-'Engine Inputs'!$B$4)+IF($D$6=1,(1-IF(OR($D$6=2,MOD(A31,2)=1),1,0))*H30*'Engine Inputs'!$B$10*(1-'Engine Inputs'!$B$4)/2,0)-IF(MOD(A31,2)=0,INDEX($B$11:$D$25,B31,3)*(1-'Engine Inputs'!$B$4),0) -> 63338655 | I31: =I30+IF(OR($D$7=2,MOD(A31,2)=1),1,0)*(MIN('Engine Inputs'!$B$12*I30/$C$7,'Engine Inputs'!$B$9)*($B$7-'Engine Inputs'!$B$5-'Engine Inputs'!$B$6-2*'Engine Inputs'!$B$7*SQRT(MIN('Engine Inputs'!$B$12*I30/$C$7,'Engine Inputs'!$B$9)/'Engine Inputs'!$B$8))+MAX(I30-MIN('Engine Inputs'!$B$12*I30/$C$7,'Engine Inputs'!$B$9)*$C$7,0)*'Engine Inputs'!$B$10/$D$7)*(1-'Engine Inputs'!$B$4)+IF($D$7=1,(1-IF(OR($D$7=2,MOD(A31,2)=1),1,0))*I30*'Engine Inputs'!$B$10*(1-'Engine Inputs'!$B$4)/2,0)-IF(MOD(A31,2)=0,INDEX($B$11:$D$25,B31,1)*(1-'Engine Inputs'!$B$4),0) -> 3901499.6 | J31: =J30+IF(OR($D$7=2,MOD(A31,2)=1),1,0)*(MIN('Engine Inputs'!$B$12*J30/$C$7,'Engine Inputs'!$B$9)*($B$7-'Engine Inputs'!$B$5-'Engine Inputs'!$B$6-2*'Engine Inputs'!$B$7*SQRT(MIN('Engine Inputs'!$B$12*J30/$C$7,'Engine Inputs'!$B$9)/'Engine Inputs'!$B$8))+MAX(J30-MIN('Engine Inputs'!$B$12*J30/$C$7,'Engine Inputs'!$B$9)*$C$7,0)*'Engine Inputs'!$B$10/$D$7)*(1-'Engine Inputs'!$B$4)+IF($D$7=1,(1-IF(OR($D$7=2,MOD(A31,2)=1),1,0))*J30*'Engine Inputs'!$B$10*(1-'Engine Inputs'!$B$4)/2,0)-IF(MOD(A31,2)=0,INDEX($B$11:$D$25,B31,2)*(1-'Engine Inputs'!$B$4),0) -> 14586020 | K31: =K30+IF(OR($D$7=2,MOD(A31,2)=1),1,0)*(MIN('Engine Inputs'!$B$12*K30/$C$7,'Engine Inputs'!$B$9)*($B$7-'Engine Inputs'!$B$5-'Engine Inputs'!$B$6-2*'Engine Inputs'!$B$7*SQRT(MIN('Engine Inputs'!$B$12*K30/$C$7,'Engine Inputs'!$B$9)/'Engine Inputs'!$B$8))+MAX(K30-MIN('Engine Inputs'!$B$12*K30/$C$7,'Engine Inputs'!$B$9)*$C$7,0)*'Engine Inputs'!$B$10/$D$7)*(1-'Engine Inputs'!$B$4)+IF($D$7=1,(1-IF(OR($D$7=2,MOD(A31,2)=1),1,0))*K30*'Engine Inputs'!$B$10*(1-'Engine Inputs'!$B$4)/2,0)-IF(MOD(A31,2)=0,INDEX($B$11:$D$25,B31,3)*(1-'Engine Inputs'!$B$4),0) -> 38740778
A32: 4 | B32: =ROUNDUP(A32/2,0) -> 2 | C32: =C31+IF(OR($D$5=2,MOD(A32,2)=1),1,0)*(MIN('Engine Inputs'!$B$12*C31/$C$5,'Engine Inputs'!$B$9)*($B$5-'Engine Inputs'!$B$5-'Engine Inputs'!$B$6-2*'Engine Inputs'!$B$7*SQRT(MIN('Engine Inputs'!$B$12*C31/$C$5,'Engine Inputs'!$B$9)/'Engine Inputs'!$B$8))+MAX(C31-MIN('Engine Inputs'!$B$12*C31/$C$5,'Engine Inputs'!$B$9)*$C$5,0)*'Engine Inputs'!$B$10/$D$5)*(1-'Engine Inputs'!$B$4)+IF($D$5=1,(1-IF(OR($D$5=2,MOD(A32,2)=1),1,0))*C31*'Engine Inputs'!$B$10*(1-'Engine Inputs'!$B$4)/2,0)-IF(MOD(A32,2)=0,INDEX($B$11:$D$25,B32,1)*(1-'Engine Inputs'!$B$4),0) -> 23248420 | D32: =D31+IF(OR($D$5=2,MOD(A32,2)=1),1,0)*(MIN('Engine Inputs'!$B$12*D31/$C$5,'Engine Inputs'!$B$9)*($B$5-'Engine Inputs'!$B$5-'Engine Inputs'!$B$6-2*'Engine Inputs'!$B$7*SQRT(MIN('Engine Inputs'!$B$12*D31/$C$5,'Engine Inputs'!$B$9)/'Engine Inputs'!$B$8))+MAX(D31-MIN('Engine Inputs'!$B$12*D31/$C$5,'Engine Inputs'!$B$9)*$C$5,0)*'Engine Inputs'!$B$10/$D$5)*(1-'Engine Inputs'!$B$4)+IF($D$5=1,(1-IF(OR($D$5=2,MOD(A32,2)=1),1,0))*D31*'Engine Inputs'!$B$10*(1-'Engine Inputs'!$B$4)/2,0)-IF(MOD(A32,2)=0,INDEX($B$11:$D$25,B32,2)*(1-'Engine Inputs'!$B$4),0) -> 86496756 | E32: =E31+IF(OR($D$5=2,MOD(A32,2)=1),1,0)*(MIN('Engine Inputs'!$B$12*E31/$C$5,'Engine Inputs'!$B$9)*($B$5-'Engine Inputs'!$B$5-'Engine Inputs'!$B$6-2*'Engine Inputs'!$B$7*SQRT(MIN('Engine Inputs'!$B$12*E31/$C$5,'Engine Inputs'!$B$9)/'Engine Inputs'!$B$8))+MAX(E31-MIN('Engine Inputs'!$B$12*E31/$C$5,'Engine Inputs'!$B$9)*$C$5,0)*'Engine Inputs'!$B$10/$D$5)*(1-'Engine Inputs'!$B$4)+IF($D$5=1,(1-IF(OR($D$5=2,MOD(A32,2)=1),1,0))*E31*'Engine Inputs'!$B$10*(1-'Engine Inputs'!$B$4)/2,0)-IF(MOD(A32,2)=0,INDEX($B$11:$D$25,B32,3)*(1-'Engine Inputs'!$B$4),0) -> 2.2829114e+08 | F32: =F31+IF(OR($D$6=2,MOD(A32,2)=1),1,0)*(MIN('Engine Inputs'!$B$12*F31/$C$6,'Engine Inputs'!$B$9)*($B$6-'Engine Inputs'!$B$5-'Engine Inputs'!$B$6-2*'Engine Inputs'!$B$7*SQRT(MIN('Engine Inputs'!$B$12*F31/$C$6,'Engine Inputs'!$B$9)/'Engine Inputs'!$B$8))+MAX(F31-MIN('Engine Inputs'!$B$12*F31/$C$6,'Engine Inputs'!$B$9)*$C$6,0)*'Engine Inputs'!$B$10/$D$6)*(1-'Engine Inputs'!$B$4)+IF($D$6=1,(1-IF(OR($D$6=2,MOD(A32,2)=1),1,0))*F31*'Engine Inputs'!$B$10*(1-'Engine Inputs'!$B$4)/2,0)-IF(MOD(A32,2)=0,INDEX($B$11:$D$25,B32,1)*(1-'Engine Inputs'!$B$4),0) -> 9434328.8 | G32: =G31+IF(OR($D$6=2,MOD(A32,2)=1),1,0)*(MIN('Engine Inputs'!$B$12*G31/$C$6,'Engine Inputs'!$B$9)*($B$6-'Engine Inputs'!$B$5-'Engine Inputs'!$B$6-2*'Engine Inputs'!$B$7*SQRT(MIN('Engine Inputs'!$B$12*G31/$C$6,'Engine Inputs'!$B$9)/'Engine Inputs'!$B$8))+MAX(G31-MIN('Engine Inputs'!$B$12*G31/$C$6,'Engine Inputs'!$B$9)*$C$6,0)*'Engine Inputs'!$B$10/$D$6)*(1-'Engine Inputs'!$B$4)+IF($D$6=1,(1-IF(OR($D$6=2,MOD(A32,2)=1),1,0))*G31*'Engine Inputs'!$B$10*(1-'Engine Inputs'!$B$4)/2,0)-IF(MOD(A32,2)=0,INDEX($B$11:$D$25,B32,2)*(1-'Engine Inputs'!$B$4),0) -> 35116129 | H32: =H31+IF(OR($D$6=2,MOD(A32,2)=1),1,0)*(MIN('Engine Inputs'!$B$12*H31/$C$6,'Engine Inputs'!$B$9)*($B$6-'Engine Inputs'!$B$5-'Engine Inputs'!$B$6-2*'Engine Inputs'!$B$7*SQRT(MIN('Engine Inputs'!$B$12*H31/$C$6,'Engine Inputs'!$B$9)/'Engine Inputs'!$B$8))+MAX(H31-MIN('Engine Inputs'!$B$12*H31/$C$6,'Engine Inputs'!$B$9)*$C$6,0)*'Engine Inputs'!$B$10/$D$6)*(1-'Engine Inputs'!$B$4)+IF($D$6=1,(1-IF(OR($D$6=2,MOD(A32,2)=1),1,0))*H31*'Engine Inputs'!$B$10*(1-'Engine Inputs'!$B$4)/2,0)-IF(MOD(A32,2)=0,INDEX($B$11:$D$25,B32,3)*(1-'Engine Inputs'!$B$4),0) -> 92735085 | I32: =I31+IF(OR($D$7=2,MOD(A32,2)=1),1,0)*(MIN('Engine Inputs'!$B$12*I31/$C$7,'Engine Inputs'!$B$9)*($B$7-'Engine Inputs'!$B$5-'Engine Inputs'!$B$6-2*'Engine Inputs'!$B$7*SQRT(MIN('Engine Inputs'!$B$12*I31/$C$7,'Engine Inputs'!$B$9)/'Engine Inputs'!$B$8))+MAX(I31-MIN('Engine Inputs'!$B$12*I31/$C$7,'Engine Inputs'!$B$9)*$C$7,0)*'Engine Inputs'!$B$10/$D$7)*(1-'Engine Inputs'!$B$4)+IF($D$7=1,(1-IF(OR($D$7=2,MOD(A32,2)=1),1,0))*I31*'Engine Inputs'!$B$10*(1-'Engine Inputs'!$B$4)/2,0)-IF(MOD(A32,2)=0,INDEX($B$11:$D$25,B32,1)*(1-'Engine Inputs'!$B$4),0) -> 3981419.3 | J32: =J31+IF(OR($D$7=2,MOD(A32,2)=1),1,0)*(MIN('Engine Inputs'!$B$12*J31/$C$7,'Engine Inputs'!$B$9)*($B$7-'Engine Inputs'!$B$5-'Engine Inputs'!$B$6-2*'Engine Inputs'!$B$7*SQRT(MIN('Engine Inputs'!$B$12*J31/$C$7,'Engine Inputs'!$B$9)/'Engine Inputs'!$B$8))+MAX(J31-MIN('Engine Inputs'!$B$12*J31/$C$7,'Engine Inputs'!$B$9)*$C$7,0)*'Engine Inputs'!$B$10/$D$7)*(1-'Engine Inputs'!$B$4)+IF($D$7=1,(1-IF(OR($D$7=2,MOD(A32,2)=1),1,0))*J31*'Engine Inputs'!$B$10*(1-'Engine Inputs'!$B$4)/2,0)-IF(MOD(A32,2)=0,INDEX($B$11:$D$25,B32,2)*(1-'Engine Inputs'!$B$4),0) -> 14884634 | K32: =K31+IF(OR($D$7=2,MOD(A32,2)=1),1,0)*(MIN('Engine Inputs'!$B$12*K31/$C$7,'Engine Inputs'!$B$9)*($B$7-'Engine Inputs'!$B$5-'Engine Inputs'!$B$6-2*'Engine Inputs'!$B$7*SQRT(MIN('Engine Inputs'!$B$12*K31/$C$7,'Engine Inputs'!$B$9)/'Engine Inputs'!$B$8))+MAX(K31-MIN('Engine Inputs'!$B$12*K31/$C$7,'Engine Inputs'!$B$9)*$C$7,0)*'Engine Inputs'!$B$10/$D$7)*(1-'Engine Inputs'!$B$4)+IF($D$7=1,(1-IF(OR($D$7=2,MOD(A32,2)=1),1,0))*K31*'Engine Inputs'!$B$10*(1-'Engine Inputs'!$B$4)/2,0)-IF(MOD(A32,2)=0,INDEX($B$11:$D$25,B32,3)*(1-'Engine Inputs'!$B$4),0) -> 39533305
A33: 5 | B33: =ROUNDUP(A33/2,0) -> 3 | C33: =C32+IF(OR($D$5=2,MOD(A33,2)=1),1,0)*(MIN('Engine Inputs'!$B$12*C32/$C$5,'Engine Inputs'!$B$9)*($B$5-'Engine Inputs'!$B$5-'Engine Inputs'!$B$6-2*'Engine Inputs'!$B$7*SQRT(MIN('Engine Inputs'!$B$12*C32/$C$5,'Engine Inputs'!$B$9)/'Engine Inputs'!$B$8))+MAX(C32-MIN('Engine Inputs'!$B$12*C32/$C$5,'Engine Inputs'!$B$9)*$C$5,0)*'Engine Inputs'!$B$10/$D$5)*(1-'Engine Inputs'!$B$4)+IF($D$5=1,(1-IF(OR($D$5=2,MOD(A33,2)=1),1,0))*C32*'Engine Inputs'!$B$10*(1-'Engine Inputs'!$B$4)/2,0)-IF(MOD(A33,2)=0,INDEX($B$11:$D$25,B33,1)*(1-'Engine Inputs'!$B$4),0) -> 42864624 | D33: =D32+IF(OR($D$5=2,MOD(A33,2)=1),1,0)*(MIN('Engine Inputs'!$B$12*D32/$C$5,'Engine Inputs'!$B$9)*($B$5-'Engine Inputs'!$B$5-'Engine Inputs'!$B$6-2*'Engine Inputs'!$B$7*SQRT(MIN('Engine Inputs'!$B$12*D32/$C$5,'Engine Inputs'!$B$9)/'Engine Inputs'!$B$8))+MAX(D32-MIN('Engine Inputs'!$B$12*D32/$C$5,'Engine Inputs'!$B$9)*$C$5,0)*'Engine Inputs'!$B$10/$D$5)*(1-'Engine Inputs'!$B$4)+IF($D$5=1,(1-IF(OR($D$5=2,MOD(A33,2)=1),1,0))*D32*'Engine Inputs'!$B$10*(1-'Engine Inputs'!$B$4)/2,0)-IF(MOD(A33,2)=0,INDEX($B$11:$D$25,B33,2)*(1-'Engine Inputs'!$B$4),0) -> 1.5884503e+08 | E33: =E32+IF(OR($D$5=2,MOD(A33,2)=1),1,0)*(MIN('Engine Inputs'!$B$12*E32/$C$5,'Engine Inputs'!$B$9)*($B$5-'Engine Inputs'!$B$5-'Engine Inputs'!$B$6-2*'Engine Inputs'!$B$7*SQRT(MIN('Engine Inputs'!$B$12*E32/$C$5,'Engine Inputs'!$B$9)/'Engine Inputs'!$B$8))+MAX(E32-MIN('Engine Inputs'!$B$12*E32/$C$5,'Engine Inputs'!$B$9)*$C$5,0)*'Engine Inputs'!$B$10/$D$5)*(1-'Engine Inputs'!$B$4)+IF($D$5=1,(1-IF(OR($D$5=2,MOD(A33,2)=1),1,0))*E32*'Engine Inputs'!$B$10*(1-'Engine Inputs'!$B$4)/2,0)-IF(MOD(A33,2)=0,INDEX($B$11:$D$25,B33,3)*(1-'Engine Inputs'!$B$4),0) -> 4.1706753e+08 | F33: =F32+IF(OR($D$6=2,MOD(A33,2)=1),1,0)*(MIN('Engine Inputs'!$B$12*F32/$C$6,'Engine Inputs'!$B$9)*($B$6-'Engine Inputs'!$B$5-'Engine Inputs'!$B$6-2*'Engine Inputs'!$B$7*SQRT(MIN('Engine Inputs'!$B$12*F32/$C$6,'Engine Inputs'!$B$9)/'Engine Inputs'!$B$8))+MAX(F32-MIN('Engine Inputs'!$B$12*F32/$C$6,'Engine Inputs'!$B$9)*$C$6,0)*'Engine Inputs'!$B$10/$D$6)*(1-'Engine Inputs'!$B$4)+IF($D$6=1,(1-IF(OR($D$6=2,MOD(A33,2)=1),1,0))*F32*'Engine Inputs'!$B$10*(1-'Engine Inputs'!$B$4)/2,0)-IF(MOD(A33,2)=0,INDEX($B$11:$D$25,B33,1)*(1-'Engine Inputs'!$B$4),0) -> 13905009 | G33: =G32+IF(OR($D$6=2,MOD(A33,2)=1),1,0)*(MIN('Engine Inputs'!$B$12*G32/$C$6,'Engine Inputs'!$B$9)*($B$6-'Engine Inputs'!$B$5-'Engine Inputs'!$B$6-2*'Engine Inputs'!$B$7*SQRT(MIN('Engine Inputs'!$B$12*G32/$C$6,'Engine Inputs'!$B$9)/'Engine Inputs'!$B$8))+MAX(G32-MIN('Engine Inputs'!$B$12*G32/$C$6,'Engine Inputs'!$B$9)*$C$6,0)*'Engine Inputs'!$B$10/$D$6)*(1-'Engine Inputs'!$B$4)+IF($D$6=1,(1-IF(OR($D$6=2,MOD(A33,2)=1),1,0))*G32*'Engine Inputs'!$B$10*(1-'Engine Inputs'!$B$4)/2,0)-IF(MOD(A33,2)=0,INDEX($B$11:$D$25,B33,2)*(1-'Engine Inputs'!$B$4),0) -> 51605053 | H33: =H32+IF(OR($D$6=2,MOD(A33,2)=1),1,0)*(MIN('Engine Inputs'!$B$12*H32/$C$6,'Engine Inputs'!$B$9)*($B$6-'Engine Inputs'!$B$5-'Engine Inputs'!$B$6-2*'Engine Inputs'!$B$7*SQRT(MIN('Engine Inputs'!$B$12*H32/$C$6,'Engine Inputs'!$B$9)/'Engine Inputs'!$B$8))+MAX(H32-MIN('Engine Inputs'!$B$12*H32/$C$6,'Engine Inputs'!$B$9)*$C$6,0)*'Engine Inputs'!$B$10/$D$6)*(1-'Engine Inputs'!$B$4)+IF($D$6=1,(1-IF(OR($D$6=2,MOD(A33,2)=1),1,0))*H32*'Engine Inputs'!$B$10*(1-'Engine Inputs'!$B$4)/2,0)-IF(MOD(A33,2)=0,INDEX($B$11:$D$25,B33,3)*(1-'Engine Inputs'!$B$4),0) -> 1.3575942e+08 | I33: =I32+IF(OR($D$7=2,MOD(A33,2)=1),1,0)*(MIN('Engine Inputs'!$B$12*I32/$C$7,'Engine Inputs'!$B$9)*($B$7-'Engine Inputs'!$B$5-'Engine Inputs'!$B$6-2*'Engine Inputs'!$B$7*SQRT(MIN('Engine Inputs'!$B$12*I32/$C$7,'Engine Inputs'!$B$9)/'Engine Inputs'!$B$8))+MAX(I32-MIN('Engine Inputs'!$B$12*I32/$C$7,'Engine Inputs'!$B$9)*$C$7,0)*'Engine Inputs'!$B$10/$D$7)*(1-'Engine Inputs'!$B$4)+IF($D$7=1,(1-IF(OR($D$7=2,MOD(A33,2)=1),1,0))*I32*'Engine Inputs'!$B$10*(1-'Engine Inputs'!$B$4)/2,0)-IF(MOD(A33,2)=0,INDEX($B$11:$D$25,B33,1)*(1-'Engine Inputs'!$B$4),0) -> 5506368.8 | J33: =J32+IF(OR($D$7=2,MOD(A33,2)=1),1,0)*(MIN('Engine Inputs'!$B$12*J32/$C$7,'Engine Inputs'!$B$9)*($B$7-'Engine Inputs'!$B$5-'Engine Inputs'!$B$6-2*'Engine Inputs'!$B$7*SQRT(MIN('Engine Inputs'!$B$12*J32/$C$7,'Engine Inputs'!$B$9)/'Engine Inputs'!$B$8))+MAX(J32-MIN('Engine Inputs'!$B$12*J32/$C$7,'Engine Inputs'!$B$9)*$C$7,0)*'Engine Inputs'!$B$10/$D$7)*(1-'Engine Inputs'!$B$4)+IF($D$7=1,(1-IF(OR($D$7=2,MOD(A33,2)=1),1,0))*J32*'Engine Inputs'!$B$10*(1-'Engine Inputs'!$B$4)/2,0)-IF(MOD(A33,2)=0,INDEX($B$11:$D$25,B33,2)*(1-'Engine Inputs'!$B$4),0) -> 20545361 | K33: =K32+IF(OR($D$7=2,MOD(A33,2)=1),1,0)*(MIN('Engine Inputs'!$B$12*K32/$C$7,'Engine Inputs'!$B$9)*($B$7-'Engine Inputs'!$B$5-'Engine Inputs'!$B$6-2*'Engine Inputs'!$B$7*SQRT(MIN('Engine Inputs'!$B$12*K32/$C$7,'Engine Inputs'!$B$9)/'Engine Inputs'!$B$8))+MAX(K32-MIN('Engine Inputs'!$B$12*K32/$C$7,'Engine Inputs'!$B$9)*$C$7,0)*'Engine Inputs'!$B$10/$D$7)*(1-'Engine Inputs'!$B$4)+IF($D$7=1,(1-IF(OR($D$7=2,MOD(A33,2)=1),1,0))*K32*'Engine Inputs'!$B$10*(1-'Engine Inputs'!$B$4)/2,0)-IF(MOD(A33,2)=0,INDEX($B$11:$D$25,B33,3)*(1-'Engine Inputs'!$B$4),0) -> 54428364
A34: 6 | B34: =ROUNDUP(A34/2,0) -> 3 | C34: =C33+IF(OR($D$5=2,MOD(A34,2)=1),1,0)*(MIN('Engine Inputs'!$B$12*C33/$C$5,'Engine Inputs'!$B$9)*($B$5-'Engine Inputs'!$B$5-'Engine Inputs'!$B$6-2*'Engine Inputs'!$B$7*SQRT(MIN('Engine Inputs'!$B$12*C33/$C$5,'Engine Inputs'!$B$9)/'Engine Inputs'!$B$8))+MAX(C33-MIN('Engine Inputs'!$B$12*C33/$C$5,'Engine Inputs'!$B$9)*$C$5,0)*'Engine Inputs'!$B$10/$D$5)*(1-'Engine Inputs'!$B$4)+IF($D$5=1,(1-IF(OR($D$5=2,MOD(A34,2)=1),1,0))*C33*'Engine Inputs'!$B$10*(1-'Engine Inputs'!$B$4)/2,0)-IF(MOD(A34,2)=0,INDEX($B$11:$D$25,B34,1)*(1-'Engine Inputs'!$B$4),0) -> 78873710 | D34: =D33+IF(OR($D$5=2,MOD(A34,2)=1),1,0)*(MIN('Engine Inputs'!$B$12*D33/$C$5,'Engine Inputs'!$B$9)*($B$5-'Engine Inputs'!$B$5-'Engine Inputs'!$B$6-2*'Engine Inputs'!$B$7*SQRT(MIN('Engine Inputs'!$B$12*D33/$C$5,'Engine Inputs'!$B$9)/'Engine Inputs'!$B$8))+MAX(D33-MIN('Engine Inputs'!$B$12*D33/$C$5,'Engine Inputs'!$B$9)*$C$5,0)*'Engine Inputs'!$B$10/$D$5)*(1-'Engine Inputs'!$B$4)+IF($D$5=1,(1-IF(OR($D$5=2,MOD(A34,2)=1),1,0))*D33*'Engine Inputs'!$B$10*(1-'Engine Inputs'!$B$4)/2,0)-IF(MOD(A34,2)=0,INDEX($B$11:$D$25,B34,2)*(1-'Engine Inputs'!$B$4),0) -> 2.9070751e+08 | E34: =E33+IF(OR($D$5=2,MOD(A34,2)=1),1,0)*(MIN('Engine Inputs'!$B$12*E33/$C$5,'Engine Inputs'!$B$9)*($B$5-'Engine Inputs'!$B$5-'Engine Inputs'!$B$6-2*'Engine Inputs'!$B$7*SQRT(MIN('Engine Inputs'!$B$12*E33/$C$5,'Engine Inputs'!$B$9)/'Engine Inputs'!$B$8))+MAX(E33-MIN('Engine Inputs'!$B$12*E33/$C$5,'Engine Inputs'!$B$9)*$C$5,0)*'Engine Inputs'!$B$10/$D$5)*(1-'Engine Inputs'!$B$4)+IF($D$5=1,(1-IF(OR($D$5=2,MOD(A34,2)=1),1,0))*E33*'Engine Inputs'!$B$10*(1-'Engine Inputs'!$B$4)/2,0)-IF(MOD(A34,2)=0,INDEX($B$11:$D$25,B34,3)*(1-'Engine Inputs'!$B$4),0) -> 7.5794077e+08 | F34: =F33+IF(OR($D$6=2,MOD(A34,2)=1),1,0)*(MIN('Engine Inputs'!$B$12*F33/$C$6,'Engine Inputs'!$B$9)*($B$6-'Engine Inputs'!$B$5-'Engine Inputs'!$B$6-2*'Engine Inputs'!$B$7*SQRT(MIN('Engine Inputs'!$B$12*F33/$C$6,'Engine Inputs'!$B$9)/'Engine Inputs'!$B$8))+MAX(F33-MIN('Engine Inputs'!$B$12*F33/$C$6,'Engine Inputs'!$B$9)*$C$6,0)*'Engine Inputs'!$B$10/$D$6)*(1-'Engine Inputs'!$B$4)+IF($D$6=1,(1-IF(OR($D$6=2,MOD(A34,2)=1),1,0))*F33*'Engine Inputs'!$B$10*(1-'Engine Inputs'!$B$4)/2,0)-IF(MOD(A34,2)=0,INDEX($B$11:$D$25,B34,1)*(1-'Engine Inputs'!$B$4),0) -> 20442978 | G34: =G33+IF(OR($D$6=2,MOD(A34,2)=1),1,0)*(MIN('Engine Inputs'!$B$12*G33/$C$6,'Engine Inputs'!$B$9)*($B$6-'Engine Inputs'!$B$5-'Engine Inputs'!$B$6-2*'Engine Inputs'!$B$7*SQRT(MIN('Engine Inputs'!$B$12*G33/$C$6,'Engine Inputs'!$B$9)/'Engine Inputs'!$B$8))+MAX(G33-MIN('Engine Inputs'!$B$12*G33/$C$6,'Engine Inputs'!$B$9)*$C$6,0)*'Engine Inputs'!$B$10/$D$6)*(1-'Engine Inputs'!$B$4)+IF($D$6=1,(1-IF(OR($D$6=2,MOD(A34,2)=1),1,0))*G33*'Engine Inputs'!$B$10*(1-'Engine Inputs'!$B$4)/2,0)-IF(MOD(A34,2)=0,INDEX($B$11:$D$25,B34,2)*(1-'Engine Inputs'!$B$4),0) -> 75597884 | H34: =H33+IF(OR($D$6=2,MOD(A34,2)=1),1,0)*(MIN('Engine Inputs'!$B$12*H33/$C$6,'Engine Inputs'!$B$9)*($B$6-'Engine Inputs'!$B$5-'Engine Inputs'!$B$6-2*'Engine Inputs'!$B$7*SQRT(MIN('Engine Inputs'!$B$12*H33/$C$6,'Engine Inputs'!$B$9)/'Engine Inputs'!$B$8))+MAX(H33-MIN('Engine Inputs'!$B$12*H33/$C$6,'Engine Inputs'!$B$9)*$C$6,0)*'Engine Inputs'!$B$10/$D$6)*(1-'Engine Inputs'!$B$4)+IF($D$6=1,(1-IF(OR($D$6=2,MOD(A34,2)=1),1,0))*H33*'Engine Inputs'!$B$10*(1-'Engine Inputs'!$B$4)/2,0)-IF(MOD(A34,2)=0,INDEX($B$11:$D$25,B34,3)*(1-'Engine Inputs'!$B$4),0) -> 1.9795532e+08 | I34: =I33+IF(OR($D$7=2,MOD(A34,2)=1),1,0)*(MIN('Engine Inputs'!$B$12*I33/$C$7,'Engine Inputs'!$B$9)*($B$7-'Engine Inputs'!$B$5-'Engine Inputs'!$B$6-2*'Engine Inputs'!$B$7*SQRT(MIN('Engine Inputs'!$B$12*I33/$C$7,'Engine Inputs'!$B$9)/'Engine Inputs'!$B$8))+MAX(I33-MIN('Engine Inputs'!$B$12*I33/$C$7,'Engine Inputs'!$B$9)*$C$7,0)*'Engine Inputs'!$B$10/$D$7)*(1-'Engine Inputs'!$B$4)+IF($D$7=1,(1-IF(OR($D$7=2,MOD(A34,2)=1),1,0))*I33*'Engine Inputs'!$B$10*(1-'Engine Inputs'!$B$4)/2,0)-IF(MOD(A34,2)=0,INDEX($B$11:$D$25,B34,1)*(1-'Engine Inputs'!$B$4),0) -> 5602869.8 | J34: =J33+IF(OR($D$7=2,MOD(A34,2)=1),1,0)*(MIN('Engine Inputs'!$B$12*J33/$C$7,'Engine Inputs'!$B$9)*($B$7-'Engine Inputs'!$B$5-'Engine Inputs'!$B$6-2*'Engine Inputs'!$B$7*SQRT(MIN('Engine Inputs'!$B$12*J33/$C$7,'Engine Inputs'!$B$9)/'Engine Inputs'!$B$8))+MAX(J33-MIN('Engine Inputs'!$B$12*J33/$C$7,'Engine Inputs'!$B$9)*$C$7,0)*'Engine Inputs'!$B$10/$D$7)*(1-'Engine Inputs'!$B$4)+IF($D$7=1,(1-IF(OR($D$7=2,MOD(A34,2)=1),1,0))*J33*'Engine Inputs'!$B$10*(1-'Engine Inputs'!$B$4)/2,0)-IF(MOD(A34,2)=0,INDEX($B$11:$D$25,B34,2)*(1-'Engine Inputs'!$B$4),0) -> 20904722 | K34: =K33+IF(OR($D$7=2,MOD(A34,2)=1),1,0)*(MIN('Engine Inputs'!$B$12*K33/$C$7,'Engine Inputs'!$B$9)*($B$7-'Engine Inputs'!$B$5-'Engine Inputs'!$B$6-2*'Engine Inputs'!$B$7*SQRT(MIN('Engine Inputs'!$B$12*K33/$C$7,'Engine Inputs'!$B$9)/'Engine Inputs'!$B$8))+MAX(K33-MIN('Engine Inputs'!$B$12*K33/$C$7,'Engine Inputs'!$B$9)*$C$7,0)*'Engine Inputs'!$B$10/$D$7)*(1-'Engine Inputs'!$B$4)+IF($D$7=1,(1-IF(OR($D$7=2,MOD(A34,2)=1),1,0))*K33*'Engine Inputs'!$B$10*(1-'Engine Inputs'!$B$4)/2,0)-IF(MOD(A34,2)=0,INDEX($B$11:$D$25,B34,3)*(1-'Engine Inputs'!$B$4),0) -> 55377923
A35: 7 | B35: =ROUNDUP(A35/2,0) -> 4 | C35: =C34+IF(OR($D$5=2,MOD(A35,2)=1),1,0)*(MIN('Engine Inputs'!$B$12*C34/$C$5,'Engine Inputs'!$B$9)*($B$5-'Engine Inputs'!$B$5-'Engine Inputs'!$B$6-2*'Engine Inputs'!$B$7*SQRT(MIN('Engine Inputs'!$B$12*C34/$C$5,'Engine Inputs'!$B$9)/'Engine Inputs'!$B$8))+MAX(C34-MIN('Engine Inputs'!$B$12*C34/$C$5,'Engine Inputs'!$B$9)*$C$5,0)*'Engine Inputs'!$B$10/$D$5)*(1-'Engine Inputs'!$B$4)+IF($D$5=1,(1-IF(OR($D$5=2,MOD(A35,2)=1),1,0))*C34*'Engine Inputs'!$B$10*(1-'Engine Inputs'!$B$4)/2,0)-IF(MOD(A35,2)=0,INDEX($B$11:$D$25,B35,1)*(1-'Engine Inputs'!$B$4),0) -> 1.4490003e+08 | D35: =D34+IF(OR($D$5=2,MOD(A35,2)=1),1,0)*(MIN('Engine Inputs'!$B$12*D34/$C$5,'Engine Inputs'!$B$9)*($B$5-'Engine Inputs'!$B$5-'Engine Inputs'!$B$6-2*'Engine Inputs'!$B$7*SQRT(MIN('Engine Inputs'!$B$12*D34/$C$5,'Engine Inputs'!$B$9)/'Engine Inputs'!$B$8))+MAX(D34-MIN('Engine Inputs'!$B$12*D34/$C$5,'Engine Inputs'!$B$9)*$C$5,0)*'Engine Inputs'!$B$10/$D$5)*(1-'Engine Inputs'!$B$4)+IF($D$5=1,(1-IF(OR($D$5=2,MOD(A35,2)=1),1,0))*D34*'Engine Inputs'!$B$10*(1-'Engine Inputs'!$B$4)/2,0)-IF(MOD(A35,2)=0,INDEX($B$11:$D$25,B35,2)*(1-'Engine Inputs'!$B$4),0) -> 5.3017233e+08 | E35: =E34+IF(OR($D$5=2,MOD(A35,2)=1),1,0)*(MIN('Engine Inputs'!$B$12*E34/$C$5,'Engine Inputs'!$B$9)*($B$5-'Engine Inputs'!$B$5-'Engine Inputs'!$B$6-2*'Engine Inputs'!$B$7*SQRT(MIN('Engine Inputs'!$B$12*E34/$C$5,'Engine Inputs'!$B$9)/'Engine Inputs'!$B$8))+MAX(E34-MIN('Engine Inputs'!$B$12*E34/$C$5,'Engine Inputs'!$B$9)*$C$5,0)*'Engine Inputs'!$B$10/$D$5)*(1-'Engine Inputs'!$B$4)+IF($D$5=1,(1-IF(OR($D$5=2,MOD(A35,2)=1),1,0))*E34*'Engine Inputs'!$B$10*(1-'Engine Inputs'!$B$4)/2,0)-IF(MOD(A35,2)=0,INDEX($B$11:$D$25,B35,3)*(1-'Engine Inputs'!$B$4),0) -> 1.369266e+09 | F35: =F34+IF(OR($D$6=2,MOD(A35,2)=1),1,0)*(MIN('Engine Inputs'!$B$12*F34/$C$6,'Engine Inputs'!$B$9)*($B$6-'Engine Inputs'!$B$5-'Engine Inputs'!$B$6-2*'Engine Inputs'!$B$7*SQRT(MIN('Engine Inputs'!$B$12*F34/$C$6,'Engine Inputs'!$B$9)/'Engine Inputs'!$B$8))+MAX(F34-MIN('Engine Inputs'!$B$12*F34/$C$6,'Engine Inputs'!$B$9)*$C$6,0)*'Engine Inputs'!$B$10/$D$6)*(1-'Engine Inputs'!$B$4)+IF($D$6=1,(1-IF(OR($D$6=2,MOD(A35,2)=1),1,0))*F34*'Engine Inputs'!$B$10*(1-'Engine Inputs'!$B$4)/2,0)-IF(MOD(A35,2)=0,INDEX($B$11:$D$25,B35,1)*(1-'Engine Inputs'!$B$4),0) -> 30085514 | G35: =G34+IF(OR($D$6=2,MOD(A35,2)=1),1,0)*(MIN('Engine Inputs'!$B$12*G34/$C$6,'Engine Inputs'!$B$9)*($B$6-'Engine Inputs'!$B$5-'Engine Inputs'!$B$6-2*'Engine Inputs'!$B$7*SQRT(MIN('Engine Inputs'!$B$12*G34/$C$6,'Engine Inputs'!$B$9)/'Engine Inputs'!$B$8))+MAX(G34-MIN('Engine Inputs'!$B$12*G34/$C$6,'Engine Inputs'!$B$9)*$C$6,0)*'Engine Inputs'!$B$10/$D$6)*(1-'Engine Inputs'!$B$4)+IF($D$6=1,(1-IF(OR($D$6=2,MOD(A35,2)=1),1,0))*G34*'Engine Inputs'!$B$10*(1-'Engine Inputs'!$B$4)/2,0)-IF(MOD(A35,2)=0,INDEX($B$11:$D$25,B35,2)*(1-'Engine Inputs'!$B$4),0) -> 1.1077842e+08 | H35: =H34+IF(OR($D$6=2,MOD(A35,2)=1),1,0)*(MIN('Engine Inputs'!$B$12*H34/$C$6,'Engine Inputs'!$B$9)*($B$6-'Engine Inputs'!$B$5-'Engine Inputs'!$B$6-2*'Engine Inputs'!$B$7*SQRT(MIN('Engine Inputs'!$B$12*H34/$C$6,'Engine Inputs'!$B$9)/'Engine Inputs'!$B$8))+MAX(H34-MIN('Engine Inputs'!$B$12*H34/$C$6,'Engine Inputs'!$B$9)*$C$6,0)*'Engine Inputs'!$B$10/$D$6)*(1-'Engine Inputs'!$B$4)+IF($D$6=1,(1-IF(OR($D$6=2,MOD(A35,2)=1),1,0))*H34*'Engine Inputs'!$B$10*(1-'Engine Inputs'!$B$4)/2,0)-IF(MOD(A35,2)=0,INDEX($B$11:$D$25,B35,3)*(1-'Engine Inputs'!$B$4),0) -> 2.8846644e+08 | I35: =I34+IF(OR($D$7=2,MOD(A35,2)=1),1,0)*(MIN('Engine Inputs'!$B$12*I34/$C$7,'Engine Inputs'!$B$9)*($B$7-'Engine Inputs'!$B$5-'Engine Inputs'!$B$6-2*'Engine Inputs'!$B$7*SQRT(MIN('Engine Inputs'!$B$12*I34/$C$7,'Engine Inputs'!$B$9)/'Engine Inputs'!$B$8))+MAX(I34-MIN('Engine Inputs'!$B$12*I34/$C$7,'Engine Inputs'!$B$9)*$C$7,0)*'Engine Inputs'!$B$10/$D$7)*(1-'Engine Inputs'!$B$4)+IF($D$7=1,(1-IF(OR($D$7=2,MOD(A35,2)=1),1,0))*I34*'Engine Inputs'!$B$10*(1-'Engine Inputs'!$B$4)/2,0)-IF(MOD(A35,2)=0,INDEX($B$11:$D$25,B35,1)*(1-'Engine Inputs'!$B$4),0) -> 7745832.2 | J35: =J34+IF(OR($D$7=2,MOD(A35,2)=1),1,0)*(MIN('Engine Inputs'!$B$12*J34/$C$7,'Engine Inputs'!$B$9)*($B$7-'Engine Inputs'!$B$5-'Engine Inputs'!$B$6-2*'Engine Inputs'!$B$7*SQRT(MIN('Engine Inputs'!$B$12*J34/$C$7,'Engine Inputs'!$B$9)/'Engine Inputs'!$B$8))+MAX(J34-MIN('Engine Inputs'!$B$12*J34/$C$7,'Engine Inputs'!$B$9)*$C$7,0)*'Engine Inputs'!$B$10/$D$7)*(1-'Engine Inputs'!$B$4)+IF($D$7=1,(1-IF(OR($D$7=2,MOD(A35,2)=1),1,0))*J34*'Engine Inputs'!$B$10*(1-'Engine Inputs'!$B$4)/2,0)-IF(MOD(A35,2)=0,INDEX($B$11:$D$25,B35,2)*(1-'Engine Inputs'!$B$4),0) -> 28833212 | K35: =K34+IF(OR($D$7=2,MOD(A35,2)=1),1,0)*(MIN('Engine Inputs'!$B$12*K34/$C$7,'Engine Inputs'!$B$9)*($B$7-'Engine Inputs'!$B$5-'Engine Inputs'!$B$6-2*'Engine Inputs'!$B$7*SQRT(MIN('Engine Inputs'!$B$12*K34/$C$7,'Engine Inputs'!$B$9)/'Engine Inputs'!$B$8))+MAX(K34-MIN('Engine Inputs'!$B$12*K34/$C$7,'Engine Inputs'!$B$9)*$C$7,0)*'Engine Inputs'!$B$10/$D$7)*(1-'Engine Inputs'!$B$4)+IF($D$7=1,(1-IF(OR($D$7=2,MOD(A35,2)=1),1,0))*K34*'Engine Inputs'!$B$10*(1-'Engine Inputs'!$B$4)/2,0)-IF(MOD(A35,2)=0,INDEX($B$11:$D$25,B35,3)*(1-'Engine Inputs'!$B$4),0) -> 76149822
A36: 8 | B36: =ROUNDUP(A36/2,0) -> 4 | C36: =C35+IF(OR($D$5=2,MOD(A36,2)=1),1,0)*(MIN('Engine Inputs'!$B$12*C35/$C$5,'Engine Inputs'!$B$9)*($B$5-'Engine Inputs'!$B$5-'Engine Inputs'!$B$6-2*'Engine Inputs'!$B$7*SQRT(MIN('Engine Inputs'!$B$12*C35/$C$5,'Engine Inputs'!$B$9)/'Engine Inputs'!$B$8))+MAX(C35-MIN('Engine Inputs'!$B$12*C35/$C$5,'Engine Inputs'!$B$9)*$C$5,0)*'Engine Inputs'!$B$10/$D$5)*(1-'Engine Inputs'!$B$4)+IF($D$5=1,(1-IF(OR($D$5=2,MOD(A36,2)=1),1,0))*C35*'Engine Inputs'!$B$10*(1-'Engine Inputs'!$B$4)/2,0)-IF(MOD(A36,2)=0,INDEX($B$11:$D$25,B36,1)*(1-'Engine Inputs'!$B$4),0) -> 2.6541125e+08 | D36: =D35+IF(OR($D$5=2,MOD(A36,2)=1),1,0)*(MIN('Engine Inputs'!$B$12*D35/$C$5,'Engine Inputs'!$B$9)*($B$5-'Engine Inputs'!$B$5-'Engine Inputs'!$B$6-2*'Engine Inputs'!$B$7*SQRT(MIN('Engine Inputs'!$B$12*D35/$C$5,'Engine Inputs'!$B$9)/'Engine Inputs'!$B$8))+MAX(D35-MIN('Engine Inputs'!$B$12*D35/$C$5,'Engine Inputs'!$B$9)*$C$5,0)*'Engine Inputs'!$B$10/$D$5)*(1-'Engine Inputs'!$B$4)+IF($D$5=1,(1-IF(OR($D$5=2,MOD(A36,2)=1),1,0))*D35*'Engine Inputs'!$B$10*(1-'Engine Inputs'!$B$4)/2,0)-IF(MOD(A36,2)=0,INDEX($B$11:$D$25,B36,2)*(1-'Engine Inputs'!$B$4),0) -> 9.6156137e+08 | E36: =E35+IF(OR($D$5=2,MOD(A36,2)=1),1,0)*(MIN('Engine Inputs'!$B$12*E35/$C$5,'Engine Inputs'!$B$9)*($B$5-'Engine Inputs'!$B$5-'Engine Inputs'!$B$6-2*'Engine Inputs'!$B$7*SQRT(MIN('Engine Inputs'!$B$12*E35/$C$5,'Engine Inputs'!$B$9)/'Engine Inputs'!$B$8))+MAX(E35-MIN('Engine Inputs'!$B$12*E35/$C$5,'Engine Inputs'!$B$9)*$C$5,0)*'Engine Inputs'!$B$10/$D$5)*(1-'Engine Inputs'!$B$4)+IF($D$5=1,(1-IF(OR($D$5=2,MOD(A36,2)=1),1,0))*E35*'Engine Inputs'!$B$10*(1-'Engine Inputs'!$B$4)/2,0)-IF(MOD(A36,2)=0,INDEX($B$11:$D$25,B36,3)*(1-'Engine Inputs'!$B$4),0) -> 2.1610751e+09 | F36: =F35+IF(OR($D$6=2,MOD(A36,2)=1),1,0)*(MIN('Engine Inputs'!$B$12*F35/$C$6,'Engine Inputs'!$B$9)*($B$6-'Engine Inputs'!$B$5-'Engine Inputs'!$B$6-2*'Engine Inputs'!$B$7*SQRT(MIN('Engine Inputs'!$B$12*F35/$C$6,'Engine Inputs'!$B$9)/'Engine Inputs'!$B$8))+MAX(F35-MIN('Engine Inputs'!$B$12*F35/$C$6,'Engine Inputs'!$B$9)*$C$6,0)*'Engine Inputs'!$B$10/$D$6)*(1-'Engine Inputs'!$B$4)+IF($D$6=1,(1-IF(OR($D$6=2,MOD(A36,2)=1),1,0))*F35*'Engine Inputs'!$B$10*(1-'Engine Inputs'!$B$4)/2,0)-IF(MOD(A36,2)=0,INDEX($B$11:$D$25,B36,1)*(1-'Engine Inputs'!$B$4),0) -> 44194949 | G36: =G35+IF(OR($D$6=2,MOD(A36,2)=1),1,0)*(MIN('Engine Inputs'!$B$12*G35/$C$6,'Engine Inputs'!$B$9)*($B$6-'Engine Inputs'!$B$5-'Engine Inputs'!$B$6-2*'Engine Inputs'!$B$7*SQRT(MIN('Engine Inputs'!$B$12*G35/$C$6,'Engine Inputs'!$B$9)/'Engine Inputs'!$B$8))+MAX(G35-MIN('Engine Inputs'!$B$12*G35/$C$6,'Engine Inputs'!$B$9)*$C$6,0)*'Engine Inputs'!$B$10/$D$6)*(1-'Engine Inputs'!$B$4)+IF($D$6=1,(1-IF(OR($D$6=2,MOD(A36,2)=1),1,0))*G35*'Engine Inputs'!$B$10*(1-'Engine Inputs'!$B$4)/2,0)-IF(MOD(A36,2)=0,INDEX($B$11:$D$25,B36,2)*(1-'Engine Inputs'!$B$4),0) -> 1.6188355e+08 | H36: =H35+IF(OR($D$6=2,MOD(A36,2)=1),1,0)*(MIN('Engine Inputs'!$B$12*H35/$C$6,'Engine Inputs'!$B$9)*($B$6-'Engine Inputs'!$B$5-'Engine Inputs'!$B$6-2*'Engine Inputs'!$B$7*SQRT(MIN('Engine Inputs'!$B$12*H35/$C$6,'Engine Inputs'!$B$9)/'Engine Inputs'!$B$8))+MAX(H35-MIN('Engine Inputs'!$B$12*H35/$C$6,'Engine Inputs'!$B$9)*$C$6,0)*'Engine Inputs'!$B$10/$D$6)*(1-'Engine Inputs'!$B$4)+IF($D$6=1,(1-IF(OR($D$6=2,MOD(A36,2)=1),1,0))*H35*'Engine Inputs'!$B$10*(1-'Engine Inputs'!$B$4)/2,0)-IF(MOD(A36,2)=0,INDEX($B$11:$D$25,B36,3)*(1-'Engine Inputs'!$B$4),0) -> 4.1871542e+08 | I36: =I35+IF(OR($D$7=2,MOD(A36,2)=1),1,0)*(MIN('Engine Inputs'!$B$12*I35/$C$7,'Engine Inputs'!$B$9)*($B$7-'Engine Inputs'!$B$5-'Engine Inputs'!$B$6-2*'Engine Inputs'!$B$7*SQRT(MIN('Engine Inputs'!$B$12*I35/$C$7,'Engine Inputs'!$B$9)/'Engine Inputs'!$B$8))+MAX(I35-MIN('Engine Inputs'!$B$12*I35/$C$7,'Engine Inputs'!$B$9)*$C$7,0)*'Engine Inputs'!$B$10/$D$7)*(1-'Engine Inputs'!$B$4)+IF($D$7=1,(1-IF(OR($D$7=2,MOD(A36,2)=1),1,0))*I35*'Engine Inputs'!$B$10*(1-'Engine Inputs'!$B$4)/2,0)-IF(MOD(A36,2)=0,INDEX($B$11:$D$25,B36,1)*(1-'Engine Inputs'!$B$4),0) -> 7896797.9 | J36: =J35+IF(OR($D$7=2,MOD(A36,2)=1),1,0)*(MIN('Engine Inputs'!$B$12*J35/$C$7,'Engine Inputs'!$B$9)*($B$7-'Engine Inputs'!$B$5-'Engine Inputs'!$B$6-2*'Engine Inputs'!$B$7*SQRT(MIN('Engine Inputs'!$B$12*J35/$C$7,'Engine Inputs'!$B$9)/'Engine Inputs'!$B$8))+MAX(J35-MIN('Engine Inputs'!$B$12*J35/$C$7,'Engine Inputs'!$B$9)*$C$7,0)*'Engine Inputs'!$B$10/$D$7)*(1-'Engine Inputs'!$B$4)+IF($D$7=1,(1-IF(OR($D$7=2,MOD(A36,2)=1),1,0))*J35*'Engine Inputs'!$B$10*(1-'Engine Inputs'!$B$4)/2,0)-IF(MOD(A36,2)=0,INDEX($B$11:$D$25,B36,2)*(1-'Engine Inputs'!$B$4),0) -> 29394138 | K36: =K35+IF(OR($D$7=2,MOD(A36,2)=1),1,0)*(MIN('Engine Inputs'!$B$12*K35/$C$7,'Engine Inputs'!$B$9)*($B$7-'Engine Inputs'!$B$5-'Engine Inputs'!$B$6-2*'Engine Inputs'!$B$7*SQRT(MIN('Engine Inputs'!$B$12*K35/$C$7,'Engine Inputs'!$B$9)/'Engine Inputs'!$B$8))+MAX(K35-MIN('Engine Inputs'!$B$12*K35/$C$7,'Engine Inputs'!$B$9)*$C$7,0)*'Engine Inputs'!$B$10/$D$7)*(1-'Engine Inputs'!$B$4)+IF($D$7=1,(1-IF(OR($D$7=2,MOD(A36,2)=1),1,0))*K35*'Engine Inputs'!$B$10*(1-'Engine Inputs'!$B$4)/2,0)-IF(MOD(A36,2)=0,INDEX($B$11:$D$25,B36,3)*(1-'Engine Inputs'!$B$4),0) -> 77627656
A37: 9 | B37: =ROUNDUP(A37/2,0) -> 5 | C37: =C36+IF(OR($D$5=2,MOD(A37,2)=1),1,0)*(MIN('Engine Inputs'!$B$12*C36/$C$5,'Engine Inputs'!$B$9)*($B$5-'Engine Inputs'!$B$5-'Engine Inputs'!$B$6-2*'Engine Inputs'!$B$7*SQRT(MIN('Engine Inputs'!$B$12*C36/$C$5,'Engine Inputs'!$B$9)/'Engine Inputs'!$B$8))+MAX(C36-MIN('Engine Inputs'!$B$12*C36/$C$5,'Engine Inputs'!$B$9)*$C$5,0)*'Engine Inputs'!$B$10/$D$5)*(1-'Engine Inputs'!$B$4)+IF($D$5=1,(1-IF(OR($D$5=2,MOD(A37,2)=1),1,0))*C36*'Engine Inputs'!$B$10*(1-'Engine Inputs'!$B$4)/2,0)-IF(MOD(A37,2)=0,INDEX($B$11:$D$25,B37,1)*(1-'Engine Inputs'!$B$4),0) -> 4.8436864e+08 | D37: =D36+IF(OR($D$5=2,MOD(A37,2)=1),1,0)*(MIN('Engine Inputs'!$B$12*D36/$C$5,'Engine Inputs'!$B$9)*($B$5-'Engine Inputs'!$B$5-'Engine Inputs'!$B$6-2*'Engine Inputs'!$B$7*SQRT(MIN('Engine Inputs'!$B$12*D36/$C$5,'Engine Inputs'!$B$9)/'Engine Inputs'!$B$8))+MAX(D36-MIN('Engine Inputs'!$B$12*D36/$C$5,'Engine Inputs'!$B$9)*$C$5,0)*'Engine Inputs'!$B$10/$D$5)*(1-'Engine Inputs'!$B$4)+IF($D$5=1,(1-IF(OR($D$5=2,MOD(A37,2)=1),1,0))*D36*'Engine Inputs'!$B$10*(1-'Engine Inputs'!$B$4)/2,0)-IF(MOD(A37,2)=0,INDEX($B$11:$D$25,B37,2)*(1-'Engine Inputs'!$B$4),0) -> 1.7316395e+09 | E37: =E36+IF(OR($D$5=2,MOD(A37,2)=1),1,0)*(MIN('Engine Inputs'!$B$12*E36/$C$5,'Engine Inputs'!$B$9)*($B$5-'Engine Inputs'!$B$5-'Engine Inputs'!$B$6-2*'Engine Inputs'!$B$7*SQRT(MIN('Engine Inputs'!$B$12*E36/$C$5,'Engine Inputs'!$B$9)/'Engine Inputs'!$B$8))+MAX(E36-MIN('Engine Inputs'!$B$12*E36/$C$5,'Engine Inputs'!$B$9)*$C$5,0)*'Engine Inputs'!$B$10/$D$5)*(1-'Engine Inputs'!$B$4)+IF($D$5=1,(1-IF(OR($D$5=2,MOD(A37,2)=1),1,0))*E36*'Engine Inputs'!$B$10*(1-'Engine Inputs'!$B$4)/2,0)-IF(MOD(A37,2)=0,INDEX($B$11:$D$25,B37,3)*(1-'Engine Inputs'!$B$4),0) -> 2.9725155e+09 | F37: =F36+IF(OR($D$6=2,MOD(A37,2)=1),1,0)*(MIN('Engine Inputs'!$B$12*F36/$C$6,'Engine Inputs'!$B$9)*($B$6-'Engine Inputs'!$B$5-'Engine Inputs'!$B$6-2*'Engine Inputs'!$B$7*SQRT(MIN('Engine Inputs'!$B$12*F36/$C$6,'Engine Inputs'!$B$9)/'Engine Inputs'!$B$8))+MAX(F36-MIN('Engine Inputs'!$B$12*F36/$C$6,'Engine Inputs'!$B$9)*$C$6,0)*'Engine Inputs'!$B$10/$D$6)*(1-'Engine Inputs'!$B$4)+IF($D$6=1,(1-IF(OR($D$6=2,MOD(A37,2)=1),1,0))*F36*'Engine Inputs'!$B$10*(1-'Engine Inputs'!$B$4)/2,0)-IF(MOD(A37,2)=0,INDEX($B$11:$D$25,B37,1)*(1-'Engine Inputs'!$B$4),0) -> 64898580 | G37: =G36+IF(OR($D$6=2,MOD(A37,2)=1),1,0)*(MIN('Engine Inputs'!$B$12*G36/$C$6,'Engine Inputs'!$B$9)*($B$6-'Engine Inputs'!$B$5-'Engine Inputs'!$B$6-2*'Engine Inputs'!$B$7*SQRT(MIN('Engine Inputs'!$B$12*G36/$C$6,'Engine Inputs'!$B$9)/'Engine Inputs'!$B$8))+MAX(G36-MIN('Engine Inputs'!$B$12*G36/$C$6,'Engine Inputs'!$B$9)*$C$6,0)*'Engine Inputs'!$B$10/$D$6)*(1-'Engine Inputs'!$B$4)+IF($D$6=1,(1-IF(OR($D$6=2,MOD(A37,2)=1),1,0))*G36*'Engine Inputs'!$B$10*(1-'Engine Inputs'!$B$4)/2,0)-IF(MOD(A37,2)=0,INDEX($B$11:$D$25,B37,2)*(1-'Engine Inputs'!$B$4),0) -> 2.3623139e+08 | H37: =H36+IF(OR($D$6=2,MOD(A37,2)=1),1,0)*(MIN('Engine Inputs'!$B$12*H36/$C$6,'Engine Inputs'!$B$9)*($B$6-'Engine Inputs'!$B$5-'Engine Inputs'!$B$6-2*'Engine Inputs'!$B$7*SQRT(MIN('Engine Inputs'!$B$12*H36/$C$6,'Engine Inputs'!$B$9)/'Engine Inputs'!$B$8))+MAX(H36-MIN('Engine Inputs'!$B$12*H36/$C$6,'Engine Inputs'!$B$9)*$C$6,0)*'Engine Inputs'!$B$10/$D$6)*(1-'Engine Inputs'!$B$4)+IF($D$6=1,(1-IF(OR($D$6=2,MOD(A37,2)=1),1,0))*H36*'Engine Inputs'!$B$10*(1-'Engine Inputs'!$B$4)/2,0)-IF(MOD(A37,2)=0,INDEX($B$11:$D$25,B37,3)*(1-'Engine Inputs'!$B$4),0) -> 6.0611382e+08 | I37: =I36+IF(OR($D$7=2,MOD(A37,2)=1),1,0)*(MIN('Engine Inputs'!$B$12*I36/$C$7,'Engine Inputs'!$B$9)*($B$7-'Engine Inputs'!$B$5-'Engine Inputs'!$B$6-2*'Engine Inputs'!$B$7*SQRT(MIN('Engine Inputs'!$B$12*I36/$C$7,'Engine Inputs'!$B$9)/'Engine Inputs'!$B$8))+MAX(I36-MIN('Engine Inputs'!$B$12*I36/$C$7,'Engine Inputs'!$B$9)*$C$7,0)*'Engine Inputs'!$B$10/$D$7)*(1-'Engine Inputs'!$B$4)+IF($D$7=1,(1-IF(OR($D$7=2,MOD(A37,2)=1),1,0))*I36*'Engine Inputs'!$B$10*(1-'Engine Inputs'!$B$4)/2,0)-IF(MOD(A37,2)=0,INDEX($B$11:$D$25,B37,1)*(1-'Engine Inputs'!$B$4),0) -> 10912042 | J37: =J36+IF(OR($D$7=2,MOD(A37,2)=1),1,0)*(MIN('Engine Inputs'!$B$12*J36/$C$7,'Engine Inputs'!$B$9)*($B$7-'Engine Inputs'!$B$5-'Engine Inputs'!$B$6-2*'Engine Inputs'!$B$7*SQRT(MIN('Engine Inputs'!$B$12*J36/$C$7,'Engine Inputs'!$B$9)/'Engine Inputs'!$B$8))+MAX(J36-MIN('Engine Inputs'!$B$12*J36/$C$7,'Engine Inputs'!$B$9)*$C$7,0)*'Engine Inputs'!$B$10/$D$7)*(1-'Engine Inputs'!$B$4)+IF($D$7=1,(1-IF(OR($D$7=2,MOD(A37,2)=1),1,0))*J36*'Engine Inputs'!$B$10*(1-'Engine Inputs'!$B$4)/2,0)-IF(MOD(A37,2)=0,INDEX($B$11:$D$25,B37,2)*(1-'Engine Inputs'!$B$4),0) -> 40506065 | K37: =K36+IF(OR($D$7=2,MOD(A37,2)=1),1,0)*(MIN('Engine Inputs'!$B$12*K36/$C$7,'Engine Inputs'!$B$9)*($B$7-'Engine Inputs'!$B$5-'Engine Inputs'!$B$6-2*'Engine Inputs'!$B$7*SQRT(MIN('Engine Inputs'!$B$12*K36/$C$7,'Engine Inputs'!$B$9)/'Engine Inputs'!$B$8))+MAX(K36-MIN('Engine Inputs'!$B$12*K36/$C$7,'Engine Inputs'!$B$9)*$C$7,0)*'Engine Inputs'!$B$10/$D$7)*(1-'Engine Inputs'!$B$4)+IF($D$7=1,(1-IF(OR($D$7=2,MOD(A37,2)=1),1,0))*K36*'Engine Inputs'!$B$10*(1-'Engine Inputs'!$B$4)/2,0)-IF(MOD(A37,2)=0,INDEX($B$11:$D$25,B37,3)*(1-'Engine Inputs'!$B$4),0) -> 1.0659068e+08
